Workbook

Sheet Life Insurance Model
A1: Life-Insurance Distributable-Earnings DCF — MET
A2: METLIFE INC
A3: Common-equity DCF: filed segment earnings less analyst-entered statutory-capital retention, capped by source-supported upstream capacity. No insurer enterprise value or operating liabilities as corporate debt.
A4: Model status | B4: =IF('Input Required'!$B$3<>"READY",'Input Required'!$B$3,IF(OR(NOT(ISNUMBER($K$8)),$K$8<2%,$K$8>50%,$K$10<0,$K$10>10%,$K$10>=$K$8-0.5%,I33<=0,$K$16<$K$17),"INPUT ERROR — check cost of equity, terminal assumptions, terminal distributable earnings, and parent cash reserve","READY")) -> INCOMPLETE — fill required inputs | J4: CAPM and equity-bridge inputs | K4: Value | L4: Source / basis
A5: Amounts: USD millions; diluted shares in millions; per-share value in USD. | J5: Risk-free rate | K5: 0.05277 | L5: live as of 2026-10-03
J6: Equity-risk premium | K6: 0.083837107 | L6: live as of 2026-10-03
A7: Historical actuals and five-year segment forecast | J7: Beta | K7: 0.759 | L7: openbb_yfinance as of 2026-10-03
A8: USD millions unless shown otherwise | J8: Cost of equity (CAPM) | K8: =IF(OR(K5="",K6="",K7=""),"",K5+K7*K6) -> 0.11640236 | L8: Risk-free rate + beta × equity-risk premium
A9: Reported fiscal year | B9: 2023 | C9: 2024 | D9: 2025 | E9: 2026 | F9: 2027 | G9: 2028 | H9: 2029 | I9: 2030 | J9: Normalized tax rate | K9: Not applied | L9: MET adjusted earnings available to common are already after tax.
A10: Asia — after-tax adjusted earnings | B10: ='Data Review'!E68 -> 1282 | C10: ='Data Review'!E67 -> 1621 | D10: ='Data Review'!E66 -> 1702 | E10: =IF('Input Required'!$B$3<>"READY","",D10*(1+E11)) | F10: =IF('Input Required'!$B$3<>"READY","",E10*(1+F11)) | G10: =IF('Input Required'!$B$3<>"READY","",F10*(1+G11)) | H10: =IF('Input Required'!$B$3<>"READY","",G10*(1+H11)) | I10: =IF('Input Required'!$B$3<>"READY","",H10*(1+I11)) | J10: Terminal growth | K10: =IF('Input Required'!$B$3<>"READY","",'Input Required'!F56/1) | L10: Source-required assumption; must be at least 0.5% below cost of equity and no greater than 10%.
A11: Asia growth assumption | E11: =IF('Input Required'!$B$3<>"READY","",'Input Required'!F6/1) | F11: =IF('Input Required'!$B$3<>"READY","",'Input Required'!F7/1) | G11: =IF('Input Required'!$B$3<>"READY","",'Input Required'!F8/1) | H11: =IF('Input Required'!$B$3<>"READY","",'Input Required'!F9/1) | I11: =IF('Input Required'!$B$3<>"READY","",'Input Required'!F10/1) | J11: Current common share price | K11: 94.43 | L11: openbb_yfinance as of 2026-10-03
A12: Corporate & Other — after-tax adjusted earnings | B12: ='Data Review'!E80 -> -295 | C12: ='Data Review'!E79 -> -317 | D12: ='Data Review'!E78 -> -487 | E12: =IF('Input Required'!$B$3<>"READY","",D12*(1+E13)) | F12: =IF('Input Required'!$B$3<>"READY","",E12*(1+F13)) | G12: =IF('Input Required'!$B$3<>"READY","",F12*(1+G13)) | H12: =IF('Input Required'!$B$3<>"READY","",G12*(1+H13)) | I12: =IF('Input Required'!$B$3<>"READY","",H12*(1+I13)) | J12: Diluted shares outstanding | K12: 673.3 | L12: SEC accession 0001099219-26-000013, filed 2026-02-19; latest filed diluted share count
A13: Corporate & Other growth assumption | E13: =IF('Input Required'!$B$3<>"READY","",'Input Required'!F11/1) | F13: =IF('Input Required'!$B$3<>"READY","",'Input Required'!F12/1) | G13: =IF('Input Required'!$B$3<>"READY","",'Input Required'!F13/1) | H13: =IF('Input Required'!$B$3<>"READY","",'Input Required'!F14/1) | I13: =IF('Input Required'!$B$3<>"READY","",'Input Required'!F15/1) | J13: Market context as of | K13: 2026-10-03 | L13: Dated market observations are retained with their source references.
A14: EMEA — after-tax adjusted earnings | B14: ='Data Review'!E74 -> 265 | C14: ='Data Review'!E73 -> 283 | D14: ='Data Review'!E72 -> 367 | E14: =IF('Input Required'!$B$3<>"READY","",D14*(1+E15)) | F14: =IF('Input Required'!$B$3<>"READY","",E14*(1+F15)) | G14: =IF('Input Required'!$B$3<>"READY","",F14*(1+G15)) | H14: =IF('Input Required'!$B$3<>"READY","",G14*(1+H15)) | I14: =IF('Input Required'!$B$3<>"READY","",H14*(1+I15))
A15: EMEA growth assumption | E15: =IF('Input Required'!$B$3<>"READY","",'Input Required'!F16/1) | F15: =IF('Input Required'!$B$3<>"READY","",'Input Required'!F17/1) | G15: =IF('Input Required'!$B$3<>"READY","",'Input Required'!F18/1) | H15: =IF('Input Required'!$B$3<>"READY","",'Input Required'!F19/1) | I15: =IF('Input Required'!$B$3<>"READY","",'Input Required'!F20/1) | J15: Holding-company equity bridge
A16: Group Benefits — after-tax adjusted earnings | B16: ='Data Review'!E62 -> 1655 | C16: ='Data Review'!E61 -> 1606 | D16: ='Data Review'!E60 -> 1692 | E16: =IF('Input Required'!$B$3<>"READY","",D16*(1+E17)) | F16: =IF('Input Required'!$B$3<>"READY","",E16*(1+F17)) | G16: =IF('Input Required'!$B$3<>"READY","",F16*(1+G17)) | H16: =IF('Input Required'!$B$3<>"READY","",G16*(1+H17)) | I16: =IF('Input Required'!$B$3<>"READY","",H16*(1+I17)) | J16: Parent cash and liquid assets | K16: =IF('Input Required'!$B$3<>"READY","",'Input Required'!F51/1000000) | L16: Blue input on Input Required; use holding-company amounts and a source or rationale.
A17: Group Benefits growth assumption | E17: =IF('Input Required'!$B$3<>"READY","",'Input Required'!F21/1) | F17: =IF('Input Required'!$B$3<>"READY","",'Input Required'!F22/1) | G17: =IF('Input Required'!$B$3<>"READY","",'Input Required'!F23/1) | H17: =IF('Input Required'!$B$3<>"READY","",'Input Required'!F24/1) | I17: =IF('Input Required'!$B$3<>"READY","",'Input Required'!F25/1) | J17: Required parent cash reserve | K17: =IF('Input Required'!$B$3<>"READY","",'Input Required'!F52/1000000) | L17: Blue input on Input Required; use holding-company amounts and a source or rationale.
A18: Latin America — after-tax adjusted earnings | B18: ='Data Review'!E71 -> 840 | C18: ='Data Review'!E70 -> 881 | D18: ='Data Review'!E69 -> 798 | E18: =IF('Input Required'!$B$3<>"READY","",D18*(1+E19)) | F18: =IF('Input Required'!$B$3<>"READY","",E18*(1+F19)) | G18: =IF('Input Required'!$B$3<>"READY","",F18*(1+G19)) | H18: =IF('Input Required'!$B$3<>"READY","",G18*(1+H19)) | I18: =IF('Input Required'!$B$3<>"READY","",H18*(1+I19)) | J18: Parent-company debt | K18: =IF('Input Required'!$B$3<>"READY","",'Input Required'!F53/1000000) | L18: Blue input on Input Required; use holding-company amounts and a source or rationale.
A19: Latin America growth assumption | E19: =IF('Input Required'!$B$3<>"READY","",'Input Required'!F26/1) | F19: =IF('Input Required'!$B$3<>"READY","",'Input Required'!F27/1) | G19: =IF('Input Required'!$B$3<>"READY","",'Input Required'!F28/1) | H19: =IF('Input Required'!$B$3<>"READY","",'Input Required'!F29/1) | I19: =IF('Input Required'!$B$3<>"READY","",'Input Required'!F30/1) | J19: Preferred equity claims | K19: =IF('Input Required'!$B$3<>"READY","",'Input Required'!F54/1000000) | L19: Blue input on Input Required; use holding-company amounts and a source or rationale.
A20: MIM — after-tax adjusted earnings | B20: ='Data Review'!E77 -> 70 | C20: ='Data Review'!E76 -> 55 | D20: ='Data Review'!E75 -> 200 | E20: =IF('Input Required'!$B$3<>"READY","",D20*(1+E21)) | F20: =IF('Input Required'!$B$3<>"READY","",E20*(1+F21)) | G20: =IF('Input Required'!$B$3<>"READY","",F20*(1+G21)) | H20: =IF('Input Required'!$B$3<>"READY","",G20*(1+H21)) | I20: =IF('Input Required'!$B$3<>"READY","",H20*(1+I21)) | J20: Noncontrolling interest | K20: =IF('Input Required'!$B$3<>"READY","",'Input Required'!F55/1000000) | L20: Blue input on Input Required; use holding-company amounts and a source or rationale.
A21: MIM growth assumption | E21: =IF('Input Required'!$B$3<>"READY","",'Input Required'!F31/1) | F21: =IF('Input Required'!$B$3<>"READY","",'Input Required'!F32/1) | G21: =IF('Input Required'!$B$3<>"READY","",'Input Required'!F33/1) | H21: =IF('Input Required'!$B$3<>"READY","",'Input Required'!F34/1) | I21: =IF('Input Required'!$B$3<>"READY","",'Input Required'!F35/1)
A22: RIS — after-tax adjusted earnings | B22: ='Data Review'!E65 -> 1708 | C22: ='Data Review'!E64 -> 1667 | D22: ='Data Review'!E63 -> 1671 | E22: =IF('Input Required'!$B$3<>"READY","",D22*(1+E23)) | F22: =IF('Input Required'!$B$3<>"READY","",E22*(1+F23)) | G22: =IF('Input Required'!$B$3<>"READY","",F22*(1+G23)) | H22: =IF('Input Required'!$B$3<>"READY","",G22*(1+H23)) | I22: =IF('Input Required'!$B$3<>"READY","",H22*(1+I23))
A23: RIS growth assumption | E23: =IF('Input Required'!$B$3<>"READY","",'Input Required'!F36/1) | F23: =IF('Input Required'!$B$3<>"READY","",'Input Required'!F37/1) | G23: =IF('Input Required'!$B$3<>"READY","",'Input Required'!F38/1) | H23: =IF('Input Required'!$B$3<>"READY","",'Input Required'!F39/1) | I23: =IF('Input Required'!$B$3<>"READY","",'Input Required'!F40/1)
A24: Total adjusted earnings on filed source basis | B24: =SUM(B10,B12,B14,B16,B18,B20,B22) -> 5525 | C24: =SUM(C10,C12,C14,C16,C18,C20,C22) -> 5796 | D24: =SUM(D10,D12,D14,D16,D18,D20,D22) -> 5943 | E24: =SUM(E10,E12,E14,E16,E18,E20,E22) -> 0 | F24: =SUM(F10,F12,F14,F16,F18,F20,F22) -> 0 | G24: =SUM(G10,G12,G14,G16,G18,G20,G22) -> 0 | H24: =SUM(H10,H12,H14,H16,H18,H20,H22) -> 0 | I24: =SUM(I10,I12,I14,I16,I18,I20,I22) -> 0
A25: Adjusted earnings available to common (after tax) | B25: =B24 -> 5525 | C25: =C24 -> 5796 | D25: =D24 -> 5943 | E25: =E24 -> 0 | F25: =F24 -> 0 | G25: =G24 -> 0 | H25: =H24 -> 0 | I25: =I24 -> 0
A26: MET filed adjusted earnings are already after tax and are not taxed again.
A28: Statutory-capital retention and distributable-earnings schedule
A30: Net statutory-capital addition / (release) | E30: =IF('Input Required'!$B$3<>"READY","",'Input Required'!F41/1000000) | F30: =IF('Input Required'!$B$3<>"READY","",'Input Required'!F42/1000000) | G30: =IF('Input Required'!$B$3<>"READY","",'Input Required'!F43/1000000) | H30: =IF('Input Required'!$B$3<>"READY","",'Input Required'!F44/1000000) | I30: =IF('Input Required'!$B$3<>"READY","",'Input Required'!F45/1000000)
A31: Cash available before upstream limit | E31: =IF('Input Required'!$B$3<>"READY","",E25-E30) | F31: =IF('Input Required'!$B$3<>"READY","",F25-F30) | G31: =IF('Input Required'!$B$3<>"READY","",G25-G30) | H31: =IF('Input Required'!$B$3<>"READY","",H25-H30) | I31: =IF('Input Required'!$B$3<>"READY","",I25-I30)
A32: Permitted upstream dividend capacity | E32: =IF('Input Required'!$B$3<>"READY","",'Input Required'!F46/1000000) | F32: =IF('Input Required'!$B$3<>"READY","",'Input Required'!F47/1000000) | G32: =IF('Input Required'!$B$3<>"READY","",'Input Required'!F48/1000000) | H32: =IF('Input Required'!$B$3<>"READY","",'Input Required'!F49/1000000) | I32: =IF('Input Required'!$B$3<>"READY","",'Input Required'!F50/1000000)
A33: Distributable earnings | E33: =IF('Input Required'!$B$3<>"READY","",IF(E31<0,E31,MIN(E31,E32))) | F33: =IF('Input Required'!$B$3<>"READY","",IF(F31<0,F31,MIN(F31,F32))) | G33: =IF('Input Required'!$B$3<>"READY","",IF(G31<0,G31,MIN(G31,G32))) | H33: =IF('Input Required'!$B$3<>"READY","",IF(H31<0,H31,MIN(H31,H32))) | I33: =IF('Input Required'!$B$3<>"READY","",IF(I31<0,I31,MIN(I31,I32)))
A34: Equity discount factor | E34: =IF('Input Required'!$B$3<>"READY","",1/(1+$K$8)^1) | F34: =IF('Input Required'!$B$3<>"READY","",1/(1+$K$8)^2) | G34: =IF('Input Required'!$B$3<>"READY","",1/(1+$K$8)^3) | H34: =IF('Input Required'!$B$3<>"READY","",1/(1+$K$8)^4) | I34: =IF('Input Required'!$B$3<>"READY","",1/(1+$K$8)^5)
A35: Present value of distributable earnings | E35: =IF('Input Required'!$B$3<>"READY","",E33*E34) | F35: =IF('Input Required'!$B$3<>"READY","",F33*F34) | G35: =IF('Input Required'!$B$3<>"READY","",G33*G34) | H35: =IF('Input Required'!$B$3<>"READY","",H33*H34) | I35: =IF('Input Required'!$B$3<>"READY","",I33*I34)
A38: Common-equity DCF valuation
A40: Terminal value | B40: =IF($B$4<>"READY","",I33*(1+$K$10)/($K$8-$K$10))
A41: Present value of terminal value | B41: =IF($B$4<>"READY","",B40/(1+$K$8)^5)
A42: Present value of forecast distributable earnings | B42: =IF($B$4<>"READY","",SUM(E35:I35))
A43: Excess parent cash above reserve | B43: =IF($B$4<>"READY","",MAX($K$16-$K$17,0))
A44: Less: parent debt | B44: =IF($B$4<>"READY","",$K$18)
A45: Less: preferred equity | B45: =IF($B$4<>"READY","",$K$19)
...

Sheet Input Required
A1: INCOMPLETE MODEL — METLIFE INC (MET)
A2: Model family: life_insurer_distributable_earnings_dcf. No valuation has been calculated because required inputs are missing.
A3: Model status | B3: =IF(COUNTIF('Data Review'!$C$5:$C$55,"INPUT ERROR")>0,"INPUT ERROR — check required inputs",IF(COUNTIF('Data Review'!$C$5:$C$55,"INPUT REQUIRED")+COUNTIF('Data Review'!$C$5:$C$55,"SOURCE REQUIRED")>0,"INCOMPLETE — fill required inputs","READY")) -> INCOMPLETE — fill required inputs
A5: Input key | B5: Required input | C5: Period | D5: Unit | E5: Why required | F5: Enter value | G5: Source / reference | H5: Source required
A6: life_segment_earnings_growth:Asia | B6: Asia adjusted-earnings growth | C6: FY2026 | D6: ratio | E6: Forecast the issuer's reported earnings measure by segment with a source or analyst rationale. Enter a source or valuation rationale for each input. Forecast FY2026; the source basis remains after-tax adjusted earnings available to common. | H6: Yes
A7: life_segment_earnings_growth:Asia | B7: Asia adjusted-earnings growth | C7: FY2027 | D7: ratio | E7: Forecast the issuer's reported earnings measure by segment with a source or analyst rationale. Enter a source or valuation rationale for each input. Forecast FY2027; the source basis remains after-tax adjusted earnings available to common. | H7: Yes
A8: life_segment_earnings_growth:Asia | B8: Asia adjusted-earnings growth | C8: FY2028 | D8: ratio | E8: Forecast the issuer's reported earnings measure by segment with a source or analyst rationale. Enter a source or valuation rationale for each input. Forecast FY2028; the source basis remains after-tax adjusted earnings available to common. | H8: Yes
A9: life_segment_earnings_growth:Asia | B9: Asia adjusted-earnings growth | C9: FY2029 | D9: ratio | E9: Forecast the issuer's reported earnings measure by segment with a source or analyst rationale. Enter a source or valuation rationale for each input. Forecast FY2029; the source basis remains after-tax adjusted earnings available to common. | H9: Yes
A10: life_segment_earnings_growth:Asia | B10: Asia adjusted-earnings growth | C10: FY2030 | D10: ratio | E10: Forecast the issuer's reported earnings measure by segment with a source or analyst rationale. Enter a source or valuation rationale for each input. Forecast FY2030; the source basis remains after-tax adjusted earnings available to common. | H10: Yes
A11: life_segment_earnings_growth:Corporate & Other | B11: Corporate & Other adjusted-earnings growth | C11: FY2026 | D11: ratio | E11: Forecast the issuer's reported earnings measure by segment with a source or analyst rationale. Enter a source or valuation rationale for each input. Forecast FY2026; the source basis remains after-tax adjusted earnings available to common. | H11: Yes
A12: life_segment_earnings_growth:Corporate & Other | B12: Corporate & Other adjusted-earnings growth | C12: FY2027 | D12: ratio | E12: Forecast the issuer's reported earnings measure by segment with a source or analyst rationale. Enter a source or valuation rationale for each input. Forecast FY2027; the source basis remains after-tax adjusted earnings available to common. | H12: Yes
A13: life_segment_earnings_growth:Corporate & Other | B13: Corporate & Other adjusted-earnings growth | C13: FY2028 | D13: ratio | E13: Forecast the issuer's reported earnings measure by segment with a source or analyst rationale. Enter a source or valuation rationale for each input. Forecast FY2028; the source basis remains after-tax adjusted earnings available to common. | H13: Yes
A14: life_segment_earnings_growth:Corporate & Other | B14: Corporate & Other adjusted-earnings growth | C14: FY2029 | D14: ratio | E14: Forecast the issuer's reported earnings measure by segment with a source or analyst rationale. Enter a source or valuation rationale for each input. Forecast FY2029; the source basis remains after-tax adjusted earnings available to common. | H14: Yes
A15: life_segment_earnings_growth:Corporate & Other | B15: Corporate & Other adjusted-earnings growth | C15: FY2030 | D15: ratio | E15: Forecast the issuer's reported earnings measure by segment with a source or analyst rationale. Enter a source or valuation rationale for each input. Forecast FY2030; the source basis remains after-tax adjusted earnings available to common. | H15: Yes
A16: life_segment_earnings_growth:EMEA | B16: EMEA adjusted-earnings growth | C16: FY2026 | D16: ratio | E16: Forecast the issuer's reported earnings measure by segment with a source or analyst rationale. Enter a source or valuation rationale for each input. Forecast FY2026; the source basis remains after-tax adjusted earnings available to common. | H16: Yes
A17: life_segment_earnings_growth:EMEA | B17: EMEA adjusted-earnings growth | C17: FY2027 | D17: ratio | E17: Forecast the issuer's reported earnings measure by segment with a source or analyst rationale. Enter a source or valuation rationale for each input. Forecast FY2027; the source basis remains after-tax adjusted earnings available to common. | H17: Yes
... A50: life_permitted_upstream_dividends | B50: Maximum upstream dividend capacity | C50: FY2030 | D50: USD actual | E50: Enter source-backed distribution capacity by legal entity or jurisdiction for each forecast year. Enter a source or valuation rationale for each input. Sum only source-supported distributions available to the parent from material statutory entities; preserve jurisdiction-specific approval limits. | H50: Yes
A51: life_parent_cash | B51: Holding-company cash and liquid assets | D51: USD actual | E51: Enter parent-company cash above reserve and parent debt or senior claims with dated source references. Enter a source or valuation rationale for each input. Use parent-company cash, not consolidated insurance-company investment assets. | H51: Yes
A52: life_parent_cash_reserve | B52: Required holding-company cash reserve | D52: USD actual | E52: Enter parent-company cash above reserve and parent debt or senior claims with dated source references. Enter a source or valuation rationale for each input. Use the disclosed company target when available or a clearly documented analyst policy. | H52: Yes
A53: life_parent_debt | B53: Holding-company debt and financing claims | D53: USD actual | E53: Enter parent-company cash above reserve and parent debt or senior claims with dated source references. Enter a source or valuation rationale for each input. Use parent-company debt; exclude insurer operating liabilities. | H53: Yes
A54: life_preferred_equity | B54: Preferred equity claims | D54: USD actual | E54: Enter parent-company cash above reserve and parent debt or senior claims with dated source references. Enter a source or valuation rationale for each input. Enter source-backed preferred equity or zero with a source reference if none is outstanding. | H54: Yes
A55: life_non_controlling_interest | B55: Noncontrolling interest claim | D55: USD actual | E55: Enter parent-company cash above reserve and parent debt or senior claims with dated source references. Enter a source or valuation rationale for each input. Enter the parent-level claim or zero with a source reference if not applicable. | H55: Yes
A56: terminal_growth_rate | B56: Terminal distributable-earnings growth | D56: ratio | E56: Enter terminal growth below the cost of equity and document the source or valuation rationale. Enter a source or valuation rationale for each input. Keep terminal growth at least 0.5% below cost of equity and no greater than 10%. | H56: Yes

Sheet Data Review
A1: Required input review
A2: Fill blue input cells on Input Required. Reported facts require a source reference; missing values are not zero.
A4: Input key | B4: Required input | C4: Status | D4: Source status | E4: Period | F4: Unit | G4: Reason | H4: Workbook cell | I4: Source / reference
A5: life_segment_earnings_growth:Asia | B5: Asia adjusted-earnings growth | C5: =IF('Input Required'!F6="","INPUT REQUIRED",IF(AND('Input Required'!H6="Yes",'Input Required'!G6=""),"SOURCE REQUIRED",IF(OR(AND('Input Required'!F6<>"",NOT(ISNUMBER('Input Required'!F6))),AND(ISNUMBER('Input Required'!F6),'Input Required'!F6<-0.95),AND(ISNUMBER('Input Required'!F6),'Input Required'!F6>2)),"INPUT ERROR","READY"))) -> INPUT REQUIRED | D5: missing | E5: FY2026 | F5: ratio | G5: Forecast the issuer's reported earnings measure by segment with a source or analyst rationale. Enter a source or valuation rationale for each input. Forecast FY2026; the source basis remains after-tax adjusted earnings available to common. | H5: Input Required!F6 | I5: ='Input Required'!G6 -> 0
A6: life_segment_earnings_growth:Asia | B6: Asia adjusted-earnings growth | C6: =IF('Input Required'!F7="","INPUT REQUIRED",IF(AND('Input Required'!H7="Yes",'Input Required'!G7=""),"SOURCE REQUIRED",IF(OR(AND('Input Required'!F7<>"",NOT(ISNUMBER('Input Required'!F7))),AND(ISNUMBER('Input Required'!F7),'Input Required'!F7<-0.95),AND(ISNUMBER('Input Required'!F7),'Input Required'!F7>2)),"INPUT ERROR","READY"))) -> INPUT REQUIRED | D6: missing | E6: FY2027 | F6: ratio | G6: Forecast the issuer's reported earnings measure by segment with a source or analyst rationale. Enter a source or valuation rationale for each input. Forecast FY2027; the source basis remains after-tax adjusted earnings available to common. | H6: Input Required!F7 | I6: ='Input Required'!G7 -> 0
A7: life_segment_earnings_growth:Asia | B7: Asia adjusted-earnings growth | C7: =IF('Input Required'!F8="","INPUT REQUIRED",IF(AND('Input Required'!H8="Yes",'Input Required'!G8=""),"SOURCE REQUIRED",IF(OR(AND('Input Required'!F8<>"",NOT(ISNUMBER('Input Required'!F8))),AND(ISNUMBER('Input Required'!F8),'Input Required'!F8<-0.95),AND(ISNUMBER('Input Required'!F8),'Input Required'!F8>2)),"INPUT ERROR","READY"))) -> INPUT REQUIRED | D7: missing | E7: FY2028 | F7: ratio | G7: Forecast the issuer's reported earnings measure by segment with a source or analyst rationale. Enter a source or valuation rationale for each input. Forecast FY2028; the source basis remains after-tax adjusted earnings available to common. | H7: Input Required!F8 | I7: ='Input Required'!G8 -> 0
A8: life_segment_earnings_growth:Asia | B8: Asia adjusted-earnings growth | C8: =IF('Input Required'!F9="","INPUT REQUIRED",IF(AND('Input Required'!H9="Yes",'Input Required'!G9=""),"SOURCE REQUIRED",IF(OR(AND('Input Required'!F9<>"",NOT(ISNUMBER('Input Required'!F9))),AND(ISNUMBER('Input Required'!F9),'Input Required'!F9<-0.95),AND(ISNUMBER('Input Required'!F9),'Input Required'!F9>2)),"INPUT ERROR","READY"))) -> INPUT REQUIRED | D8: missing | E8: FY2029 | F8: ratio | G8: Forecast the issuer's reported earnings measure by segment with a source or analyst rationale. Enter a source or valuation rationale for each input. Forecast FY2029; the source basis remains after-tax adjusted earnings available to common. | H8: Input Required!F9 | I8: ='Input Required'!G9 -> 0
A9: life_segment_earnings_growth:Asia | B9: Asia adjusted-earnings growth | C9: =IF('Input Required'!F10="","INPUT REQUIRED",IF(AND('Input Required'!H10="Yes",'Input Required'!G10=""),"SOURCE REQUIRED",IF(OR(AND('Input Required'!F10<>"",NOT(ISNUMBER('Input Required'!F10))),AND(ISNUMBER('Input Required'!F10),'Input Required'!F10<-0.95),AND(ISNUMBER('Input Required'!F10),'Input Required'!F10>2)),"INPUT ERROR","READY"))) -> INPUT REQUIRED | D9: missing | E9: FY2030 | F9: ratio | G9: Forecast the issuer's reported earnings measure by segment with a source or analyst rationale. Enter a source or valuation rationale for each input. Forecast FY2030; the source basis remains after-tax adjusted earnings available to common. | H9: Input Required!F10 | I9: ='Input Required'!G10 -> 0
A10: life_segment_earnings_growth:Corporate & Other | B10: Corporate & Other adjusted-earnings growth | C10: =IF('Input Required'!F11="","INPUT REQUIRED",IF(AND('Input Required'!H11="Yes",'Input Required'!G11=""),"SOURCE REQUIRED",IF(OR(AND('Input Required'!F11<>"",NOT(ISNUMBER('Input Required'!F11))),AND(ISNUMBER('Input Required'!F11),'Input Required'!F11<-0.95),AND(ISNUMBER('Input Required'!F11),'Input Required'!F11>2)),"INPUT ERROR","READY"))) -> INPUT REQUIRED | D10: missing | E10: FY2026 | F10: ratio | G10: Forecast the issuer's reported earnings measure by segment with a source or analyst rationale. Enter a source or valuation rationale for each input. Forecast FY2026; the source basis remains after-tax adjusted earnings available to common. | H10: Input Required!F11 | I10: ='Input Required'!G11 -> 0
A11: life_segment_earnings_growth:Corporate & Other | B11: Corporate & Other adjusted-earnings growth | C11: =IF('Input Required'!F12="","INPUT REQUIRED",IF(AND('Input Required'!H12="Yes",'Input Required'!G12=""),"SOURCE REQUIRED",IF(OR(AND('Input Required'!F12<>"",NOT(ISNUMBER('Input Required'!F12))),AND(ISNUMBER('Input Required'!F12),'Input Required'!F12<-0.95),AND(ISNUMBER('Input Required'!F12),'Input Required'!F12>2)),"INPUT ERROR","READY"))) -> INPUT REQUIRED | D11: missing | E11: FY2027 | F11: ratio | G11: Forecast the issuer's reported earnings measure by segment with a source or analyst rationale. Enter a source or valuation rationale for each input. Forecast FY2027; the source basis remains after-tax adjusted earnings available to common. | H11: Input Required!F12 | I11: ='Input Required'!G12 -> 0
A12: life_segment_earnings_growth:Corporate & Other | B12: Corporate & Other adjusted-earnings growth | C12: =IF('Input Required'!F13="","INPUT REQUIRED",IF(AND('Input Required'!H13="Yes",'Input Required'!G13=""),"SOURCE REQUIRED",IF(OR(AND('Input Required'!F13<>"",NOT(ISNUMBER('Input Required'!F13))),AND(ISNUMBER('Input Required'!F13),'Input Required'!F13<-0.95),AND(ISNUMBER('Input Required'!F13),'Input Required'!F13>2)),"INPUT ERROR","READY"))) -> INPUT REQUIRED | D12: missing | E12: FY2028 | F12: ratio | G12: Forecast the issuer's reported earnings measure by segment with a source or analyst rationale. Enter a source or valuation rationale for each input. Forecast FY2028; the source basis remains after-tax adjusted earnings available to common. | H12: Input Required!F13 | I12: ='Input Required'!G13 -> 0
A13: life_segment_earnings_growth:Corporate & Other | B13: Corporate & Other adjusted-earnings growth | C13: =IF('Input Required'!F14="","INPUT REQUIRED",IF(AND('Input Required'!H14="Yes",'Input Required'!G14=""),"SOURCE REQUIRED",IF(OR(AND('Input Required'!F14<>"",NOT(ISNUMBER('Input Required'!F14))),AND(ISNUMBER('Input Required'!F14),'Input Required'!F14<-0.95),AND(ISNUMBER('Input Required'!F14),'Input Required'!F14>2)),"INPUT ERROR","READY"))) -> INPUT REQUIRED | D13: missing | E13: FY2029 | F13: ratio | G13: Forecast the issuer's reported earnings measure by segment with a source or analyst rationale. Enter a source or valuation rationale for each input. Forecast FY2029; the source basis remains after-tax adjusted earnings available to common. | H13: Input Required!F14 | I13: ='Input Required'!G14 -> 0
A14: life_segment_earnings_growth:Corporate & Other | B14: Corporate & Other adjusted-earnings growth | C14: =IF('Input Required'!F15="","INPUT REQUIRED",IF(AND('Input Required'!H15="Yes",'Input Required'!G15=""),"SOURCE REQUIRED",IF(OR(AND('Input Required'!F15<>"",NOT(ISNUMBER('Input Required'!F15))),AND(ISNUMBER('Input Required'!F15),'Input Required'!F15<-0.95),AND(ISNUMBER('Input Required'!F15),'Input Required'!F15>2)),"INPUT ERROR","READY"))) -> INPUT REQUIRED | D14: missing | E14: FY2030 | F14: ratio | G14: Forecast the issuer's reported earnings measure by segment with a source or analyst rationale. Enter a source or valuation rationale for each input. Forecast FY2030; the source basis remains after-tax adjusted earnings available to common. | H14: Input Required!F15 | I14: ='Input Required'!G15 -> 0
A15: life_segment_earnings_growth:EMEA | B15: EMEA adjusted-earnings growth | C15: =IF('Input Required'!F16="","INPUT REQUIRED",IF(AND('Input Required'!H16="Yes",'Input Required'!G16=""),"SOURCE REQUIRED",IF(OR(AND('Input Required'!F16<>"",NOT(ISNUMBER('Input Required'!F16))),AND(ISNUMBER('Input Required'!F16),'Input Required'!F16<-0.95),AND(ISNUMBER('Input Required'!F16),'Input Required'!F16>2)),"INPUT ERROR","READY"))) -> INPUT REQUIRED | D15: missing | E15: FY2026 | F15: ratio | G15: Forecast the issuer's reported earnings measure by segment with a source or analyst rationale. Enter a source or valuation rationale for each input. Forecast FY2026; the source basis remains after-tax adjusted earnings available to common. | H15: Input Required!F16 | I15: ='Input Required'!G16 -> 0
A16: life_segment_earnings_growth:EMEA | B16: EMEA adjusted-earnings growth | C16: =IF('Input Required'!F17="","INPUT REQUIRED",IF(AND('Input Required'!H17="Yes",'Input Required'!G17=""),"SOURCE REQUIRED",IF(OR(AND('Input Required'!F17<>"",NOT(ISNUMBER('Input Required'!F17))),AND(ISNUMBER('Input Required'!F17),'Input Required'!F17<-0.95),AND(ISNUMBER('Input Required'!F17),'Input Required'!F17>2)),"INPUT ERROR","READY"))) -> INPUT REQUIRED | D16: missing | E16: FY2027 | F16: ratio | G16: Forecast the issuer's reported earnings measure by segment with a source or analyst rationale. Enter a source or valuation rationale for each input. Forecast FY2027; the source basis remains after-tax adjusted earnings available to common. | H16: Input Required!F17 | I16: ='Input Required'!G17 -> 0
... A39: life_segment_earnings_growth:RIS | B39: RIS adjusted-earnings growth | C39: =IF('Input Required'!F40="","INPUT REQUIRED",IF(AND('Input Required'!H40="Yes",'Input Required'!G40=""),"SOURCE REQUIRED",IF(OR(AND('Input Required'!F40<>"",NOT(ISNUMBER('Input Required'!F40))),AND(ISNUMBER('Input Required'!F40),'Input Required'!F40<-0.95),AND(ISNUMBER('Input Required'!F40),'Input Required'!F40>2)),"INPUT ERROR","READY"))) -> INPUT REQUIRED | D39: missing | E39: FY2030 | F39: ratio | G39: Forecast the issuer's reported earnings measure by segment with a source or analyst rationale. Enter a source or valuation rationale for each input. Forecast FY2030; the source basis remains after-tax adjusted earnings available to common. | H39: Input Required!F40 | I39: ='Input Required'!G40 -> 0
A40: life_net_capital_addition | B40: Net statutory capital addition / (release) | C40: =IF('Input Required'!F41="","INPUT REQUIRED",IF(AND('Input Required'!H41="Yes",'Input Required'!G41=""),"SOURCE REQUIRED",IF(OR(AND('Input Required'!F41<>"",NOT(ISNUMBER('Input Required'!F41))),AND(ISNUMBER('Input Required'!F41),'Input Required'!F41<-1000000000000),AND(ISNUMBER('Input Required'!F41),'Input Required'!F41>1000000000000)),"INPUT ERROR","READY"))) -> INPUT REQUIRED | D40: missing | E40: FY2026 | F40: USD actual | G40: Enter capital additions or releases by disclosed capital group; an RBC floor is not an exact capital balance. Enter a source or valuation rationale for each input. Aggregate the material insurer legal entities and jurisdictions. Positive values are retained capital; negative values are capital releases. | H40: Input Required!F41 | I40: ='Input Required'!G41 -> 0
A41: life_net_capital_addition | B41: Net statutory capital addition / (release) | C41: =IF('Input Required'!F42="","INPUT REQUIRED",IF(AND('Input Required'!H42="Yes",'Input Required'!G42=""),"SOURCE REQUIRED",IF(OR(AND('Input Required'!F42<>"",NOT(ISNUMBER('Input Required'!F42))),AND(ISNUMBER('Input Required'!F42),'Input Required'!F42<-1000000000000),AND(ISNUMBER('Input Required'!F42),'Input Required'!F42>1000000000000)),"INPUT ERROR","READY"))) -> INPUT REQUIRED | D41: missing | E41: FY2027 | F41: USD actual | G41: Enter capital additions or releases by disclosed capital group; an RBC floor is not an exact capital balance. Enter a source or valuation rationale for each input. Aggregate the material insurer legal entities and jurisdictions. Positive values are retained capital; negative values are capital releases. | H41: Input Required!F42 | I41: ='Input Required'!G42 -> 0
A42: life_net_capital_addition | B42: Net statutory capital addition / (release) | C42: =IF('Input Required'!F43="","INPUT REQUIRED",IF(AND('Input Required'!H43="Yes",'Input Required'!G43=""),"SOURCE REQUIRED",IF(OR(AND('Input Required'!F43<>"",NOT(ISNUMBER('Input Required'!F43))),AND(ISNUMBER('Input Required'!F43),'Input Required'!F43<-1000000000000),AND(ISNUMBER('Input Required'!F43),'Input Required'!F43>1000000000000)),"INPUT ERROR","READY"))) -> INPUT REQUIRED | D42: missing | E42: FY2028 | F42: USD actual | G42: Enter capital additions or releases by disclosed capital group; an RBC floor is not an exact capital balance. Enter a source or valuation rationale for each input. Aggregate the material insurer legal entities and jurisdictions. Positive values are retained capital; negative values are capital releases. | H42: Input Required!F43 | I42: ='Input Required'!G43 -> 0
A43: life_net_capital_addition | B43: Net statutory capital addition / (release) | C43: =IF('Input Required'!F44="","INPUT REQUIRED",IF(AND('Input Required'!H44="Yes",'Input Required'!G44=""),"SOURCE REQUIRED",IF(OR(AND('Input Required'!F44<>"",NOT(ISNUMBER('Input Required'!F44))),AND(ISNUMBER('Input Required'!F44),'Input Required'!F44<-1000000000000),AND(ISNUMBER('Input Required'!F44),'Input Required'!F44>1000000000000)),"INPUT ERROR","READY"))) -> INPUT REQUIRED | D43: missing | E43: FY2029 | F43: USD actual | G43: Enter capital additions or releases by disclosed capital group; an RBC floor is not an exact capital balance. Enter a source or valuation rationale for each input. Aggregate the material insurer legal entities and jurisdictions. Positive values are retained capital; negative values are capital releases. | H43: Input Required!F44 | I43: ='Input Required'!G44 -> 0
A44: life_net_capital_addition | B44: Net statutory capital addition / (release) | C44: =IF('Input Required'!F45="","INPUT REQUIRED",IF(AND('Input Required'!H45="Yes",'Input Required'!G45=""),"SOURCE REQUIRED",IF(OR(AND('Input Required'!F45<>"",NOT(ISNUMBER('Input Required'!F45))),AND(ISNUMBER('Input Required'!F45),'Input Required'!F45<-1000000000000),AND(ISNUMBER('Input Required'!F45),'Input Required'!F45>1000000000000)),"INPUT ERROR","READY"))) -> INPUT REQUIRED | D44: missing | E44: FY2030 | F44: USD actual | G44: Enter capital additions or releases by disclosed capital group; an RBC floor is not an exact capital balance. Enter a source or valuation rationale for each input. Aggregate the material insurer legal entities and jurisdictions. Positive values are retained capital; negative values are capital releases. | H44: Input Required!F45 | I44: ='Input Required'!G45 -> 0
A45: life_permitted_upstream_dividends | B45: Maximum upstream dividend capacity | C45: =IF('Input Required'!F46="","INPUT REQUIRED",IF(AND('Input Required'!H46="Yes",'Input Required'!G46=""),"SOURCE REQUIRED",IF(OR(AND('Input Required'!F46<>"",NOT(ISNUMBER('Input Required'!F46))),AND(ISNUMBER('Input Required'!F46),'Input Required'!F46<0),AND(ISNUMBER('Input Required'!F46),'Input Required'!F46>1000000000000)),"INPUT ERROR","READY"))) -> INPUT REQUIRED | D45: missing | E45: FY2026 | F45: USD actual | G45: Enter source-backed distribution capacity by legal entity or jurisdiction for each forecast year. Enter a source or valuation rationale for each input. Sum only source-supported distributions available to the parent from material statutory entities; preserve jurisdiction-specific approval limits. | H45: Input Required!F46 | I45: ='Input Required'!G46 -> 0
A46: life_permitted_upstream_dividends | B46: Maximum upstream dividend capacity | C46: =IF('Input Required'!F47="","INPUT REQUIRED",IF(AND('Input Required'!H47="Yes",'Input Required'!G47=""),"SOURCE REQUIRED",IF(OR(AND('Input Required'!F47<>"",NOT(ISNUMBER('Input Required'!F47))),AND(ISNUMBER('Input Required'!F47),'Input Required'!F47<0),AND(ISNUMBER('Input Required'!F47),'Input Required'!F47>1000000000000)),"INPUT ERROR","READY"))) -> INPUT REQUIRED | D46: missing | E46: FY2027 | F46: USD actual | G46: Enter source-backed distribution capacity by legal entity or jurisdiction for each forecast year. Enter a source or valuation rationale for each input. Sum only source-supported distributions available to the parent from material statutory entities; preserve jurisdiction-specific approval limits. | H46: Input Required!F47 | I46: ='Input Required'!G47 -> 0
A47: life_permitted_upstream_dividends | B47: Maximum upstream dividend capacity | C47: =IF('Input Required'!F48="","INPUT REQUIRED",IF(AND('Input Required'!H48="Yes",'Input Required'!G48=""),"SOURCE REQUIRED",IF(OR(AND('Input Required'!F48<>"",NOT(ISNUMBER('Input Required'!F48))),AND(ISNUMBER('Input Required'!F48),'Input Required'!F48<0),AND(ISNUMBER('Input Required'!F48),'Input Required'!F48>1000000000000)),"INPUT ERROR","READY"))) -> INPUT REQUIRED | D47: missing | E47: FY2028 | F47: USD actual | G47: Enter source-backed distribution capacity by legal entity or jurisdiction for each forecast year. Enter a source or valuation rationale for each input. Sum only source-supported distributions available to the parent from material statutory entities; preserve jurisdiction-specific approval limits. | H47: Input Required!F48 | I47: ='Input Required'!G48 -> 0
A48: life_permitted_upstream_dividends | B48: Maximum upstream dividend capacity | C48: =IF('Input Required'!F49="","INPUT REQUIRED",IF(AND('Input Required'!H49="Yes",'Input Required'!G49=""),"SOURCE REQUIRED",IF(OR(AND('Input Required'!F49<>"",NOT(ISNUMBER('Input Required'!F49))),AND(ISNUMBER('Input Required'!F49),'Input Required'!F49<0),AND(ISNUMBER('Input Required'!F49),'Input Required'!F49>1000000000000)),"INPUT ERROR","READY"))) -> INPUT REQUIRED | D48: missing | E48: FY2029 | F48: USD actual | G48: Enter source-backed distribution capacity by legal entity or jurisdiction for each forecast year. Enter a source or valuation rationale for each input. Sum only source-supported distributions available to the parent from material statutory entities; preserve jurisdiction-specific approval limits. | H48: Input Required!F49 | I48: ='Input Required'!G49 -> 0
A49: life_permitted_upstream_dividends | B49: Maximum upstream dividend capacity | C49: =IF('Input Required'!F50="","INPUT REQUIRED",IF(AND('Input Required'!H50="Yes",'Input Required'!G50=""),"SOURCE REQUIRED",IF(OR(AND('Input Required'!F50<>"",NOT(ISNUMBER('Input Required'!F50))),AND(ISNUMBER('Input Required'!F50),'Input Required'!F50<0),AND(ISNUMBER('Input Required'!F50),'Input Required'!F50>1000000000000)),"INPUT ERROR","READY"))) -> INPUT REQUIRED | D49: missing | E49: FY2030 | F49: USD actual | G49: Enter source-backed distribution capacity by legal entity or jurisdiction for each forecast year. Enter a source or valuation rationale for each input. Sum only source-supported distributions available to the parent from material statutory entities; preserve jurisdiction-specific approval limits. | H49: Input Required!F50 | I49: ='Input Required'!G50 -> 0
A50: life_parent_cash | B50: Holding-company cash and liquid assets | C50: =IF('Input Required'!F51="","INPUT REQUIRED",IF(AND('Input Required'!H51="Yes",'Input Required'!G51=""),"SOURCE REQUIRED",IF(OR(AND('Input Required'!F51<>"",NOT(ISNUMBER('Input Required'!F51))),AND(ISNUMBER('Input Required'!F51),'Input Required'!F51<0),AND(ISNUMBER('Input Required'!F51),'Input Required'!F51>1000000000000)),"INPUT ERROR","READY"))) -> INPUT REQUIRED | D50: missing | F50: USD actual | G50: Enter parent-company cash above reserve and parent debt or senior claims with dated source references. Enter a source or valuation rationale for each input. Use parent-company cash, not consolidated insurance-company investment assets. | H50: Input Required!F51 | I50: ='Input Required'!G51 -> 0
A51: life_parent_cash_reserve | B51: Required holding-company cash reserve | C51: =IF('Input Required'!F52="","INPUT REQUIRED",IF(AND('Input Required'!H52="Yes",'Input Required'!G52=""),"SOURCE REQUIRED",IF(OR(AND('Input Required'!F52<>"",NOT(ISNUMBER('Input Required'!F52))),AND(ISNUMBER('Input Required'!F52),'Input Required'!F52<0),AND(ISNUMBER('Input Required'!F52),'Input Required'!F52>1000000000000)),"INPUT ERROR","READY"))) -> INPUT REQUIRED | D51: missing | F51: USD actual | G51: Enter parent-company cash above reserve and parent debt or senior claims with dated source references. Enter a source or valuation rationale for each input. Use the disclosed company target when available or a clearly documented analyst policy. | H51: Input Required!F52 | I51: ='Input Required'!G52 -> 0
A52: life_parent_debt | B52: Holding-company debt and financing claims | C52: =IF('Input Required'!F53="","INPUT REQUIRED",IF(AND('Input Required'!H53="Yes",'Input Required'!G53=""),"SOURCE REQUIRED",IF(OR(AND('Input Required'!F53<>"",NOT(ISNUMBER('Input Required'!F53))),AND(ISNUMBER('Input Required'!F53),'Input Required'!F53<0),AND(ISNUMBER('Input Required'!F53),'Input Required'!F53>1000000000000)),"INPUT ERROR","READY"))) -> INPUT REQUIRED | D52: missing | F52: USD actual | G52: Enter parent-company cash above reserve and parent debt or senior claims with dated source references. Enter a source or valuation rationale for each input. Use parent-company debt; exclude insurer operating liabilities. | H52: Input Required!F53 | I52: ='Input Required'!G53 -> 0
A53: life_preferred_equity | B53: Preferred equity claims | C53: =IF('Input Required'!F54="","INPUT REQUIRED",IF(AND('Input Required'!H54="Yes",'Input Required'!G54=""),"SOURCE REQUIRED",IF(OR(AND('Input Required'!F54<>"",NOT(ISNUMBER('Input Required'!F54))),AND(ISNUMBER('Input Required'!F54),'Input Required'!F54<0),AND(ISNUMBER('Input Required'!F54),'Input Required'!F54>1000000000000)),"INPUT ERROR","READY"))) -> INPUT REQUIRED | D53: missing | F53: USD actual | G53: Enter parent-company cash above reserve and parent debt or senior claims with dated source references. Enter a source or valuation rationale for each input. Enter source-backed preferred equity or zero with a source reference if none is outstanding. | H53: Input Required!F54 | I53: ='Input Required'!G54 -> 0
A54: life_non_controlling_interest | B54: Noncontrolling interest claim | C54: =IF('Input Required'!F55="","INPUT REQUIRED",IF(AND('Input Required'!H55="Yes",'Input Required'!G55=""),"SOURCE REQUIRED",IF(OR(AND('Input Required'!F55<>"",NOT(ISNUMBER('Input Required'!F55))),AND(ISNUMBER('Input Required'!F55),'Input Required'!F55<0),AND(ISNUMBER('Input Required'!F55),'Input Required'!F55>1000000000000)),"INPUT ERROR","READY"))) -> INPUT REQUIRED | D54: missing | F54: USD actual | G54: Enter parent-company cash above reserve and parent debt or senior claims with dated source references. Enter a source or valuation rationale for each input. Enter the parent-level claim or zero with a source reference if not applicable. | H54: Input Required!F55 | I54: ='Input Required'!G55 -> 0
A55: terminal_growth_rate | B55: Terminal distributable-earnings growth | C55: =IF('Input Required'!F56="","INPUT REQUIRED",IF(AND('Input Required'!H56="Yes",'Input Required'!G56=""),"SOURCE REQUIRED",IF(OR(AND('Input Required'!F56<>"",NOT(ISNUMBER('Input Required'!F56))),AND(ISNUMBER('Input Required'!F56),'Input Required'!F56<0),AND(ISNUMBER('Input Required'!F56),'Input Required'!F56>0.1)),"INPUT ERROR","READY"))) -> INPUT REQUIRED | D55: missing | F55: ratio | G55: Enter terminal growth below the cost of equity and document the source or valuation rationale. Enter a source or valuation rationale for each input. Keep terminal growth at least 0.5% below cost of equity and no greater than 10%. | H55: Input Required!F56 | I55: ='Input Required'!G56 -> 0
A58: SEC-filed life-insurance source facts
A59: Metric | B59: Segment | C59: Capital group / jurisdiction | D59: Fiscal year | E59: Reported value | F59: Unit | G59: Unit scale | H59: Source earnings basis | I59: Comparison | J59: Accession | K59: Filed | L59: Report date | M59: Form | N59: Source statement / table scope
A60: adjusted_earnings_available_to_common | B60: Group Benefits | D60: 2025 | E60: 1692 | F60: USD | G60: millions | H60: after_tax_adjusted_earnings_available_to_common | J60: 0001099219-26-000013 | K60: 2026-02-19 | L60: 2025-12-31 | M60: 10-K | N60: SEC 10-K MD&A, adjusted earnings available to common shareholders by segment; Group Benefits; FY2025; Years Ended December 31, 2025 2024 2023 (In millions) Group Benefits $ 1,692 $ 1,606 $ 1,655 RIS 1,671 1,667 1,708 Asia 1,702 1,621 1,282 Latin America 798 881 840 EMEA 367 283 265 MIM 200 55 70 Corporate & Other (487) (317) (295) Adjusted earnings available to common shareholders $ 5,943 $ 5,796 $ 5,525 Adjusted earnings available to common shareholders on a constant currency basis $ 5,943 $ 5,742 $ 5,430 Adjusted premiums, fees and other revenues $ 57,408 $ 52,379 $ 51,966 Adjusted premiums, fees and other revenues on a constant currency basis $ 57,408 $ 52,178 $ 51,195
A61: adjusted_earnings_available_to_common | B61: Group Benefits | D61: 2024 | E61: 1606 | F61: USD | G61: millions | H61: after_tax_adjusted_earnings_available_to_common | J61: 0001099219-26-000013 | K61: 2026-02-19 | L61: 2025-12-31 | M61: 10-K | N61: SEC 10-K MD&A, adjusted earnings available to common shareholders by segment; Group Benefits; FY2024; Years Ended December 31, 2025 2024 2023 (In millions) Group Benefits $ 1,692 $ 1,606 $ 1,655 RIS 1,671 1,667 1,708 Asia 1,702 1,621 1,282 Latin America 798 881 840 EMEA 367 283 265 MIM 200 55 70 Corporate & Other (487) (317) (295) Adjusted earnings available to common shareholders $ 5,943 $ 5,796 $ 5,525 Adjusted earnings available to common shareholders on a constant currency basis $ 5,943 $ 5,742 $ 5,430 Adjusted premiums, fees and other revenues $ 57,408 $ 52,379 $ 51,966 Adjusted premiums, fees and other revenues on a constant currency basis $ 57,408 $ 52,178 $ 51,195
A62: adjusted_earnings_available_to_common | B62: Group Benefits | D62: 2023 | E62: 1655 | F62: USD | G62: millions | H62: after_tax_adjusted_earnings_available_to_common | J62: 0001099219-26-000013 | K62: 2026-02-19 | L62: 2025-12-31 | M62: 10-K | N62: SEC 10-K MD&A, adjusted earnings available to common shareholders by segment; Group Benefits; FY2023; Years Ended December 31, 2025 2024 2023 (In millions) Group Benefits $ 1,692 $ 1,606 $ 1,655 RIS 1,671 1,667 1,708 Asia 1,702 1,621 1,282 Latin America 798 881 840 EMEA 367 283 265 MIM 200 55 70 Corporate & Other (487) (317) (295) Adjusted earnings available to common shareholders $ 5,943 $ 5,796 $ 5,525 Adjusted earnings available to common shareholders on a constant currency basis $ 5,943 $ 5,742 $ 5,430 Adjusted premiums, fees and other revenues $ 57,408 $ 52,379 $ 51,966 Adjusted premiums, fees and other revenues on a constant currency basis $ 57,408 $ 52,178 $ 51,195
A63: adjusted_earnings_available_to_common | B63: RIS | D63: 2025 | E63: 1671 | F63: USD | G63: millions | H63: after_tax_adjusted_earnings_available_to_common | J63: 0001099219-26-000013 | K63: 2026-02-19 | L63: 2025-12-31 | M63: 10-K | N63: SEC 10-K MD&A, adjusted earnings available to common shareholders by segment; RIS; FY2025; Years Ended December 31, 2025 2024 2023 (In millions) Group Benefits $ 1,692 $ 1,606 $ 1,655 RIS 1,671 1,667 1,708 Asia 1,702 1,621 1,282 Latin America 798 881 840 EMEA 367 283 265 MIM 200 55 70 Corporate & Other (487) (317) (295) Adjusted earnings available to common shareholders $ 5,943 $ 5,796 $ 5,525 Adjusted earnings available to common shareholders on a constant currency basis $ 5,943 $ 5,742 $ 5,430 Adjusted premiums, fees and other revenues $ 57,408 $ 52,379 $ 51,966 Adjusted premiums, fees and other revenues on a constant currency basis $ 57,408 $ 52,178 $ 51,195
A64: adjusted_earnings_available_to_common | B64: RIS | D64: 2024 | E64: 1667 | F64: USD | G64: millions | H64: after_tax_adjusted_earnings_available_to_common | J64: 0001099219-26-000013 | K64: 2026-02-19 | L64: 2025-12-31 | M64: 10-K | N64: SEC 10-K MD&A, adjusted earnings available to common shareholders by segment; RIS; FY2024; Years Ended December 31, 2025 2024 2023 (In millions) Group Benefits $ 1,692 $ 1,606 $ 1,655 RIS 1,671 1,667 1,708 Asia 1,702 1,621 1,282 Latin America 798 881 840 EMEA 367 283 265 MIM 200 55 70 Corporate & Other (487) (317) (295) Adjusted earnings available to common shareholders $ 5,943 $ 5,796 $ 5,525 Adjusted earnings available to common shareholders on a constant currency basis $ 5,943 $ 5,742 $ 5,430 Adjusted premiums, fees and other revenues $ 57,408 $ 52,379 $ 51,966 Adjusted premiums, fees and other revenues on a constant currency basis $ 57,408 $ 52,178 $ 51,195
A65: adjusted_earnings_available_to_common | B65: RIS | D65: 2023 | E65: 1708 | F65: USD | G65: millions | H65: after_tax_adjusted_earnings_available_to_common | J65: 0001099219-26-000013 | K65: 2026-02-19 | L65: 2025-12-31 | M65: 10-K | N65: SEC 10-K MD&A, adjusted earnings available to common shareholders by segment; RIS; FY2023; Years Ended December 31, 2025 2024 2023 (In millions) Group Benefits $ 1,692 $ 1,606 $ 1,655 RIS 1,671 1,667 1,708 Asia 1,702 1,621 1,282 Latin America 798 881 840 EMEA 367 283 265 MIM 200 55 70 Corporate & Other (487) (317) (295) Adjusted earnings available to common shareholders $ 5,943 $ 5,796 $ 5,525 Adjusted earnings available to common shareholders on a constant currency basis $ 5,943 $ 5,742 $ 5,430 Adjusted premiums, fees and other revenues $ 57,408 $ 52,379 $ 51,966 Adjusted premiums, fees and other revenues on a constant currency basis $ 57,408 $ 52,178 $ 51,195
...
