Workbook

Sheet Cover
B7: Deal Overview: | F7: Table of Contents:
B9: Company: | C9: Apple Inc. | F9: Outputs - Base
B10: Industry: | C10: Consumer Electronics | F10: DCF Model - Base (1)
F11: DCF Model - Bull (2)
B12: Scenario | C12: 1 | F12: DCF Model - Bear (3)
F13: WACC
B14: Implied Equity Value - GGM | C14: =CHOOSE($C$12,'DCF Model - Base (1)'!Q111,'DCF Model - Bull (2)'!Q111,'DCF Model - Bear (3)'!Q111) -> 1063996.9 | F14: Comps
B15: Implied Equity Value - Multiples | C15: =CHOOSE($C$12,'DCF Model - Base (1)'!Q98,'DCF Model - Bull (2)'!Q98,'DCF Model - Bear (3)'!Q98) -> 1390376.5 | F15: Data Given (Recalculated)
B17: Implied Upside - GGM | C17: =CHOOSE($C$12,'DCF Model - Base (1)'!Q113,'DCF Model - Bull (2)'!Q113,'DCF Model - Bear (3)'!Q113) -> -0.78151708
B18: Implied Upside - Multiples | C18: =CHOOSE($C$12,'DCF Model - Base (1)'!Q100,'DCF Model - Bull (2)'!Q100,'DCF Model - Bear (3)'!Q100) -> -0.71449776
B20: Last Modified: | C20: 46298
B22: Authors: | F22: Legend:
B24: Name: | F24: xxx | G24: Hard Coded Figure
B25: Email: | F25: xxx | G25: Soft Coded Figure
B26: Phone Number: | F26: xxx | G26: Reference from Preceding Cell
F27: xxx | G27: Change in Formula/Odd Calculation
F28: xxx | G28: Reference from Other Worksheet

Sheet Outputs - Base
B2: Discounted Cash Flow Output
B3: Company Apple Inc.
B4: All $ in USD millions unless otherwise stated
B6: Discounted Cash Flow | H6: FY2021A | I6: FY2022A | J6: FY2023A | K6: FY2024A | L6: FY2025A | M6: FY2026E | N6: FY2027E | O6: FY2028E | P6: FY2029E | Q6: FY2030E
B8: EBIT | H8: =CHOOSE(Cover!$C$12,'DCF Model - Base (1)'!H51,'DCF Model - Bull (2)'!H51,'DCF Model - Bear (3)'!H51) -> 108949 | I8: =CHOOSE(Cover!$C$12,'DCF Model - Base (1)'!I51,'DCF Model - Bull (2)'!I51,'DCF Model - Bear (3)'!I51) -> 119437 | J8: =CHOOSE(Cover!$C$12,'DCF Model - Base (1)'!J51,'DCF Model - Bull (2)'!J51,'DCF Model - Bear (3)'!J51) -> 114301 | K8: =CHOOSE(Cover!$C$12,'DCF Model - Base (1)'!K51,'DCF Model - Bull (2)'!K51,'DCF Model - Bear (3)'!K51) -> 123216 | L8: =CHOOSE(Cover!$C$12,'DCF Model - Base (1)'!L51,'DCF Model - Bull (2)'!L51,'DCF Model - Bear (3)'!L51) -> 133050 | M8: =CHOOSE(Cover!$C$12,'DCF Model - Base (1)'!M51,'DCF Model - Bull (2)'!M51,'DCF Model - Bear (3)'!M51) -> 136666.18 | N8: =CHOOSE(Cover!$C$12,'DCF Model - Base (1)'!N51,'DCF Model - Bull (2)'!N51,'DCF Model - Bear (3)'!N51) -> 140376.44 | O8: =CHOOSE(Cover!$C$12,'DCF Model - Base (1)'!O51,'DCF Model - Bull (2)'!O51,'DCF Model - Bear (3)'!O51) -> 144183.06 | ... Q8: =CHOOSE(Cover!$C$12,'DCF Model - Base (1)'!Q51,'DCF Model - Bull (2)'!Q51,'DCF Model - Bear (3)'!Q51) -> 150648.74
B9: (+) Depreciation & Amortization | H9: =CHOOSE(Cover!$C$12,'DCF Model - Base (1)'!H68,'DCF Model - Bull (2)'!H68,'DCF Model - Bear (3)'!H68) -> 11284 | I9: =CHOOSE(Cover!$C$12,'DCF Model - Base (1)'!I68,'DCF Model - Bull (2)'!I68,'DCF Model - Bear (3)'!I68) -> 11104 | J9: =CHOOSE(Cover!$C$12,'DCF Model - Base (1)'!J68,'DCF Model - Bull (2)'!J68,'DCF Model - Bear (3)'!J68) -> 11519 | K9: =CHOOSE(Cover!$C$12,'DCF Model - Base (1)'!K68,'DCF Model - Bull (2)'!K68,'DCF Model - Bear (3)'!K68) -> 11445 | L9: =CHOOSE(Cover!$C$12,'DCF Model - Base (1)'!L68,'DCF Model - Bull (2)'!L68,'DCF Model - Bear (3)'!L68) -> 11698 | M9: =CHOOSE(Cover!$C$12,'DCF Model - Base (1)'!M68,'DCF Model - Bull (2)'!M68,'DCF Model - Bear (3)'!M68) -> 12526.292 | N9: =CHOOSE(Cover!$C$12,'DCF Model - Base (1)'!N68,'DCF Model - Bull (2)'!N68,'DCF Model - Bear (3)'!N68) -> 12937.154 | O9: =CHOOSE(Cover!$C$12,'DCF Model - Base (1)'!O68,'DCF Model - Bull (2)'!O68,'DCF Model - Bear (3)'!O68) -> 13361.493 | ... Q9: =CHOOSE(Cover!$C$12,'DCF Model - Base (1)'!Q68,'DCF Model - Bull (2)'!Q68,'DCF Model - Bear (3)'!Q68) -> 14116.88
B10: EBITDA | H10: =CHOOSE(Cover!$C$12,'DCF Model - Base (1)'!H54,'DCF Model - Bull (2)'!H54,'DCF Model - Bear (3)'!H54) -> 120233 | I10: =CHOOSE(Cover!$C$12,'DCF Model - Base (1)'!I54,'DCF Model - Bull (2)'!I54,'DCF Model - Bear (3)'!I54) -> 130541 | J10: =CHOOSE(Cover!$C$12,'DCF Model - Base (1)'!J54,'DCF Model - Bull (2)'!J54,'DCF Model - Bear (3)'!J54) -> 125820 | K10: =CHOOSE(Cover!$C$12,'DCF Model - Base (1)'!K54,'DCF Model - Bull (2)'!K54,'DCF Model - Bear (3)'!K54) -> 134661 | L10: =CHOOSE(Cover!$C$12,'DCF Model - Base (1)'!L54,'DCF Model - Bull (2)'!L54,'DCF Model - Bear (3)'!L54) -> 144748 | M10: =CHOOSE(Cover!$C$12,'DCF Model - Base (1)'!M54,'DCF Model - Bull (2)'!M54,'DCF Model - Bear (3)'!M54) -> 149192.47 | N10: =CHOOSE(Cover!$C$12,'DCF Model - Base (1)'!N54,'DCF Model - Bull (2)'!N54,'DCF Model - Bear (3)'!N54) -> 153313.59 | O10: =CHOOSE(Cover!$C$12,'DCF Model - Base (1)'!O54,'DCF Model - Bull (2)'!O54,'DCF Model - Bear (3)'!O54) -> 157544.55 | ... Q10: =CHOOSE(Cover!$C$12,'DCF Model - Base (1)'!Q54,'DCF Model - Bull (2)'!Q54,'DCF Model - Bear (3)'!Q54) -> 164765.62
B12: NOPAT | H12: =CHOOSE(Cover!$C$12,'DCF Model - Base (1)'!H60,'DCF Model - Bull (2)'!H60,'DCF Model - Bear (3)'!H60) -> 91942.059 | I12: =CHOOSE(Cover!$C$12,'DCF Model - Base (1)'!I60,'DCF Model - Bull (2)'!I60,'DCF Model - Bear (3)'!I60) -> 100792.88 | J12: =CHOOSE(Cover!$C$12,'DCF Model - Base (1)'!J60,'DCF Model - Bull (2)'!J60,'DCF Model - Bear (3)'!J60) -> 96458.611 | K12: =CHOOSE(Cover!$C$12,'DCF Model - Base (1)'!K60,'DCF Model - Bull (2)'!K60,'DCF Model - Bear (3)'!K60) -> 103981.98 | L12: =CHOOSE(Cover!$C$12,'DCF Model - Base (1)'!L60,'DCF Model - Bull (2)'!L60,'DCF Model - Bear (3)'!L60) -> 112280.89 | M12: =CHOOSE(Cover!$C$12,'DCF Model - Base (1)'!M60,'DCF Model - Bull (2)'!M60,'DCF Model - Bear (3)'!M60) -> 115332.59 | N12: =CHOOSE(Cover!$C$12,'DCF Model - Base (1)'!N60,'DCF Model - Bull (2)'!N60,'DCF Model - Bear (3)'!N60) -> 118463.67 | O12: =CHOOSE(Cover!$C$12,'DCF Model - Base (1)'!O60,'DCF Model - Bull (2)'!O60,'DCF Model - Bear (3)'!O60) -> 121676.08 | ... Q12: =CHOOSE(Cover!$C$12,'DCF Model - Base (1)'!Q60,'DCF Model - Bull (2)'!Q60,'DCF Model - Bear (3)'!Q60) -> 127132.47
B13: (+) Depreciation | H13: =H9 -> 11284 | I13: =I9 -> 11104 | J13: =J9 -> 11519 | K13: =K9 -> 11445 | L13: =L9 -> 11698 | M13: =M9 -> 12526.292 | N13: =N9 -> 12937.154 | O13: =O9 -> 13361.493 | ... Q13: =Q9 -> 14116.88
B14: (-) Capital Expenditures | H14: =CHOOSE(Cover!$C$12,'DCF Model - Base (1)'!H65,'DCF Model - Bull (2)'!H65,'DCF Model - Bear (3)'!H65) -> -11085 | I14: =CHOOSE(Cover!$C$12,'DCF Model - Base (1)'!I65,'DCF Model - Bull (2)'!I65,'DCF Model - Bear (3)'!I65) -> -10708 | J14: =CHOOSE(Cover!$C$12,'DCF Model - Base (1)'!J65,'DCF Model - Bull (2)'!J65,'DCF Model - Bear (3)'!J65) -> -10959 | K14: =CHOOSE(Cover!$C$12,'DCF Model - Base (1)'!K65,'DCF Model - Bull (2)'!K65,'DCF Model - Bear (3)'!K65) -> -9447 | L14: =CHOOSE(Cover!$C$12,'DCF Model - Base (1)'!L65,'DCF Model - Bull (2)'!L65,'DCF Model - Bear (3)'!L65) -> -12715 | M14: =CHOOSE(Cover!$C$12,'DCF Model - Base (1)'!M65,'DCF Model - Bull (2)'!M65,'DCF Model - Bear (3)'!M65) -> -11935.043 | N14: =CHOOSE(Cover!$C$12,'DCF Model - Base (1)'!N65,'DCF Model - Bull (2)'!N65,'DCF Model - Bear (3)'!N65) -> -12326.513 | O14: =CHOOSE(Cover!$C$12,'DCF Model - Base (1)'!O65,'DCF Model - Bull (2)'!O65,'DCF Model - Bear (3)'!O65) -> -12730.822 | ... Q14: =CHOOSE(Cover!$C$12,'DCF Model - Base (1)'!Q65,'DCF Model - Bull (2)'!Q65,'DCF Model - Bear (3)'!Q65) -> -13450.554
B15: (-) Change in NWC | H15: =CHOOSE(Cover!$C$12,'DCF Model - Base (1)'!H77,'DCF Model - Bull (2)'!H77,'DCF Model - Bear (3)'!H77) | I15: =CHOOSE(Cover!$C$12,'DCF Model - Base (1)'!I77,'DCF Model - Bull (2)'!I77,'DCF Model - Bear (3)'!I77) -> 9080 | J15: =CHOOSE(Cover!$C$12,'DCF Model - Base (1)'!J77,'DCF Model - Bull (2)'!J77,'DCF Model - Bear (3)'!J77) -> -4213 | K15: =CHOOSE(Cover!$C$12,'DCF Model - Base (1)'!K77,'DCF Model - Bull (2)'!K77,'DCF Model - Bear (3)'!K77) -> 1492 | L15: =CHOOSE(Cover!$C$12,'DCF Model - Base (1)'!L77,'DCF Model - Bull (2)'!L77,'DCF Model - Bear (3)'!L77) -> -3899 | M15: =CHOOSE(Cover!$C$12,'DCF Model - Base (1)'!M77,'DCF Model - Bull (2)'!M77,'DCF Model - Bear (3)'!M77) -> 2243.5174 | N15: =CHOOSE(Cover!$C$12,'DCF Model - Base (1)'!N77,'DCF Model - Bull (2)'!N77,'DCF Model - Bear (3)'!N77) -> 872.75937 | O15: =CHOOSE(Cover!$C$12,'DCF Model - Base (1)'!O77,'DCF Model - Bull (2)'!O77,'DCF Model - Bear (3)'!O77) -> 901.38588 | ... Q15: =CHOOSE(Cover!$C$12,'DCF Model - Base (1)'!Q77,'DCF Model - Bull (2)'!Q77,'DCF Model - Bear (3)'!Q77) -> 766.74642
B16: Unlevered Free Cash Flow | H16: =SUM(H12:H15) -> 92141.059 | I16: =SUM(I12:I15) -> 110268.88 | J16: =SUM(J12:J15) -> 92805.611 | K16: =SUM(K12:K15) -> 107471.98 | L16: =SUM(L12:L15) -> 107364.89 | M16: =SUM(M12:M15) -> 118167.35 | N16: =SUM(N12:N15) -> 119947.07 | O16: =SUM(O12:O15) -> 123208.14 | ... Q16: =SUM(Q12:Q15) -> 128565.54
B18: Date of Valuation | E18: =CHOOSE(Cover!$C$12,'DCF Model - Base (1)'!I9,'DCF Model - Bull (2)'!I9,'DCF Model - Bear (3)'!I9) -> 46298
B19: Date For Discounting Cash Flows | M19: =CHOOSE(Cover!$C$12,'DCF Model - Base (1)'!M82,'DCF Model - Bull (2)'!M82,'DCF Model - Bear (3)'!M82) -> 46660 | N19: =CHOOSE(Cover!$C$12,'DCF Model - Base (1)'!N82,'DCF Model - Bull (2)'!N82,'DCF Model - Bear (3)'!N82) -> 47026 | O19: =CHOOSE(Cover!$C$12,'DCF Model - Base (1)'!O82,'DCF Model - Bull (2)'!O82,'DCF Model - Bear (3)'!O82) -> 47391 | P19: =CHOOSE(Cover!$C$12,'DCF Model - Base (1)'!P82,'DCF Model - Bull (2)'!P82,'DCF Model - Bear (3)'!P82) -> 47756 | Q19: =CHOOSE(Cover!$C$12,'DCF Model - Base (1)'!Q82,'DCF Model - Bull (2)'!Q82,'DCF Model - Bear (3)'!Q82) -> 48121
B20: Period, Stub Adjusted | M20: =CHOOSE(Cover!$C$12,'DCF Model - Base (1)'!M83,'DCF Model - Bull (2)'!M83,'DCF Model - Bear (3)'!M83) -> 1 | N20: =CHOOSE(Cover!$C$12,'DCF Model - Base (1)'!N83,'DCF Model - Bull (2)'!N83,'DCF Model - Bear (3)'!N83) -> 2 | O20: =CHOOSE(Cover!$C$12,'DCF Model - Base (1)'!O83,'DCF Model - Bull (2)'!O83,'DCF Model - Bear (3)'!O83) -> 3 | P20: =CHOOSE(Cover!$C$12,'DCF Model - Base (1)'!P83,'DCF Model - Bull (2)'!P83,'DCF Model - Bear (3)'!P83) -> 4 | Q20: =CHOOSE(Cover!$C$12,'DCF Model - Base (1)'!Q83,'DCF Model - Bull (2)'!Q83,'DCF Model - Bear (3)'!Q83) -> 5
B21: Discount Period, Stub and Mid-Year Adjusted | M21: =CHOOSE(Cover!$C$12,'DCF Model - Base (1)'!M84,'DCF Model - Bull (2)'!M84,'DCF Model - Bear (3)'!M84) -> 0.5 | N21: =CHOOSE(Cover!$C$12,'DCF Model - Base (1)'!N84,'DCF Model - Bull (2)'!N84,'DCF Model - Bear (3)'!N84) -> 1.5 | O21: =CHOOSE(Cover!$C$12,'DCF Model - Base (1)'!O84,'DCF Model - Bull (2)'!O84,'DCF Model - Bear (3)'!O84) -> 2.5 | P21: =CHOOSE(Cover!$C$12,'DCF Model - Base (1)'!P84,'DCF Model - Bull (2)'!P84,'DCF Model - Bear (3)'!P84) -> 3.5 | Q21: =CHOOSE(Cover!$C$12,'DCF Model - Base (1)'!Q84,'DCF Model - Bull (2)'!Q84,'DCF Model - Bear (3)'!Q84) -> 4.5
B22: Discount Rate | H22: =CHOOSE(Cover!$C$12,'DCF Model - Base (1)'!$F$12,'DCF Model - Bull (2)'!$F$12,'DCF Model - Bear (3)'!$F$12) -> 0.14162494 | I22: =CHOOSE(Cover!$C$12,'DCF Model - Base (1)'!$F$12,'DCF Model - Bull (2)'!$F$12,'DCF Model - Bear (3)'!$F$12) -> 0.14162494 | J22: =CHOOSE(Cover!$C$12,'DCF Model - Base (1)'!$F$12,'DCF Model - Bull (2)'!$F$12,'DCF Model - Bear (3)'!$F$12) -> 0.14162494 | K22: =CHOOSE(Cover!$C$12,'DCF Model - Base (1)'!$F$12,'DCF Model - Bull (2)'!$F$12,'DCF Model - Bear (3)'!$F$12) -> 0.14162494 | L22: =CHOOSE(Cover!$C$12,'DCF Model - Base (1)'!$F$12,'DCF Model - Bull (2)'!$F$12,'DCF Model - Bear (3)'!$F$12) -> 0.14162494 | M22: =CHOOSE(Cover!$C$12,'DCF Model - Base (1)'!$F$12,'DCF Model - Bull (2)'!$F$12,'DCF Model - Bear (3)'!$F$12) -> 0.14162494 | N22: =CHOOSE(Cover!$C$12,'DCF Model - Base (1)'!$F$12,'DCF Model - Bull (2)'!$F$12,'DCF Model - Bear (3)'!$F$12) -> 0.14162494 | O22: =CHOOSE(Cover!$C$12,'DCF Model - Base (1)'!$F$12,'DCF Model - Bull (2)'!$F$12,'DCF Model - Bear (3)'!$F$12) -> 0.14162494 | ... Q22: =CHOOSE(Cover!$C$12,'DCF Model - Base (1)'!$F$12,'DCF Model - Bull (2)'!$F$12,'DCF Model - Bear (3)'!$F$12) -> 0.14162494
B23: Present Value of Unlevered Free Cash Flow | M23: =M16/(1+M22)^M21 -> 110595.07 | N23: =N16/(1+N22)^N21 -> 98334.177 | O23: =O16/(1+O22)^O21 -> 88477.079 | P23: =P16/(1+P22)^P21 -> 79296.173 | Q23: =Q16/(1+Q22)^Q21 -> 70838.454
B26: EV Calculation - Multiples Method | F26: EV Calculation - GGM | J26: Multiples Method
B27: WACC | D27: =CHOOSE(Cover!$C$12,'DCF Model - Base (1)'!$F$12,'DCF Model - Bull (2)'!$F$12,'DCF Model - Bear (3)'!$F$12) -> 0.14162494 | F27: WACC | H27: =D27 -> 0.14162494 | J27: Terminal Value % of TEV | L27: =D33/D35 -> 0.67010429
B28: Exit Multiple | D28: =CHOOSE(Cover!$C$12,'DCF Model - Base (1)'!$C$16,'DCF Model - Bull (2)'!$C$16,'DCF Model - Bear (3)'!$C$16) -> 10.699147 | F28: Long Term Growth Rate | H28: =CHOOSE(Cover!$C$12,'DCF Model - Base (1)'!$Q$103,'DCF Model - Bull (2)'!$Q$103,'DCF Model - Bear (3)'!$Q$103) -> 0.025 | J28: PV of UFCF % of TEV | L28: =D30/D35 -> 0.32989571
J29: Implied TV Exit EBITDA Multiple | L29: =D35/Q10 -> 8.2335952
B30: PV of UFCF | D30: =SUM(M23:Q23) -> 447540.96 | F30: PV of UFCF | H30: =D30 -> 447540.96
B31: Final Year EBITDA | D31: =Q10 -> 164765.62 | F31: Final Year UFCF × (1 + g) | H31: =Q16*(1+H28) -> 131779.68
B32: Terminal Value | D32: =D31*D28 -> 1762851.6 | F32: Terminal Value | H32: =H31/(D27-H28) -> 1129944.3
B33: PV of Terminal Value | D33: =D32/(1+D27)^Q20 -> 909072.5 | F33: PV of Terminal Value | H33: =H32/(1+H27)^Q20 -> 582692.97
J34: Gordon Growth Method
B35: Enterprise Value | D35: =D33+D30 -> 1356613.5 | F35: Enterprise Value | H35: =H33+H30 -> 1030233.9 | J35: Terminal Value % of TEV | L35: =H33/H35 -> 0.56559288
B36: (-) Outstanding Debt | D36: =-CHOOSE(Cover!$C$12,'DCF Model - Base (1)'!$AA$18,'DCF Model - Bull (2)'!$AA$18,'DCF Model - Bear (3)'!$AA$18) -> -98657 | F36: (-) Outstanding Debt | H36: =D36 -> -98657 | J36: PV of UFCF % of TEV | L36: =H30/H35 -> 0.43440712
B37: (-) Minority Interest and Preferred Equity | D37: =-CHOOSE(Cover!$C$12,'DCF Model - Base (1)'!$F$20,'DCF Model - Bull (2)'!$F$20,'DCF Model - Bear (3)'!$F$20)-CHOOSE(Cover!$C$12,'DCF Model - Base (1)'!$F$21,'DCF Model - Bull (2)'!$F$21,'DCF Model - Bear (3)'!$F$21) -> 0 | F37: (-) Minority Interest and Preferred Equity | H37: =D37 -> 0
B38: (+) Cash and Non-Operating Assets | D38: =CHOOSE(Cover!$C$12,'DCF Model - Base (1)'!$AA$17,'DCF Model - Bull (2)'!$AA$17,'DCF Model - Bear (3)'!$AA$17)+CHOOSE(Cover!$C$12,'DCF Model - Base (1)'!$AA$19,'DCF Model - Bull (2)'!$AA$19,'DCF Model - Bear (3)'!$AA$19) -> 132420 | F38: (+) Cash and Non-Operating Assets | H38: =D38 -> 132420
B40: Implied Equity Value | D40: =SUM(D35:D38) -> 1390376.5 | F40: Implied Equity Value | H40: =SUM(H35:H38) -> 1063996.9 | J40: Blended
B41: Current Equity Value | D41: =CHOOSE(Cover!$C$12,'DCF Model - Base (1)'!$C$11,'DCF Model - Bull (2)'!$C$11,'DCF Model - Bear (3)'!$C$11) -> 4869931.9 | F41: Current Equity Value | H41: =D41 -> 4869931.9 | J41: Terminal Value % of TEV | L41: =AVERAGE(L35,L27) -> 0.61784858
B42: Implied Upside | D42: =D40/D41 - 1 -> -0.71449776 | F42: Implied Upside | H42: =H40/H41 - 1 -> -0.78151708 | J42: PV of UFCF % of TEV | L42: =AVERAGE(L36,L28) -> 0.38215142
B43: Implied Share Price | D43: =D40/'DCF Model - Base (1)'!$I$16 -> 92.662748 | F43: Implied Share Price | H43: =H40/'DCF Model - Base (1)'!$I$16 -> 70.910924

Sheet DCF Model - Base (1)
B2: Discounted Cash Flow Model
B3: Company Apple Inc.
B4: All $ in USD millions unless otherwise stated
B6: Assumptions
B8: Valuation Summary | E8: Operating Assumptions | H8: Other Inputs
B9: Implied Enterprise Value | C9: =Q94 -> 1356613.5 | E9: CapEx % of Revenue | F9: 0.027768114 | H9: Valuation Date | I9: 46298
B10: Implied EV / EBITDA | C10: =IFERROR(C9/L54,0) -> 9.3722432 | E10: NWC intensity overlay % of Revenue | F10: 0 | H10: Closing Date
B11: Current Equity Value | C11: 4869931.9 | E11: Tax Rate | F11: 0.15610002 | H11: Fiscal Year End | I11: 46291
B12: Implied Equity Value | C12: =C9-AA18+AA17+AA19-F20-F21 -> 1390376.5 | E12: WACC | F12: =WACC!D34 -> 0.14162494
B13: Implied Share Price (Gordon Growth) | C13: =Q111/$I$16 -> 70.910924 | E13: D&A % revenue | F13: 0.029143716 | H13: EBIT Margin Convergence (Years) | I13: 5
B14: Implied Share Price (Exit Multiple) | C14: =C12/$I$16 -> 92.662748 | E14: Stage 1 Revenue Growth | F14: 0.0328 | H14: Revenue Growth Stage 1 (Years) | I14: 3
B15: Terminal Assumptions | E15: Starting EBIT Margin | F15: 0.319708 | H15: Revenue Growth Fade (Years) | I15: 4
B16: Exit EBITDA Multiple | C16: 10.699147 | E16: Forecast Gross Margin | F16: 0.45747548 | H16: Diluted Shares (millions) | I16: 15004.697
B17: Cash and Cash Equivalents | C17: 35934 | E17: Steady-State EBIT Margin | F17: 0.31100812 | H17: Current Share Price | I17: 333.69 | AA17: =C17 -> 35934
B18: Income Statement | H18: FY2021A | I18: FY2022A | J18: FY2023A | K18: FY2024A | L18: FY2025A | M18: FY2026E | N18: FY2027E | O18: FY2028E | P18: FY2029E | Q18: FY2030E | S18: FY'21-22A | T18: FY'23-30E | AA18: 98657
E19: Stage 2 Revenue Growth | F19: 0.01968 | AA19: 96486
B20: Total Revenue | E20: Minority Interest | F20: 0 | H20: ='Data Given (Recalculated)'!G12 -> 365817 | I20: ='Data Given (Recalculated)'!H12 -> 394328 | J20: ='Data Given (Recalculated)'!I12 -> 383285 | K20: ='Data Given (Recalculated)'!J12 -> 391035 | L20: ='Data Given (Recalculated)'!K12 -> 416161 | M20: =L20*(1+M21) -> 429811.08 | N20: =M20*(1+N21) -> 443908.88 | O20: =N20*(1+O21) -> 458469.1 | P20: =O20*(1+P21) -> 472003.1 | Q20: =P20*(1+Q21) -> 484388.46 | S20: =IFERROR((I20/H20)^(1/(COLUMNS(H20:I20)-1))-1,"") -> 0.077937876 | T20: =IFERROR((Q20/J20)^(1/(COLUMNS(J20:Q20)-1))-1,"") -> 0.034009591
B21: % growth | E21: Preferred Equity | F21: 0 | H21: ="" | I21: =IFERROR(I20/H20-1,0) -> 0.077937876 | J21: =IFERROR(J20/I20-1,0) -> -0.028004605 | K21: =IFERROR(K20/J20-1,0) -> 0.020219941 | L21: =IFERROR(L20/K20-1,0) -> 0.064255118 | M21: =$F$14+($F$19-$F$14)*MAX(0,MIN(1,(M$83-$I$14)/$I$15)) -> 0.0328 | N21: =$F$14+($F$19-$F$14)*MAX(0,MIN(1,(N$83-$I$14)/$I$15)) -> 0.0328 | O21: =$F$14+($F$19-$F$14)*MAX(0,MIN(1,(O$83-$I$14)/$I$15)) -> 0.0328 | P21: =$F$14+($F$19-$F$14)*MAX(0,MIN(1,(P$83-$I$14)/$I$15)) -> 0.02952 | Q21: =$F$14+($F$19-$F$14)*MAX(0,MIN(1,(Q$83-$I$14)/$I$15)) -> 0.02624
B23: Cost of Revenue
B24: Cost of Revenue | H24: ='Data Given (Recalculated)'!G16 -> 212981 | I24: ='Data Given (Recalculated)'!H16 -> 223546 | J24: ='Data Given (Recalculated)'!I16 -> 214137 | K24: ='Data Given (Recalculated)'!J16 -> 210352 | L24: ='Data Given (Recalculated)'!K16 -> 201436 | M24: =M20*(1-$F$16)-M27 -> 213018.66 | N24: =N20*(1-$F$16)-N27 -> 220005.68 | O24: =O20*(1-$F$16)-O27 -> 227221.86 | P24: =P20*(1-$F$16)-P27 -> 233929.45 | Q24: =Q20*(1-$F$16)-Q27 -> 240067.76 | S24: =IFERROR((I24/H24)^(1/(COLUMNS(H24:I24)-1))-1,"") -> 0.049605364 | T24: =IFERROR((Q24/J24)^(1/(COLUMNS(J24:Q24)-1))-1,"") -> 0.016463369
B25: % of revenue | H25: =IFERROR(H24/H20,0) -> 0.5822064 | I25: =IFERROR(I24/I20,0) -> 0.56690369 | J25: =IFERROR(J24/J20,0) -> 0.5586887 | K25: =IFERROR(K24/K20,0) -> 0.5379365 | L25: =IFERROR(L24/L20,0) -> 0.48403382 | M25: =IFERROR(M24/M20,0) -> 0.49560999 | N25: =IFERROR(N24/N20,0) -> 0.49560999 | O25: =IFERROR(O24/O20,0) -> 0.49560999 | ... Q25: =IFERROR(Q24/Q20,0) -> 0.49560999
B27: Other Cost of Revenue | H27: ='Data Given (Recalculated)'!G17 -> 0 | I27: ='Data Given (Recalculated)'!H17 -> 0 | J27: ='Data Given (Recalculated)'!I17 -> 0 | K27: ='Data Given (Recalculated)'!J17 -> 0 | L27: ='Data Given (Recalculated)'!K17 -> 19524 | M27: =M20*L28 -> 20164.387 | N27: =N20*M28 -> 20825.779 | O27: =O20*N28 -> 21508.865 | P27: =P20*O28 -> 22143.806 | Q27: =Q20*P28 -> 22724.86 | S27: =IFERROR((I27/H27)^(1/(COLUMNS(H27:I27)-1))-1,"") | T27: =IFERROR((Q27/J27)^(1/(COLUMNS(J27:Q27)-1))-1,"")
B28: % of revenue | H28: =IFERROR(H27/H20,0) -> 0 | I28: =IFERROR(I27/I20,0) -> 0 | J28: =IFERROR(J27/J20,0) -> 0 | K28: =IFERROR(K27/K20,0) -> 0 | L28: =IFERROR(L27/L20,0) -> 0.046914535 | M28: =IFERROR(M27/M20,0) -> 0.046914535 | N28: =IFERROR(N27/N20,0) -> 0.046914535 | O28: =IFERROR(O27/O20,0) -> 0.046914535 | ... Q28: =IFERROR(Q27/Q20,0) -> 0.046914535
B30: Total Cost of Sales | H30: =H24+H27 -> 212981 | I30: =I24+I27 -> 223546 | J30: =J24+J27 -> 214137 | K30: =K24+K27 -> 210352 | L30: =L24+L27 -> 220960 | M30: =M24+M27 -> 233183.05 | N30: =N24+N27 -> 240831.46 | O30: =O24+O27 -> 248730.73 | ... Q30: =Q24+Q27 -> 262792.62
B32: Gross Profit | H32: =H20-H30 -> 152836 | I32: =I20-I30 -> 170782 | J32: =J20-J30 -> 169148 | K32: =K20-K30 -> 180683 | L32: =L20-L30 -> 195201 | M32: =M20-M30 -> 196628.03 | N32: =N20-N30 -> 203077.43 | O32: =O20-O30 -> 209738.37 | ... Q32: =Q20-Q30 -> 221595.84 | S32: =IFERROR((I32/H32)^(1/(COLUMNS(H32:I32)-1))-1,"") -> 0.11741998 | T32: =IFERROR((Q32/J32)^(1/(COLUMNS(J32:Q32)-1))-1,"") -> 0.039337009
B33: % margin | H33: =IFERROR(H32/H20,0) -> 0.4177936 | I33: =IFERROR(I32/I20,0) -> 0.43309631 | J33: =IFERROR(J32/J20,0) -> 0.4413113 | K33: =IFERROR(K32/K20,0) -> 0.4620635 | L33: =IFERROR(L32/L20,0) -> 0.46905164 | M33: =IFERROR(M32/M20,0) -> 0.45747548 | N33: =IFERROR(N32/N20,0) -> 0.45747548 | O33: =IFERROR(O32/O20,0) -> 0.45747548 | ... Q33: =IFERROR(Q32/Q20,0) -> 0.45747548
B35: Operating Expenses
B36: Research & Development | H36: ='Data Given (Recalculated)'!G24 -> 21914 | I36: ='Data Given (Recalculated)'!H24 -> 26251 | J36: ='Data Given (Recalculated)'!I24 -> 29915 | K36: ='Data Given (Recalculated)'!J24 -> 31370 | L36: ='Data Given (Recalculated)'!K24 -> 34550 | M36: =M20*M37 -> 35683.24 | N36: =N20*N37 -> 36853.65 | O36: =O20*O37 -> 38062.45 | P36: =P20*P37 -> 39186.054 | Q36: =Q20*Q37 -> 40214.296 | S36: =IFERROR((I36/H36)^(1/(COLUMNS(H36:I36)-1))-1,"") -> 0.19791001 | T36: =IFERROR((Q36/J36)^(1/(COLUMNS(J36:Q36)-1))-1,"") -> 0.043172003
B37: % of revenue | H37: =IFERROR(H36/H20,0) -> 0.059904269 | I37: =IFERROR(I36/I20,0) -> 0.066571484 | J37: =IFERROR(J36/J20,0) -> 0.078048971 | K37: =IFERROR(K36/K20,0) -> 0.080222998 | L37: =IFERROR(L36/L20,0) -> 0.083020754 | M37: =L37 -> 0.083020754 | N37: =M37 -> 0.083020754 | O37: =N37 -> 0.083020754 | P37: =O37 -> 0.083020754 | Q37: =P37 -> 0.083020754
B39: SG&A | H39: ='Data Given (Recalculated)'!G25 -> 21973 | I39: ='Data Given (Recalculated)'!H25 -> 25094 | J39: ='Data Given (Recalculated)'!I25 -> 24932 | K39: ='Data Given (Recalculated)'!J25 -> 26097 | L39: ='Data Given (Recalculated)'!K25 -> 27601 | M39: =M20*M40 -> 28506.313 | N39: =N20*N40 -> 29441.32 | O39: =O20*O40 -> 30406.995 | P39: =P20*P40 -> 31304.61 | Q39: =Q20*Q40 -> 32126.043 | S39: =IFERROR((I39/H39)^(1/(COLUMNS(H39:I39)-1))-1,"") -> 0.14203796 | T39: =IFERROR((Q39/J39)^(1/(COLUMNS(J39:Q39)-1))-1,"") -> 0.036880215
B40: % of revenue | H40: =IFERROR(H39/H20,0) -> 0.060065552 | I40: =IFERROR(I39/I20,0) -> 0.063637378 | J40: =IFERROR(J39/J20,0) -> 0.065048202 | K40: =IFERROR(K39/K20,0) -> 0.066738272 | L40: =IFERROR(L39/L20,0) -> 0.066322889 | M40: =L40 -> 0.066322889 | N40: =M40 -> 0.066322889 | O40: =N40 -> 0.066322889 | P40: =O40 -> 0.066322889 | Q40: =P40 -> 0.066322889
B42: D&A (included in Operating) | H42: ='Data Given (Recalculated)'!G26 -> 11284 | I42: ='Data Given (Recalculated)'!H26 -> 11104 | J42: ='Data Given (Recalculated)'!I26 -> 11519 | K42: ='Data Given (Recalculated)'!J26 -> 11445 | L42: ='Data Given (Recalculated)'!K26 -> 11698 | M42: =M20*$F$13 -> 12526.292 | N42: =N20*$F$13 -> 12937.154 | O42: =O20*$F$13 -> 13361.493 | P42: =P20*$F$13 -> 13755.924 | Q42: =Q20*$F$13 -> 14116.88 | S42: =IFERROR((I42/H42)^(1/(COLUMNS(H42:I42)-1))-1,"") -> -0.01595179 | T42: =IFERROR((Q42/J42)^(1/(COLUMNS(J42:Q42)-1))-1,"") -> 0.029479506
B43: % of revenue | H43: =IFERROR(H42/H20,0) -> 0.030846024 | I43: =IFERROR(I42/I20,0) -> 0.028159299 | J43: =IFERROR(J42/J20,0) -> 0.030053355 | K43: =IFERROR(K42/K20,0) -> 0.02926848 | L43: =IFERROR(L42/L20,0) -> 0.028109313 | M43: =L43 -> 0.028109313 | N43: =M43 -> 0.028109313 | O43: =N43 -> 0.028109313 | P43: =O43 -> 0.028109313 | Q43: =P43 -> 0.028109313
B45: Other OpEx / (Income) | H45: ='Data Given (Recalculated)'!G27 -> 0 | I45: ='Data Given (Recalculated)'!H27 -> 0 | J45: ='Data Given (Recalculated)'!I27 -> 0 | K45: ='Data Given (Recalculated)'!J27 -> 0 | L45: ='Data Given (Recalculated)'!K27 -> 0 | M45: =M32-M36-M39-M20*M53 -> -4227.7019 | N45: =N32-N36-N39-N20*N53 -> -3593.9796 | O45: =O32-O36-O39-O20*O53 -> -2914.1368 | P45: =P32-P36-P39-P20*P53 -> -2178.888 | Q45: =Q32-Q36-Q39-Q20*Q53 -> -1393.2376 | S45: =IFERROR((I45/H45)^(1/(COLUMNS(H45:I45)-1))-1,"") | T45: =IFERROR((Q45/J45)^(1/(COLUMNS(J45:Q45)-1))-1,"")
B46: % of revenue | H46: =IFERROR(H45/H20,0) -> 0 | I46: =IFERROR(I45/I20,0) -> 0 | J46: =IFERROR(J45/J20,0) -> 0 | K46: =IFERROR(K45/K20,0) -> 0 | L46: =IFERROR(L45/L20,0) -> 0 | M46: =IFERROR(M45/M20,0) -> -0.0098361865 | N46: =IFERROR(N45/N20,0) -> -0.0080962102 | O46: =IFERROR(O45/O20,0) -> -0.006356234 | ... Q46: =IFERROR(Q45/Q20,0) -> -0.0028762814
B48: Total Operating Expenses | H48: =-(H36+H39+H45) -> -43887 | I48: =-(I36+I39+I45) -> -51345 | J48: =-(J36+J39+J45) -> -54847 | K48: =-(K36+K39+K45) -> -57467 | L48: =-(L36+L39+L45) -> -62151 | M48: =-(M36+M39+M45) -> -59961.851 | N48: =-(N36+N39+N45) -> -62700.99 | O48: =-(O36+O39+O45) -> -65555.308 | ... Q48: =-(Q36+Q39+Q45) -> -70947.101 | S48: =IFERROR((I48/H48)^(1/(COLUMNS(H48:I48)-1))-1,"") -> 0.16993643 | T48: =IFERROR((Q48/J48)^(1/(COLUMNS(J48:Q48)-1))-1,"") -> 0.037453941
B49: % of revenue | H49: =IFERROR(-H48/H20,0) -> 0.11996982 | I49: =IFERROR(-I48/I20,0) -> 0.13020886 | J49: =IFERROR(-J48/J20,0) -> 0.14309717 | K49: =IFERROR(-K48/K20,0) -> 0.14696127 | L49: =IFERROR(-L48/L20,0) -> 0.14934364 | M49: =IFERROR(-M48/M20,0) -> 0.13950746 | N49: =IFERROR(-N48/N20,0) -> 0.14124743 | O49: =IFERROR(-O48/O20,0) -> 0.14298741 | ... Q49: =IFERROR(-Q48/Q20,0) -> 0.14646736
B51: EBIT | H51: =H32+H48 -> 108949 | I51: =I32+I48 -> 119437 | J51: =J32+J48 -> 114301 | K51: =K32+K48 -> 123216 | L51: =L32+L48 -> 133050 | M51: =M32+M48 -> 136666.18 | N51: =N32+N48 -> 140376.44 | O51: =O32+O48 -> 144183.06 | ... Q51: =Q32+Q48 -> 150648.74 | S51: =IFERROR((I51/H51)^(1/(COLUMNS(H51:I51)-1))-1,"") -> 0.096265225 | T51: =IFERROR((Q51/J51)^(1/(COLUMNS(J51:Q51)-1))-1,"") -> 0.040233375
B52: % margin | H52: =IFERROR(H51/H20,0) -> 0.29782378 | I52: =IFERROR(I51/I20,0) -> 0.30288744 | J52: =IFERROR(J51/J20,0) -> 0.29821412 | K52: =IFERROR(K51/K20,0) -> 0.31510223 | L52: =IFERROR(L51/L20,0) -> 0.319708 | M52: =IFERROR(M51/M20,0) -> 0.31796802 | N52: =IFERROR(N51/N20,0) -> 0.31622805 | O52: =IFERROR(O51/O20,0) -> 0.31448807 | ... Q52: =IFERROR(Q51/Q20,0) -> 0.31100812
B53: Forecast EBIT Margin Driver | M53: =IF(M$83<$I$13,$F$15+($F$17-$F$15)*M$83/$I$13,$F$17) -> 0.31796802 | N53: =IF(N$83<$I$13,$F$15+($F$17-$F$15)*N$83/$I$13,$F$17) -> 0.31622805 | O53: =IF(O$83<$I$13,$F$15+($F$17-$F$15)*O$83/$I$13,$F$17) -> 0.31448807 | P53: =IF(P$83<$I$13,$F$15+($F$17-$F$15)*P$83/$I$13,$F$17) -> 0.31274809 | Q53: =IF(Q$83<$I$13,$F$15+($F$17-$F$15)*Q$83/$I$13,$F$17) -> 0.31100812
...

Sheet DCF Model - Bull (2)
B2: Discounted Cash Flow Model
B3: Company Apple Inc.
B4: All $ in USD millions unless otherwise stated
B6: Assumptions
B8: Valuation Summary | E8: Operating Assumptions | H8: Other Inputs
B9: Implied Enterprise Value | C9: =Q94 -> 1601928.3 | E9: CapEx | F9: 0.025268114 | H9: Valuation Date | I9: 46298
B10: Implied EV / EBITDA | C10: =IFERROR(C9/L54,0) -> 11.067015 | E10: Change in NWC | F10: -0.0025 | H10: Closing Date
B11: Current Equity Value | C11: 4869931.9 | E11: Tax Rate | F11: 0.15610002 | H11: Fiscal Year End | I11: 46291
B12: Implied Equity Value | C12: =C9-AA18+AA17+AA19-F20-F21 -> 1635691.3 | E12: WACC | F12: =WACC!D35 -> 0.1334077
B13: Implied Share Price (Gordon Growth) | C13: =Q111/$I$16 -> 84.79197 | E13: D&A % revenue | F13: 0.029143716 | H13: EBIT Margin Convergence (Years) | I13: 5
B14: Implied Share Price (Exit Multiple) | C14: =C12/$I$16 -> 109.01195 | E14: Stage 1 Revenue Growth | F14: 0.0428 | H14: Revenue Growth Stage 1 (Years) | I14: 3
B15: Terminal Assumptions | E15: Starting EBIT Margin | F15: 0.329708 | H15: Revenue Growth Fade (Years) | I15: 4
B16: Exit EBITDA Multiple | C16: 11.699147 | E16: Forecast Gross Margin | F16: 0.45747548 | H16: Diluted Shares (millions) | I16: 15004.697
B17: Cash and Cash Equivalents | C17: 35934 | E17: Steady-State EBIT Margin | F17: 0.32100812 | H17: Current Share Price | I17: 333.69 | AA17: =C17 -> 35934
B18: Income Statement | H18: FY2021A | I18: FY2022A | J18: FY2023A | K18: FY2024A | L18: FY2025A | M18: FY2026E | N18: FY2027E | O18: FY2028E | P18: FY2029E | Q18: FY2030E | S18: FY'21-22A | T18: FY'23-30E | AA18: 98657
E19: Stage 2 Revenue Growth | F19: 0.02968 | AA19: 96486
B20: Total Revenue | F20: 0 | H20: ='Data Given (Recalculated)'!G12 -> 365817 | I20: ='Data Given (Recalculated)'!H12 -> 394328 | J20: ='Data Given (Recalculated)'!I12 -> 383285 | K20: ='Data Given (Recalculated)'!J12 -> 391035 | L20: ='Data Given (Recalculated)'!K12 -> 416161 | M20: =L20*(1+M21) -> 433972.69 | N20: =M20*(1+N21) -> 452546.72 | O20: =N20*(1+O21) -> 471915.72 | P20: =O20*(1+P21) -> 490565.83 | Q20: =P20*(1+Q21) -> 508343.94 | S20: =IFERROR((I20/H20)^(1/(COLUMNS(H20:I20)-1))-1,"") -> 0.077937876 | T20: =IFERROR((Q20/J20)^(1/(COLUMNS(J20:Q20)-1))-1,"") -> 0.041164624
B21: % growth | F21: 0 | H21: ="" | I21: =IFERROR(I20/H20-1,0) -> 0.077937876 | J21: =IFERROR(J20/I20-1,0) -> -0.028004605 | K21: =IFERROR(K20/J20-1,0) -> 0.020219941 | L21: =IFERROR(L20/K20-1,0) -> 0.064255118 | M21: =$F$14+($F$19-$F$14)*MAX(0,MIN(1,(M$83-$I$14)/$I$15)) -> 0.0428 | N21: =$F$14+($F$19-$F$14)*MAX(0,MIN(1,(N$83-$I$14)/$I$15)) -> 0.0428 | O21: =$F$14+($F$19-$F$14)*MAX(0,MIN(1,(O$83-$I$14)/$I$15)) -> 0.0428 | P21: =$F$14+($F$19-$F$14)*MAX(0,MIN(1,(P$83-$I$14)/$I$15)) -> 0.03952 | Q21: =$F$14+($F$19-$F$14)*MAX(0,MIN(1,(Q$83-$I$14)/$I$15)) -> 0.03624
B23: Cost of Revenue
B24: Cost of Revenue | H24: ='Data Given (Recalculated)'!G16 -> 212981 | I24: ='Data Given (Recalculated)'!H16 -> 223546 | J24: ='Data Given (Recalculated)'!I16 -> 214137 | K24: ='Data Given (Recalculated)'!J16 -> 210352 | L24: ='Data Given (Recalculated)'!K16 -> 201436 | M24: =M20*(1-$F$16)-M27 -> 215081.2 | N24: =N20*(1-$F$16)-N27 -> 224286.67 | O24: =O20*(1-$F$16)-O27 -> 233886.14 | P24: =P20*(1-$F$16)-P27 -> 243129.32 | Q24: =Q20*(1-$F$16)-Q27 -> 251940.33 | S24: =IFERROR((I24/H24)^(1/(COLUMNS(H24:I24)-1))-1,"") -> 0.049605364 | T24: =IFERROR((Q24/J24)^(1/(COLUMNS(J24:Q24)-1))-1,"") -> 0.023496988
B25: % of revenue | H25: =IFERROR(H24/H20,0) -> 0.5822064 | I25: =IFERROR(I24/I20,0) -> 0.56690369 | J25: =IFERROR(J24/J20,0) -> 0.5586887 | K25: =IFERROR(K24/K20,0) -> 0.5379365 | L25: =IFERROR(L24/L20,0) -> 0.48403382 | M25: =IFERROR(M24/M20,0) -> 0.49560999 | N25: =IFERROR(N24/N20,0) -> 0.49560999 | O25: =IFERROR(O24/O20,0) -> 0.49560999 | ... Q25: =IFERROR(Q24/Q20,0) -> 0.49560999
B27: Other Cost of Revenue | H27: ='Data Given (Recalculated)'!G17 -> 0 | I27: ='Data Given (Recalculated)'!H17 -> 0 | J27: ='Data Given (Recalculated)'!I17 -> 0 | K27: ='Data Given (Recalculated)'!J17 -> 0 | L27: ='Data Given (Recalculated)'!K17 -> 19524 | M27: =M20*L28 -> 20359.627 | N27: =N20*M28 -> 21231.019 | O27: =O20*N28 -> 22139.707 | P27: =P20*O28 -> 23014.668 | Q27: =Q20*P28 -> 23848.72 | S27: =IFERROR((I27/H27)^(1/(COLUMNS(H27:I27)-1))-1,"") | T27: =IFERROR((Q27/J27)^(1/(COLUMNS(J27:Q27)-1))-1,"")
B28: % of revenue | H28: =IFERROR(H27/H20,0) -> 0 | I28: =IFERROR(I27/I20,0) -> 0 | J28: =IFERROR(J27/J20,0) -> 0 | K28: =IFERROR(K27/K20,0) -> 0 | L28: =IFERROR(L27/L20,0) -> 0.046914535 | M28: =IFERROR(M27/M20,0) -> 0.046914535 | N28: =IFERROR(N27/N20,0) -> 0.046914535 | O28: =IFERROR(O27/O20,0) -> 0.046914535 | ... Q28: =IFERROR(Q27/Q20,0) -> 0.046914535
B30: Total Cost of Sales | H30: =H24+H27 -> 212981 | I30: =I24+I27 -> 223546 | J30: =J24+J27 -> 214137 | K30: =K24+K27 -> 210352 | L30: =L24+L27 -> 220960 | M30: =M24+M27 -> 235440.83 | N30: =N24+N27 -> 245517.69 | O30: =O24+O27 -> 256025.85 | ... Q30: =Q24+Q27 -> 275789.05
B32: Gross Profit | H32: =H20-H30 -> 152836 | I32: =I20-I30 -> 170782 | J32: =J20-J30 -> 169148 | K32: =K20-K30 -> 180683 | L32: =L20-L30 -> 195201 | M32: =M20-M30 -> 198531.86 | N32: =N20-N30 -> 207029.03 | O32: =O20-O30 -> 215889.87 | ... Q32: =Q20-Q30 -> 232554.89 | S32: =IFERROR((I32/H32)^(1/(COLUMNS(H32:I32)-1))-1,"") -> 0.11741998 | T32: =IFERROR((Q32/J32)^(1/(COLUMNS(J32:Q32)-1))-1,"") -> 0.046528907
B33: % margin | H33: =IFERROR(H32/H20,0) -> 0.4177936 | I33: =IFERROR(I32/I20,0) -> 0.43309631 | J33: =IFERROR(J32/J20,0) -> 0.4413113 | K33: =IFERROR(K32/K20,0) -> 0.4620635 | L33: =IFERROR(L32/L20,0) -> 0.46905164 | M33: =IFERROR(M32/M20,0) -> 0.45747548 | N33: =IFERROR(N32/N20,0) -> 0.45747548 | O33: =IFERROR(O32/O20,0) -> 0.45747548 | ... Q33: =IFERROR(Q32/Q20,0) -> 0.45747548
B35: Operating Expenses
B36: Research & Development | H36: ='Data Given (Recalculated)'!G24 -> 21914 | I36: ='Data Given (Recalculated)'!H24 -> 26251 | J36: ='Data Given (Recalculated)'!I24 -> 29915 | K36: ='Data Given (Recalculated)'!J24 -> 31370 | L36: ='Data Given (Recalculated)'!K24 -> 34550 | M36: =M20*M37 -> 36028.74 | N36: =N20*N37 -> 37570.77 | O36: =O20*O37 -> 39178.799 | P36: =P20*P37 -> 40727.145 | Q36: =Q20*Q37 -> 42203.097 | S36: =IFERROR((I36/H36)^(1/(COLUMNS(H36:I36)-1))-1,"") -> 0.19791001 | T36: =IFERROR((Q36/J36)^(1/(COLUMNS(J36:Q36)-1))-1,"") -> 0.050390437
B37: % of revenue | H37: =IFERROR(H36/H20,0) -> 0.059904269 | I37: =IFERROR(I36/I20,0) -> 0.066571484 | J37: =IFERROR(J36/J20,0) -> 0.078048971 | K37: =IFERROR(K36/K20,0) -> 0.080222998 | L37: =IFERROR(L36/L20,0) -> 0.083020754 | M37: =L37 -> 0.083020754 | N37: =M37 -> 0.083020754 | O37: =N37 -> 0.083020754 | P37: =O37 -> 0.083020754 | Q37: =P37 -> 0.083020754
B39: SG&A | H39: ='Data Given (Recalculated)'!G25 -> 21973 | I39: ='Data Given (Recalculated)'!H25 -> 25094 | J39: ='Data Given (Recalculated)'!I25 -> 24932 | K39: ='Data Given (Recalculated)'!J25 -> 26097 | L39: ='Data Given (Recalculated)'!K25 -> 27601 | M39: =M20*M40 -> 28782.323 | N39: =N20*N40 -> 30014.206 | O39: =O20*O40 -> 31298.814 | P39: =P20*P40 -> 32535.743 | Q39: =Q20*Q40 -> 33714.839 | S39: =IFERROR((I39/H39)^(1/(COLUMNS(H39:I39)-1))-1,"") -> 0.14203796 | T39: =IFERROR((Q39/J39)^(1/(COLUMNS(J39:Q39)-1))-1,"") -> 0.044055112
B40: % of revenue | H40: =IFERROR(H39/H20,0) -> 0.060065552 | I40: =IFERROR(I39/I20,0) -> 0.063637378 | J40: =IFERROR(J39/J20,0) -> 0.065048202 | K40: =IFERROR(K39/K20,0) -> 0.066738272 | L40: =IFERROR(L39/L20,0) -> 0.066322889 | M40: =L40 -> 0.066322889 | N40: =M40 -> 0.066322889 | O40: =N40 -> 0.066322889 | P40: =O40 -> 0.066322889 | Q40: =P40 -> 0.066322889
B42: D&A (included in Operating) | H42: ='Data Given (Recalculated)'!G26 -> 11284 | I42: ='Data Given (Recalculated)'!H26 -> 11104 | J42: ='Data Given (Recalculated)'!I26 -> 11519 | K42: ='Data Given (Recalculated)'!J26 -> 11445 | L42: ='Data Given (Recalculated)'!K26 -> 11698 | M42: =M20*$F$13 -> 12647.577 | N42: =N20*$F$13 -> 13188.893 | O42: =O20*$F$13 -> 13753.378 | P42: =P20*$F$13 -> 14296.911 | Q42: =Q20*$F$13 -> 14815.031 | S42: =IFERROR((I42/H42)^(1/(COLUMNS(H42:I42)-1))-1,"") -> -0.01595179 | T42: =IFERROR((Q42/J42)^(1/(COLUMNS(J42:Q42)-1))-1,"") -> 0.036603193
B43: % of revenue | H43: =IFERROR(H42/H20,0) -> 0.030846024 | I43: =IFERROR(I42/I20,0) -> 0.028159299 | J43: =IFERROR(J42/J20,0) -> 0.030053355 | K43: =IFERROR(K42/K20,0) -> 0.02926848 | L43: =IFERROR(L42/L20,0) -> 0.028109313 | M43: =L43 -> 0.028109313 | N43: =M43 -> 0.028109313 | O43: =N43 -> 0.028109313 | P43: =O43 -> 0.028109313 | Q43: =P43 -> 0.028109313
B45: Other OpEx / (Income) | H45: ='Data Given (Recalculated)'!G27 -> 0 | I45: ='Data Given (Recalculated)'!H27 -> 0 | J45: ='Data Given (Recalculated)'!I27 -> 0 | K45: ='Data Given (Recalculated)'!J27 -> 0 | L45: ='Data Given (Recalculated)'!K27 -> 0 | M45: =M32-M36-M39-M20*M53 -> -8608.3632 | N45: =N32-N36-N39-N20*N53 -> -8189.3806 | O45: =O32-O36-O39-O20*O53 -> -7718.764 | P45: =P32-P36-P39-P20*P53 -> -7170.2366 | Q45: =Q32-Q36-Q39-Q20*Q53 -> -6545.5796 | S45: =IFERROR((I45/H45)^(1/(COLUMNS(H45:I45)-1))-1,"") | T45: =IFERROR((Q45/J45)^(1/(COLUMNS(J45:Q45)-1))-1,"")
B46: % of revenue | H46: =IFERROR(H45/H20,0) -> 0 | I46: =IFERROR(I45/I20,0) -> 0 | J46: =IFERROR(J45/J20,0) -> 0 | K46: =IFERROR(K45/K20,0) -> 0 | L46: =IFERROR(L45/L20,0) -> 0 | M46: =IFERROR(M45/M20,0) -> -0.019836186 | N46: =IFERROR(N45/N20,0) -> -0.01809621 | O46: =IFERROR(O45/O20,0) -> -0.016356234 | ... Q46: =IFERROR(Q45/Q20,0) -> -0.012876281
B48: Total Operating Expenses | H48: =-(H36+H39+H45) -> -43887 | I48: =-(I36+I39+I45) -> -51345 | J48: =-(J36+J39+J45) -> -54847 | K48: =-(K36+K39+K45) -> -57467 | L48: =-(L36+L39+L45) -> -62151 | M48: =-(M36+M39+M45) -> -56202.7 | N48: =-(N36+N39+N45) -> -59395.596 | O48: =-(O36+O39+O45) -> -62758.849 | ... Q48: =-(Q36+Q39+Q45) -> -69372.356 | S48: =IFERROR((I48/H48)^(1/(COLUMNS(H48:I48)-1))-1,"") -> 0.16993643 | T48: =IFERROR((Q48/J48)^(1/(COLUMNS(J48:Q48)-1))-1,"") -> 0.034132588
B49: % of revenue | H49: =IFERROR(-H48/H20,0) -> 0.11996982 | I49: =IFERROR(-I48/I20,0) -> 0.13020886 | J49: =IFERROR(-J48/J20,0) -> 0.14309717 | K49: =IFERROR(-K48/K20,0) -> 0.14696127 | L49: =IFERROR(-L48/L20,0) -> 0.14934364 | M49: =IFERROR(-M48/M20,0) -> 0.12950746 | N49: =IFERROR(-N48/N20,0) -> 0.13124743 | O49: =IFERROR(-O48/O20,0) -> 0.13298741 | ... Q49: =IFERROR(-Q48/Q20,0) -> 0.13646736
B51: EBIT | H51: =H32+H48 -> 108949 | I51: =I32+I48 -> 119437 | J51: =J32+J48 -> 114301 | K51: =K32+K48 -> 123216 | L51: =L32+L48 -> 133050 | M51: =M32+M48 -> 142329.16 | N51: =N32+N48 -> 147633.43 | O51: =O32+O48 -> 153131.02 | ... Q51: =Q32+Q48 -> 163182.53 | S51: =IFERROR((I51/H51)^(1/(COLUMNS(H51:I51)-1))-1,"") -> 0.096265225 | T51: =IFERROR((Q51/J51)^(1/(COLUMNS(J51:Q51)-1))-1,"") -> 0.052177693
B52: % margin | H52: =IFERROR(H51/H20,0) -> 0.29782378 | I52: =IFERROR(I51/I20,0) -> 0.30288744 | J52: =IFERROR(J51/J20,0) -> 0.29821412 | K52: =IFERROR(K51/K20,0) -> 0.31510223 | L52: =IFERROR(L51/L20,0) -> 0.319708 | M52: =IFERROR(M51/M20,0) -> 0.32796802 | N52: =IFERROR(N51/N20,0) -> 0.32622805 | O52: =IFERROR(O51/O20,0) -> 0.32448807 | ... Q52: =IFERROR(Q51/Q20,0) -> 0.32100812
B53: Forecast EBIT Margin Driver | M53: =IF(M$83<$I$13,$F$15+($F$17-$F$15)*M$83/$I$13,$F$17) -> 0.32796802 | N53: =IF(N$83<$I$13,$F$15+($F$17-$F$15)*N$83/$I$13,$F$17) -> 0.32622805 | O53: =IF(O$83<$I$13,$F$15+($F$17-$F$15)*O$83/$I$13,$F$17) -> 0.32448807 | P53: =IF(P$83<$I$13,$F$15+($F$17-$F$15)*P$83/$I$13,$F$17) -> 0.32274809 | Q53: =IF(Q$83<$I$13,$F$15+($F$17-$F$15)*Q$83/$I$13,$F$17) -> 0.32100812
...

Sheet DCF Model - Bear (3)
B2: Discounted Cash Flow Model
B3: Company Apple Inc.
B4: All $ in USD millions unless otherwise stated
B6: Assumptions
B8: Valuation Summary | E8: Operating Assumptions | H8: Other Inputs
B9: Implied Enterprise Value | C9: =Q94 -> 1144283.6 | E9: CapEx | F9: 0.030268114 | H9: Valuation Date | I9: 46298
B10: Implied EV / EBITDA | C10: =IFERROR(C9/L54,0) -> 7.9053501 | E10: Change in NWC | F10: 0.0025 | H10: Closing Date
B11: Current Equity Value | C11: 4869931.9 | E11: Tax Rate | F11: 0.15610002 | H11: Fiscal Year End | I11: 46291
B12: Implied Equity Value | C12: =C9-AA18+AA17+AA19-F20-F21 -> 1178046.6 | E12: WACC | F12: =WACC!D36 -> 0.14984218
B13: Implied Share Price (Gordon Growth) | C13: =Q111/$I$16 -> 60.032157 | E13: D&A % revenue | F13: 0.029143716 | H13: EBIT Margin Convergence (Years) | I13: 5
B14: Implied Share Price (Exit Multiple) | C14: =C12/$I$16 -> 78.511856 | E14: Stage 1 Revenue Growth | F14: 0.0228 | H14: Revenue Growth Stage 1 (Years) | I14: 3
B15: Terminal Assumptions | E15: Starting EBIT Margin | F15: 0.309708 | H15: Revenue Growth Fade (Years) | I15: 4
B16: Exit EBITDA Multiple | C16: 9.699147 | E16: Forecast Gross Margin | F16: 0.45747548 | H16: Diluted Shares (millions) | I16: 15004.697
B17: Cash and Cash Equivalents | C17: 35934 | E17: Steady-State EBIT Margin | F17: 0.30100812 | H17: Current Share Price | I17: 333.69 | AA17: =C17 -> 35934
B18: Income Statement | H18: FY2021A | I18: FY2022A | J18: FY2023A | K18: FY2024A | L18: FY2025A | M18: FY2026E | N18: FY2027E | O18: FY2028E | P18: FY2029E | Q18: FY2030E | S18: FY'21-22A | T18: FY'23-30E | AA18: 98657
E19: Stage 2 Revenue Growth | F19: 0.00968 | AA19: 96486
B20: Total Revenue | F20: 0 | H20: ='Data Given (Recalculated)'!G12 -> 365817 | I20: ='Data Given (Recalculated)'!H12 -> 394328 | J20: ='Data Given (Recalculated)'!I12 -> 383285 | K20: ='Data Given (Recalculated)'!J12 -> 391035 | L20: ='Data Given (Recalculated)'!K12 -> 416161 | M20: =L20*(1+M21) -> 425649.47 | N20: =M20*(1+N21) -> 435354.28 | O20: =N20*(1+O21) -> 445280.36 | P20: =O20*(1+P21) -> 453972.23 | Q20: =P20*(1+Q21) -> 461344.74 | S20: =IFERROR((I20/H20)^(1/(COLUMNS(H20:I20)-1))-1,"") -> 0.077937876 | T20: =IFERROR((Q20/J20)^(1/(COLUMNS(J20:Q20)-1))-1,"") -> 0.026834698
B21: % growth | F21: 0 | H21: ="" | I21: =IFERROR(I20/H20-1,0) -> 0.077937876 | J21: =IFERROR(J20/I20-1,0) -> -0.028004605 | K21: =IFERROR(K20/J20-1,0) -> 0.020219941 | L21: =IFERROR(L20/K20-1,0) -> 0.064255118 | M21: =$F$14+($F$19-$F$14)*MAX(0,MIN(1,(M$83-$I$14)/$I$15)) -> 0.0228 | N21: =$F$14+($F$19-$F$14)*MAX(0,MIN(1,(N$83-$I$14)/$I$15)) -> 0.0228 | O21: =$F$14+($F$19-$F$14)*MAX(0,MIN(1,(O$83-$I$14)/$I$15)) -> 0.0228 | P21: =$F$14+($F$19-$F$14)*MAX(0,MIN(1,(P$83-$I$14)/$I$15)) -> 0.01952 | Q21: =$F$14+($F$19-$F$14)*MAX(0,MIN(1,(Q$83-$I$14)/$I$15)) -> 0.01624
B23: Cost of Revenue
B24: Cost of Revenue | H24: ='Data Given (Recalculated)'!G16 -> 212981 | I24: ='Data Given (Recalculated)'!H16 -> 223546 | J24: ='Data Given (Recalculated)'!I16 -> 214137 | K24: ='Data Given (Recalculated)'!J16 -> 210352 | L24: ='Data Given (Recalculated)'!K16 -> 201436 | M24: =M20*(1-$F$16)-M27 -> 210956.13 | N24: =N20*(1-$F$16)-N27 -> 215765.93 | O24: =O20*(1-$F$16)-O27 -> 220685.39 | P24: =P20*(1-$F$16)-P27 -> 224993.17 | Q24: =Q20*(1-$F$16)-Q27 -> 228647.06 | S24: =IFERROR((I24/H24)^(1/(COLUMNS(H24:I24)-1))-1,"") -> 0.049605364 | T24: =IFERROR((Q24/J24)^(1/(COLUMNS(J24:Q24)-1))-1,"") -> 0.0094102277
B25: % of revenue | H25: =IFERROR(H24/H20,0) -> 0.5822064 | I25: =IFERROR(I24/I20,0) -> 0.56690369 | J25: =IFERROR(J24/J20,0) -> 0.5586887 | K25: =IFERROR(K24/K20,0) -> 0.5379365 | L25: =IFERROR(L24/L20,0) -> 0.48403382 | M25: =IFERROR(M24/M20,0) -> 0.49560999 | N25: =IFERROR(N24/N20,0) -> 0.49560999 | O25: =IFERROR(O24/O20,0) -> 0.49560999 | ... Q25: =IFERROR(Q24/Q20,0) -> 0.49560999
B27: Other Cost of Revenue | H27: ='Data Given (Recalculated)'!G17 -> 0 | I27: ='Data Given (Recalculated)'!H17 -> 0 | J27: ='Data Given (Recalculated)'!I17 -> 0 | K27: ='Data Given (Recalculated)'!J17 -> 0 | L27: ='Data Given (Recalculated)'!K17 -> 19524 | M27: =M20*L28 -> 19969.147 | N27: =N20*M28 -> 20424.444 | O27: =O20*N28 -> 20890.121 | P27: =P20*O28 -> 21297.896 | Q27: =Q20*P28 -> 21643.774 | S27: =IFERROR((I27/H27)^(1/(COLUMNS(H27:I27)-1))-1,"") | T27: =IFERROR((Q27/J27)^(1/(COLUMNS(J27:Q27)-1))-1,"")
B28: % of revenue | H28: =IFERROR(H27/H20,0) -> 0 | I28: =IFERROR(I27/I20,0) -> 0 | J28: =IFERROR(J27/J20,0) -> 0 | K28: =IFERROR(K27/K20,0) -> 0 | L28: =IFERROR(L27/L20,0) -> 0.046914535 | M28: =IFERROR(M27/M20,0) -> 0.046914535 | N28: =IFERROR(N27/N20,0) -> 0.046914535 | O28: =IFERROR(O27/O20,0) -> 0.046914535 | ... Q28: =IFERROR(Q27/Q20,0) -> 0.046914535
B30: Total Cost of Sales | H30: =H24+H27 -> 212981 | I30: =I24+I27 -> 223546 | J30: =J24+J27 -> 214137 | K30: =K24+K27 -> 210352 | L30: =L24+L27 -> 220960 | M30: =M24+M27 -> 230925.28 | N30: =N24+N27 -> 236190.37 | O30: =O24+O27 -> 241575.51 | ... Q30: =Q24+Q27 -> 250290.83
B32: Gross Profit | H32: =H20-H30 -> 152836 | I32: =I20-I30 -> 170782 | J32: =J20-J30 -> 169148 | K32: =K20-K30 -> 180683 | L32: =L20-L30 -> 195201 | M32: =M20-M30 -> 194724.2 | N32: =N20-N30 -> 199163.91 | O32: =O20-O30 -> 203704.84 | ... Q32: =Q20-Q30 -> 211053.9 | S32: =IFERROR((I32/H32)^(1/(COLUMNS(H32:I32)-1))-1,"") -> 0.11741998 | T32: =IFERROR((Q32/J32)^(1/(COLUMNS(J32:Q32)-1))-1,"") -> 0.03212515
B33: % margin | H33: =IFERROR(H32/H20,0) -> 0.4177936 | I33: =IFERROR(I32/I20,0) -> 0.43309631 | J33: =IFERROR(J32/J20,0) -> 0.4413113 | K33: =IFERROR(K32/K20,0) -> 0.4620635 | L33: =IFERROR(L32/L20,0) -> 0.46905164 | M33: =IFERROR(M32/M20,0) -> 0.45747548 | N33: =IFERROR(N32/N20,0) -> 0.45747548 | O33: =IFERROR(O32/O20,0) -> 0.45747548 | ... Q33: =IFERROR(Q32/Q20,0) -> 0.45747548
B35: Operating Expenses
B36: Research & Development | H36: ='Data Given (Recalculated)'!G24 -> 21914 | I36: ='Data Given (Recalculated)'!H24 -> 26251 | J36: ='Data Given (Recalculated)'!I24 -> 29915 | K36: ='Data Given (Recalculated)'!J24 -> 31370 | L36: ='Data Given (Recalculated)'!K24 -> 34550 | M36: =M20*M37 -> 35337.74 | N36: =N20*N37 -> 36143.44 | O36: =O20*O37 -> 36967.511 | P36: =P20*P37 -> 37689.117 | Q36: =Q20*Q37 -> 38301.188 | S36: =IFERROR((I36/H36)^(1/(COLUMNS(H36:I36)-1))-1,"") -> 0.19791001 | T36: =IFERROR((Q36/J36)^(1/(COLUMNS(J36:Q36)-1))-1,"") -> 0.035933532
B37: % of revenue | H37: =IFERROR(H36/H20,0) -> 0.059904269 | I37: =IFERROR(I36/I20,0) -> 0.066571484 | J37: =IFERROR(J36/J20,0) -> 0.078048971 | K37: =IFERROR(K36/K20,0) -> 0.080222998 | L37: =IFERROR(L36/L20,0) -> 0.083020754 | M37: =L37 -> 0.083020754 | N37: =M37 -> 0.083020754 | O37: =N37 -> 0.083020754 | P37: =O37 -> 0.083020754 | Q37: =P37 -> 0.083020754
B39: SG&A | H39: ='Data Given (Recalculated)'!G25 -> 21973 | I39: ='Data Given (Recalculated)'!H25 -> 25094 | J39: ='Data Given (Recalculated)'!I25 -> 24932 | K39: ='Data Given (Recalculated)'!J25 -> 26097 | L39: ='Data Given (Recalculated)'!K25 -> 27601 | M39: =M20*M40 -> 28230.303 | N39: =N20*N40 -> 28873.954 | O39: =O20*O40 -> 29532.28 | P39: =P20*P40 -> 30108.75 | Q39: =Q20*Q40 -> 30597.716 | S39: =IFERROR((I39/H39)^(1/(COLUMNS(H39:I39)-1))-1,"") -> 0.14203796 | T39: =IFERROR((Q39/J39)^(1/(COLUMNS(J39:Q39)-1))-1,"") -> 0.029685403
B40: % of revenue | H40: =IFERROR(H39/H20,0) -> 0.060065552 | I40: =IFERROR(I39/I20,0) -> 0.063637378 | J40: =IFERROR(J39/J20,0) -> 0.065048202 | K40: =IFERROR(K39/K20,0) -> 0.066738272 | L40: =IFERROR(L39/L20,0) -> 0.066322889 | M40: =L40 -> 0.066322889 | N40: =M40 -> 0.066322889 | O40: =N40 -> 0.066322889 | P40: =O40 -> 0.066322889 | Q40: =P40 -> 0.066322889
B42: D&A (included in Operating) | H42: ='Data Given (Recalculated)'!G26 -> 11284 | I42: ='Data Given (Recalculated)'!H26 -> 11104 | J42: ='Data Given (Recalculated)'!I26 -> 11519 | K42: ='Data Given (Recalculated)'!J26 -> 11445 | L42: ='Data Given (Recalculated)'!K26 -> 11698 | M42: =M20*$F$13 -> 12405.007 | N42: =N20*$F$13 -> 12687.841 | O42: =O20*$F$13 -> 12977.124 | P42: =P20*$F$13 -> 13230.438 | Q42: =Q20*$F$13 -> 13445.3 | S42: =IFERROR((I42/H42)^(1/(COLUMNS(H42:I42)-1))-1,"") -> -0.01595179 | T42: =IFERROR((Q42/J42)^(1/(COLUMNS(J42:Q42)-1))-1,"") -> 0.022336047
B43: % of revenue | H43: =IFERROR(H42/H20,0) -> 0.030846024 | I43: =IFERROR(I42/I20,0) -> 0.028159299 | J43: =IFERROR(J42/J20,0) -> 0.030053355 | K43: =IFERROR(K42/K20,0) -> 0.02926848 | L43: =IFERROR(L42/L20,0) -> 0.028109313 | M43: =L43 -> 0.028109313 | N43: =M43 -> 0.028109313 | O43: =N43 -> 0.028109313 | P43: =O43 -> 0.028109313 | Q43: =P43 -> 0.028109313
B45: Other OpEx / (Income) | H45: ='Data Given (Recalculated)'!G27 -> 0 | I45: ='Data Given (Recalculated)'!H27 -> 0 | J45: ='Data Given (Recalculated)'!I27 -> 0 | K45: ='Data Given (Recalculated)'!J27 -> 0 | L45: ='Data Given (Recalculated)'!K27 -> 0 | M45: =M32-M36-M39-M20*M53 -> 69.727138 | N45: =N32-N36-N39-N20*N53 -> 828.82303 | O45: =O32-O36-O39-O20*O53 -> 1622.4974 | P45: =P32-P36-P39-P20*P53 -> 2444.0695 | Q45: =Q32-Q36-Q39-Q20*Q53 -> 3286.4901 | S45: =IFERROR((I45/H45)^(1/(COLUMNS(H45:I45)-1))-1,"") | T45: =IFERROR((Q45/J45)^(1/(COLUMNS(J45:Q45)-1))-1,"")
B46: % of revenue | H46: =IFERROR(H45/H20,0) -> 0 | I46: =IFERROR(I45/I20,0) -> 0 | J46: =IFERROR(J45/J20,0) -> 0 | K46: =IFERROR(K45/K20,0) -> 0 | L46: =IFERROR(L45/L20,0) -> 0 | M46: =IFERROR(M45/M20,0) -> 0.00016381352 | N46: =IFERROR(N45/N20,0) -> 0.0019037898 | O46: =IFERROR(O45/O20,0) -> 0.003643766 | ... Q46: =IFERROR(Q45/Q20,0) -> 0.0071237186
B48: Total Operating Expenses | H48: =-(H36+H39+H45) -> -43887 | I48: =-(I36+I39+I45) -> -51345 | J48: =-(J36+J39+J45) -> -54847 | K48: =-(K36+K39+K45) -> -57467 | L48: =-(L36+L39+L45) -> -62151 | M48: =-(M36+M39+M45) -> -63637.77 | N48: =-(N36+N39+N45) -> -65846.217 | O48: =-(O36+O39+O45) -> -68122.288 | ... Q48: =-(Q36+Q39+Q45) -> -72185.394 | S48: =IFERROR((I48/H48)^(1/(COLUMNS(H48:I48)-1))-1,"") -> 0.16993643 | T48: =IFERROR((Q48/J48)^(1/(COLUMNS(J48:Q48)-1))-1,"") -> 0.040021579
B49: % of revenue | H49: =IFERROR(-H48/H20,0) -> 0.11996982 | I49: =IFERROR(-I48/I20,0) -> 0.13020886 | J49: =IFERROR(-J48/J20,0) -> 0.14309717 | K49: =IFERROR(-K48/K20,0) -> 0.14696127 | L49: =IFERROR(-L48/L20,0) -> 0.14934364 | M49: =IFERROR(-M48/M20,0) -> 0.14950746 | N49: =IFERROR(-N48/N20,0) -> 0.15124743 | O49: =IFERROR(-O48/O20,0) -> 0.15298741 | ... Q49: =IFERROR(-Q48/Q20,0) -> 0.15646736
B51: EBIT | H51: =H32+H48 -> 108949 | I51: =I32+I48 -> 119437 | J51: =J32+J48 -> 114301 | K51: =K32+K48 -> 123216 | L51: =L32+L48 -> 133050 | M51: =M32+M48 -> 131086.43 | N51: =N32+N48 -> 133317.69 | O51: =O32+O48 -> 135582.56 | ... Q51: =Q32+Q48 -> 138868.51 | S51: =IFERROR((I51/H51)^(1/(COLUMNS(H51:I51)-1))-1,"") -> 0.096265225 | T51: =IFERROR((Q51/J51)^(1/(COLUMNS(J51:Q51)-1))-1,"") -> 0.028203568
B52: % margin | H52: =IFERROR(H51/H20,0) -> 0.29782378 | I52: =IFERROR(I51/I20,0) -> 0.30288744 | J52: =IFERROR(J51/J20,0) -> 0.29821412 | K52: =IFERROR(K51/K20,0) -> 0.31510223 | L52: =IFERROR(L51/L20,0) -> 0.319708 | M52: =IFERROR(M51/M20,0) -> 0.30796802 | N52: =IFERROR(N51/N20,0) -> 0.30622805 | O52: =IFERROR(O51/O20,0) -> 0.30448807 | ... Q52: =IFERROR(Q51/Q20,0) -> 0.30100812
B53: Forecast EBIT Margin Driver | M53: =IF(M$83<$I$13,$F$15+($F$17-$F$15)*M$83/$I$13,$F$17) -> 0.30796802 | N53: =IF(N$83<$I$13,$F$15+($F$17-$F$15)*N$83/$I$13,$F$17) -> 0.30622805 | O53: =IF(O$83<$I$13,$F$15+($F$17-$F$15)*O$83/$I$13,$F$17) -> 0.30448807 | P53: =IF(P$83<$I$13,$F$15+($F$17-$F$15)*P$83/$I$13,$F$17) -> 0.30274809 | Q53: =IF(Q$83<$I$13,$F$15+($F$17-$F$15)*Q$83/$I$13,$F$17) -> 0.30100812
...

Sheet WACC
B2: WACC Calculation
B3: Company Apple Inc.
B4: All $ in USD millions unless otherwise stated
B6: WACC Calculation | F6: Beta Calculation
F7: Company | H7: Levered Beta | I7: Debt ($B) | J7: Equity Value | K7: D/E | L7: Tax Rate | M7: Unlevered Beta | N7: Correlation
B8: Cost of Equity | F8: 1 | G8: =IF(Comps!B8="","",Comps!B8) -> Sony Group Corporation (SONY) | H8: =IF(G8="","",Comps!E8) -> 0.763 | I8: 417.3 | J8: =IF(G8="","",Comps!F8) -> 139235.84 | K8: =IFERROR(IF(J8>0,(I8*1000)/J8,""),"") -> 2.9970733 | L8: 0.265 | M8: =IF(G8="","",IFERROR(H8/(1+(1-L8)*K8),"")) -> 0.23822542 | N8: 0.114
B9: Risk Free Rate (10 Year Treasury Yield) | D9: 0.05277 | F9: 2 | G9: =IF(Comps!B9="","",Comps!B9) -> Dell Technologies Inc. (DELL) | H9: =IF(G9="","",Comps!E9) -> 1.409 | I9: 23 | J9: =IF(G9="","",Comps!F9) -> 357657.38 | K9: =IFERROR(IF(J9>0,(I9*1000)/J9,""),"") -> 0.064307355 | L9: 0.265 | M9: =IF(G9="","",IFERROR(H9/(1+(1-L9)*K9),"")) -> 1.3454081 | N9: 0.469
B10: Equity Risk Premium | D10: 0.083837107 | F10: 3 | G10: =IF(Comps!B10="","",Comps!B10) -> HP Inc. (HPQ) | H10: =IF(G10="","",Comps!E10) -> 1.205 | I10: 2400.6 | J10: =IF(G10="","",Comps!F10) -> 28965.526 | K10: =IFERROR(IF(J10>0,(I10*1000)/J10,""),"") -> 82.877834 | L10: 0.265 | M10: =IF(G10="","",IFERROR(H10/(1+(1-L10)*K10),"")) -> 0.019462101 | N10: 0.277
B11: Levered Beta | D11: 1.085 | F11: 4 | G11: =IF(Comps!B11="","",Comps!B11) -> Logitech International S.A. - R (LOGI) | H11: =IF(G11="","",Comps!E11) -> 0.649 | I11: 14.6 | J11: =IF(G11="","",Comps!F11) -> 14937.407 | K11: =IFERROR(IF(J11>0,(I11*1000)/J11,""),"") -> 0.97741191 | L11: 0.265 | M11: =IF(G11="","",IFERROR(H11/(1+(1-L11)*K11),"")) -> 0.3776774 | N11: 0.258
B12: Average Correlation | D12: =N23 -> 0.2795 | F12: 5 | G12: =IF(Comps!B12="","",Comps!B12) | H12: =IF(G12="","",Comps!E12) | J12: =IF(G12="","",Comps!F12) | K12: =IFERROR(IF(J12>0,(I12*1000)/J12,""),"") | M12: =IF(G12="","",IFERROR(H12/(1+(1-L12)*K12),""))
B13: Total Beta | D13: =D11/D12 -> 3.881932 | F13: 6 | G13: =IF(Comps!B13="","",Comps!B13) | H13: =IF(G13="","",Comps!E13) | J13: =IF(G13="","",Comps!F13) | K13: =IFERROR(IF(J13>0,(I13*1000)/J13,""),"") | M13: =IF(G13="","",IFERROR(H13/(1+(1-L13)*K13),""))
B14: Illiquidity Discount | D14: 0 | F14: Min | H14: =IFERROR(IF(COUNT(H8:H11)>0,MIN(H8:H11),""),"") -> 0.649 | I14: =IFERROR(IF(COUNT(I8:I11)>0,MIN(I8:I11),""),"") -> 14.6 | J14: =IFERROR(IF(COUNT(J8:J11)>0,MIN(J8:J11),""),"") -> 14937.407 | K14: =IFERROR(IF(COUNT(K8:K11)>0,MIN(K8:K11),""),"") -> 0.064307355 | L14: =IFERROR(IF(COUNT(L8:L11)>0,MIN(L8:L11),""),"") -> 0.265 | M14: =IFERROR(IF(COUNT(M8:M11)>0,MIN(M8:M11),""),"") -> 0.019462101 | N14: =IFERROR(IF(COUNT(N8:N11)>0,MIN(N8:N11),""),"") -> 0.114
B15: Size Premium | D15: 0 | F15: 0.25 | H15: =IFERROR(IF(COUNT(H8:H11)>0,SMALL(H8:H11,INT((COUNT(H8:H11)-1)*0.25+1))+((COUNT(H8:H11)-1)*0.25+1-INT((COUNT(H8:H11)-1)*0.25+1))*(SMALL(H8:H11,MIN(COUNT(H8:H11),INT((COUNT(H8:H11)-1)*0.25+1)+1))-SMALL(H8:H11,INT((COUNT(H8:H11)-1)*0.25+1))),""),"") -> 0.7345 | I15: =IFERROR(IF(COUNT(I8:I11)>0,SMALL(I8:I11,INT((COUNT(I8:I11)-1)*0.25+1))+((COUNT(I8:I11)-1)*0.25+1-INT((COUNT(I8:I11)-1)*0.25+1))*(SMALL(I8:I11,MIN(COUNT(I8:I11),INT((COUNT(I8:I11)-1)*0.25+1)+1))-SMALL(I8:I11,INT((COUNT(I8:I11)-1)*0.25+1))),""),"") -> 20.9 | J15: =IFERROR(IF(COUNT(J8:J11)>0,SMALL(J8:J11,INT((COUNT(J8:J11)-1)*0.25+1))+((COUNT(J8:J11)-1)*0.25+1-INT((COUNT(J8:J11)-1)*0.25+1))*(SMALL(J8:J11,MIN(COUNT(J8:J11),INT((COUNT(J8:J11)-1)*0.25+1)+1))-SMALL(J8:J11,INT((COUNT(J8:J11)-1)*0.25+1))),""),"") -> 25458.496 | K15: =IFERROR(IF(COUNT(K8:K11)>0,SMALL(K8:K11,INT((COUNT(K8:K11)-1)*0.25+1))+((COUNT(K8:K11)-1)*0.25+1-INT((COUNT(K8:K11)-1)*0.25+1))*(SMALL(K8:K11,MIN(COUNT(K8:K11),INT((COUNT(K8:K11)-1)*0.25+1)+1))-SMALL(K8:K11,INT((COUNT(K8:K11)-1)*0.25+1))),""),"") -> 0.74913577 | L15: =IFERROR(IF(COUNT(L8:L11)>0,SMALL(L8:L11,INT((COUNT(L8:L11)-1)*0.25+1))+((COUNT(L8:L11)-1)*0.25+1-INT((COUNT(L8:L11)-1)*0.25+1))*(SMALL(L8:L11,MIN(COUNT(L8:L11),INT((COUNT(L8:L11)-1)*0.25+1)+1))-SMALL(L8:L11,INT((COUNT(L8:L11)-1)*0.25+1))),""),"") -> 0.265 | M15: =IFERROR(IF(COUNT(M8:M11)>0,SMALL(M8:M11,INT((COUNT(M8:M11)-1)*0.25+1))+((COUNT(M8:M11)-1)*0.25+1-INT((COUNT(M8:M11)-1)*0.25+1))*(SMALL(M8:M11,MIN(COUNT(M8:M11),INT((COUNT(M8:M11)-1)*0.25+1)+1))-SMALL(M8:M11,INT((COUNT(M8:M11)-1)*0.25+1))),""),"") -> 0.18353459 | N15: =IFERROR(IF(COUNT(N8:N11)>0,SMALL(N8:N11,INT((COUNT(N8:N11)-1)*0.25+1))+((COUNT(N8:N11)-1)*0.25+1-INT((COUNT(N8:N11)-1)*0.25+1))*(SMALL(N8:N11,MIN(COUNT(N8:N11),INT((COUNT(N8:N11)-1)*0.25+1)+1))-SMALL(N8:N11,INT((COUNT(N8:N11)-1)*0.25+1))),""),"") -> 0.222
B16: CAPM/Cost of Equity | D16: =D9+D11*(D10)+D14+D15 -> 0.14373326 | F16: Mean | H16: =IFERROR(IF(COUNT(H8:H11)>0,AVERAGE(H8:H11),1),1) -> 1.0065 | I16: =IFERROR(IF(COUNT(I8:I11)>0,AVERAGE(I8:I11),0),0) -> 713.875 | J16: =IFERROR(IF(COUNT(J8:J11)>0,AVERAGE(J8:J11),0),0) -> 135199.04 | K16: =IFERROR(IF(COUNT(K8:K11)>0,AVERAGE(K8:K11),0),0) -> 21.729157 | L16: =IFERROR(IF(COUNT(L8:L11)>0,AVERAGE(L8:L11),0.25),0.25) -> 0.265 | M16: =IFERROR(IF(COUNT(M8:M11)>0,AVERAGE(M8:M11),1),1) -> 0.49519325 | N16: =IFERROR(IF(COUNT(N8:N11)>0,AVERAGE(N8:N11),1),1) -> 0.2795
F17: Median | H17: =IFERROR(IF(COUNT(H8:H11)>0,MEDIAN(H8:H11),1),1) -> 0.984 | I17: =IFERROR(IF(COUNT(I8:I11)>0,MEDIAN(I8:I11),0),0) -> 220.15 | J17: =IFERROR(IF(COUNT(J8:J11)>0,MEDIAN(J8:J11),0),0) -> 84100.681 | K17: =IFERROR(IF(COUNT(K8:K11)>0,MEDIAN(K8:K11),0),0) -> 1.9872426 | L17: =IFERROR(IF(COUNT(L8:L11)>0,MEDIAN(L8:L11),0.25),0.25) -> 0.265 | M17: =IFERROR(IF(COUNT(M8:M11)>0,MEDIAN(M8:M11),1),1) -> 0.30795141 | N17: =IFERROR(IF(COUNT(N8:N11)>0,MEDIAN(N8:N11),1),1) -> 0.2675
B18: Cost of Debt | F18: 0.75 | H18: =IFERROR(IF(COUNT(H8:H11)>0,SMALL(H8:H11,INT((COUNT(H8:H11)-1)*0.75+1))+((COUNT(H8:H11)-1)*0.75+1-INT((COUNT(H8:H11)-1)*0.75+1))*(SMALL(H8:H11,MIN(COUNT(H8:H11),INT((COUNT(H8:H11)-1)*0.75+1)+1))-SMALL(H8:H11,INT((COUNT(H8:H11)-1)*0.75+1))),""),"") -> 1.256 | I18: =IFERROR(IF(COUNT(I8:I11)>0,SMALL(I8:I11,INT((COUNT(I8:I11)-1)*0.75+1))+((COUNT(I8:I11)-1)*0.75+1-INT((COUNT(I8:I11)-1)*0.75+1))*(SMALL(I8:I11,MIN(COUNT(I8:I11),INT((COUNT(I8:I11)-1)*0.75+1)+1))-SMALL(I8:I11,INT((COUNT(I8:I11)-1)*0.75+1))),""),"") -> 913.125 | J18: =IFERROR(IF(COUNT(J8:J11)>0,SMALL(J8:J11,INT((COUNT(J8:J11)-1)*0.75+1))+((COUNT(J8:J11)-1)*0.75+1-INT((COUNT(J8:J11)-1)*0.75+1))*(SMALL(J8:J11,MIN(COUNT(J8:J11),INT((COUNT(J8:J11)-1)*0.75+1)+1))-SMALL(J8:J11,INT((COUNT(J8:J11)-1)*0.75+1))),""),"") -> 193841.22 | K18: =IFERROR(IF(COUNT(K8:K11)>0,SMALL(K8:K11,INT((COUNT(K8:K11)-1)*0.75+1))+((COUNT(K8:K11)-1)*0.75+1-INT((COUNT(K8:K11)-1)*0.75+1))*(SMALL(K8:K11,MIN(COUNT(K8:K11),INT((COUNT(K8:K11)-1)*0.75+1)+1))-SMALL(K8:K11,INT((COUNT(K8:K11)-1)*0.75+1))),""),"") -> 22.967263 | L18: =IFERROR(IF(COUNT(L8:L11)>0,SMALL(L8:L11,INT((COUNT(L8:L11)-1)*0.75+1))+((COUNT(L8:L11)-1)*0.75+1-INT((COUNT(L8:L11)-1)*0.75+1))*(SMALL(L8:L11,MIN(COUNT(L8:L11),INT((COUNT(L8:L11)-1)*0.75+1)+1))-SMALL(L8:L11,INT((COUNT(L8:L11)-1)*0.75+1))),""),"") -> 0.265 | M18: =IFERROR(IF(COUNT(M8:M11)>0,SMALL(M8:M11,INT((COUNT(M8:M11)-1)*0.75+1))+((COUNT(M8:M11)-1)*0.75+1-INT((COUNT(M8:M11)-1)*0.75+1))*(SMALL(M8:M11,MIN(COUNT(M8:M11),INT((COUNT(M8:M11)-1)*0.75+1)+1))-SMALL(M8:M11,INT((COUNT(M8:M11)-1)*0.75+1))),""),"") -> 0.61961007 | N18: =IFERROR(IF(COUNT(N8:N11)>0,SMALL(N8:N11,INT((COUNT(N8:N11)-1)*0.75+1))+((COUNT(N8:N11)-1)*0.75+1-INT((COUNT(N8:N11)-1)*0.75+1))*(SMALL(N8:N11,MIN(COUNT(N8:N11),INT((COUNT(N8:N11)-1)*0.75+1)+1))-SMALL(N8:N11,INT((COUNT(N8:N11)-1)*0.75+1))),""),"") -> 0.325
B19: Interest Rate on Debt | D19: 0.0445 | F19: Max | H19: =IFERROR(IF(COUNT(H8:H11)>0,MAX(H8:H11),""),"") -> 1.409 | I19: =IFERROR(IF(COUNT(I8:I11)>0,MAX(I8:I11),""),"") -> 2400.6 | J19: =IFERROR(IF(COUNT(J8:J11)>0,MAX(J8:J11),""),"") -> 357657.38 | K19: =IFERROR(IF(COUNT(K8:K11)>0,MAX(K8:K11),""),"") -> 82.877834 | L19: =IFERROR(IF(COUNT(L8:L11)>0,MAX(L8:L11),""),"") -> 0.265 | M19: =IFERROR(IF(COUNT(M8:M11)>0,MAX(M8:M11),""),"") -> 1.3454081 | N19: =IFERROR(IF(COUNT(N8:N11)>0,MAX(N8:N11),""),"") -> 0.469
B20: Tax Rate | D20: =IFERROR('DCF Model - Base (1)'!$F$11,0.21) -> 0.15610002
B21: Cost of Debt Post-Tax | D21: =IFERROR(D19*(1-D20),D19*0.79) -> 0.037553549 | F21: Relevered Beta
F22: Company | H22: Levered Beta | I22: Debt Units | J22: Equity Values Units | K22: Optimal D/E | L22: Tax Rate | M22: Unlevered Beta | N22: Correlation
B23: Total Equity | D23: ='DCF Model - Base (1)'!C11 -> 4869931.9 | F23: ABC Corp. | H23: =M23*(1+(1-L23)*K23) -> 0.75775241 | I23: =IFERROR(D23+D24-J23,D24) -> 3305319.6 | J23: =IFERROR((D23+D24)/(1+K23),D23) -> 1663269.3 | K23: =IFERROR(IF(K17>0,K17,IF(D23>0,D24/D23,0.15)),0.15) -> 1.9872426 | L23: =L16 -> 0.265 | M23: =M17 -> 0.30795141 | N23: =N16 -> 0.2795
B24: Total Debt | D24: ='DCF Model - Base (1)'!AA18 -> 98657
B26: Current Debt/Equity Ratio | D26: =D28/D27 -> 0.020258394
B27: Current Equity/Capital | D27: =IFERROR(D23/(D23+D24),0.85) -> 0.98014386
B28: Current Debt/Capital | D28: =IFERROR(D24/(D23+D24),0.15) -> 0.019856141
B30: Optimal Debt/Equity Ratio | D30: =D32/D31 -> 1.9872426
B31: Optimal Equity/Capital | D31: =IFERROR(J23/(I23+J23),0.85) -> 0.33475688
B32: Optimal Debt/Capital | D32: =IFERROR(I23/(I23+J23),0.15) -> 0.66524312
B34: Base WACC | D34: =(D27*D16)+(D28*D21) -> 0.14162494
B35: Bull WACC | D35: =(D27*D39)+(D28*D21) -> 0.1334077
B36: Bear WACC | D36: =(D27*D40)+(D28*D21) -> 0.14984218
B37: Bull Beta | D37: 0.985
B38: Bear Beta | D38: 1.185
B39: Bull Cost of Equity | D39: =D9+D37*(D10)+D14+D15 -> 0.13534955
B40: Bear Cost of Equity | D40: =D9+D38*(D10)+D14+D15 -> 0.15211697

Sheet Comps
B2: Comparable Companies Analysis
B3: Company Apple Inc.
B4: All $ in USD millions unless otherwise stated
