Workbook

Sheet Biotech Model
A1: Commercial DCF and Pipeline rNPV — MRNA
A2: Moderna, Inc.
A3: Commercial revenue starts from reported consolidated revenue (which can include collaboration and milestone revenue). Pipeline assumptions are blank and analyst-owned.
A4: Model status | B4: =IF('Input Required'!$B$3<>"READY",'Input Required'!$B$3,IF(OR($M$15<2%,$M$15>50%),"INPUT ERROR — WACC outside supported range",IF(OR($M$16>10%,$M$16>$M$15-0.5%),"INPUT ERROR — terminal growth must be at least 0.5% below WACC","READY"))) -> INCOMPLETE — fill required inputs | L4: WACC and market inputs | M4: Value | N4: Source / as-of date
A5: Units: USD millions; diluted shares in millions; per-share value in USD. | L5: Risk-free rate | M5: 0.05277 | N5: live as of 2026-10-03
A6: FY2025 reported consolidated revenue base | B6: 1944 | L6: Equity-risk premium | M6: 0.083837107 | N6: live as of 2026-10-03
L7: Beta | M7: 1.106 | N7: openbb_yfinance as of 2026-10-03
A8: Commercial franchise DCF | L8: Cost of equity | M8: =M5+M7*M6 -> 0.14549384
B9: 2026 | C9: 2027 | D9: 2028 | E9: 2029 | F9: 2030 | G9: 2031 | H9: 2032 | I9: 2033 | J9: 2034 | K9: 2035 | L9: Cost of debt | M9: =IF('Input Required'!$B$3<>"READY","",'Input Required'!F194/1)
A10: Commercial revenue growth | B10: =IF('Input Required'!$B$3<>"READY","",'Input Required'!F6/1) | C10: =IF('Input Required'!$B$3<>"READY","",'Input Required'!F7/1) | D10: =IF('Input Required'!$B$3<>"READY","",'Input Required'!F8/1) | E10: =IF('Input Required'!$B$3<>"READY","",'Input Required'!F9/1) | F10: =IF('Input Required'!$B$3<>"READY","",'Input Required'!F10/1) | G10: =IF('Input Required'!$B$3<>"READY","",'Input Required'!F11/1) | H10: =IF('Input Required'!$B$3<>"READY","",'Input Required'!F12/1) | I10: =IF('Input Required'!$B$3<>"READY","",'Input Required'!F13/1) | J10: =IF('Input Required'!$B$3<>"READY","",'Input Required'!F14/1) | K10: =IF('Input Required'!$B$3<>"READY","",'Input Required'!F15/1) | L10: Normalized tax rate | M10: =IF('Input Required'!$B$3<>"READY","",'Input Required'!F195/1)
A11: Commercial revenue | B11: =IF('Biotech Model'!$B$4<>"READY","",$B$6*(1+B10)) | C11: =IF('Biotech Model'!$B$4<>"READY","",B11*(1+C10)) | D11: =IF('Biotech Model'!$B$4<>"READY","",C11*(1+D10)) | E11: =IF('Biotech Model'!$B$4<>"READY","",D11*(1+E10)) | F11: =IF('Biotech Model'!$B$4<>"READY","",E11*(1+F10)) | G11: =IF('Biotech Model'!$B$4<>"READY","",F11*(1+G10)) | H11: =IF('Biotech Model'!$B$4<>"READY","",G11*(1+H10)) | I11: =IF('Biotech Model'!$B$4<>"READY","",H11*(1+I10)) | J11: =IF('Biotech Model'!$B$4<>"READY","",I11*(1+J10)) | K11: =IF('Biotech Model'!$B$4<>"READY","",J11*(1+K10)) | L11: Market capitalization | M11: 75858.813
A12: Post-tax commercial FCFF margin | B12: =IF('Input Required'!$B$3<>"READY","",'Input Required'!F16/1) | C12: =IF('Input Required'!$B$3<>"READY","",'Input Required'!F16/1) | D12: =IF('Input Required'!$B$3<>"READY","",'Input Required'!F16/1) | E12: =IF('Input Required'!$B$3<>"READY","",'Input Required'!F16/1) | F12: =IF('Input Required'!$B$3<>"READY","",'Input Required'!F16/1) | G12: =IF('Input Required'!$B$3<>"READY","",'Input Required'!F16/1) | H12: =IF('Input Required'!$B$3<>"READY","",'Input Required'!F16/1) | I12: =IF('Input Required'!$B$3<>"READY","",'Input Required'!F16/1) | J12: =IF('Input Required'!$B$3<>"READY","",'Input Required'!F16/1) | K12: =IF('Input Required'!$B$3<>"READY","",'Input Required'!F16/1) | L12: Interest-bearing debt | M12: 590
A13: Commercial FCFF | B13: =IF('Biotech Model'!$B$4<>"READY","",B11*B12) | C13: =IF('Biotech Model'!$B$4<>"READY","",C11*C12) | D13: =IF('Biotech Model'!$B$4<>"READY","",D11*D12) | E13: =IF('Biotech Model'!$B$4<>"READY","",E11*E12) | F13: =IF('Biotech Model'!$B$4<>"READY","",F11*F12) | G13: =IF('Biotech Model'!$B$4<>"READY","",G11*G12) | H13: =IF('Biotech Model'!$B$4<>"READY","",H11*H12) | I13: =IF('Biotech Model'!$B$4<>"READY","",I11*I12) | ... K13: =IF('Biotech Model'!$B$4<>"READY","",K11*K12) | L13: Equity weight | M13: =IFERROR(M11/(M11+M12),1) -> 0.99228242
A14: Discount factor | B14: =IF('Biotech Model'!$B$4<>"READY","",1/(1+$M$15)^1) | C14: =IF('Biotech Model'!$B$4<>"READY","",1/(1+$M$15)^2) | D14: =IF('Biotech Model'!$B$4<>"READY","",1/(1+$M$15)^3) | E14: =IF('Biotech Model'!$B$4<>"READY","",1/(1+$M$15)^4) | F14: =IF('Biotech Model'!$B$4<>"READY","",1/(1+$M$15)^5) | G14: =IF('Biotech Model'!$B$4<>"READY","",1/(1+$M$15)^6) | H14: =IF('Biotech Model'!$B$4<>"READY","",1/(1+$M$15)^7) | I14: =IF('Biotech Model'!$B$4<>"READY","",1/(1+$M$15)^8) | J14: =IF('Biotech Model'!$B$4<>"READY","",1/(1+$M$15)^9) | K14: =IF('Biotech Model'!$B$4<>"READY","",1/(1+$M$15)^10) | L14: Debt weight | M14: =IFERROR(M12/(M11+M12),0) -> 0.0077175822
A15: PV of commercial FCFF | B15: =IF('Biotech Model'!$B$4<>"READY","",B13*B14) | C15: =IF('Biotech Model'!$B$4<>"READY","",C13*C14) | D15: =IF('Biotech Model'!$B$4<>"READY","",D13*D14) | E15: =IF('Biotech Model'!$B$4<>"READY","",E13*E14) | F15: =IF('Biotech Model'!$B$4<>"READY","",F13*F14) | G15: =IF('Biotech Model'!$B$4<>"READY","",G13*G14) | H15: =IF('Biotech Model'!$B$4<>"READY","",H13*H14) | I15: =IF('Biotech Model'!$B$4<>"READY","",I13*I14) | ... K15: =IF('Biotech Model'!$B$4<>"READY","",K13*K14) | L15: WACC | M15: =IF('Input Required'!$B$3<>"READY","",M8*M13+M9*(1-M10)*M14)
L16: Terminal growth | M16: =IF('Input Required'!$B$3<>"READY","",'Input Required'!F196/1)
L18: Commercial franchise terminal value | M18: =IF('Biotech Model'!$B$4<>"READY","",IF($M$15<=$M$16,"",$K$13*(1+$M$16)/($M$15-$M$16)))
L19: PV of commercial terminal value | M19: =IF('Biotech Model'!$B$4<>"READY","",IF($M$15<=$M$16,"",$M$18/(1+$M$15)^10))
L20: PV of commercial forecast | M20: =IF('Biotech Model'!$B$4<>"READY","",SUM($B$15:$K$15))
L21: Commercial franchise enterprise value | M21: =IF('Biotech Model'!$B$4<>"READY","",IF($M$15<=$M$16,"",$M$19+$M$20))
L22: Individually forecast late-stage asset rNPV | M22: ='Pipeline Valuation'!$B$3
L23: Other SEC-listed pipeline asset rNPV | M23: ='Pipeline Valuation'!$B$4
L24: Pipeline rNPV outside the SEC-mapped asset inventory | M24: =IF('Input Required'!$B$3<>"READY","",'Input Required'!F193/1000000)
L25: Enterprise value | M25: =IF('Biotech Model'!$B$4<>"READY","",IF($M$15<=$M$16,"",SUM(M21:M24)))
L26: Add cash and cash equivalents | M26: 2595
L27: Add marketable securities / nonoperating assets | M27: 0
L28: Less interest-bearing debt | M28: 590
L29: Less noncontrolling interest | M29: 0
L30: Less preferred equity | M30: 0
L31: Common-equity value | M31: =IF('Biotech Model'!$B$4<>"READY","",IF($M$15<=$M$16,"",M25+M26+M27-M28-M29-M30))
L32: Diluted shares (millions) | M32: 389
L33: Implied value per share | M33: =IF('Biotech Model'!$B$4<>"READY","",IF($M$15<=$M$16,"",IFERROR(M31/M32,0)))
L34: Current share price | M34: 190.01
L35: Implied upside / (downside) | M35: =IF('Biotech Model'!$B$4<>"READY","",IF($M$15<=$M$16,"",IFERROR(M33/M34-1,0)))
A37: Formula guide: Commercial revenue = prior year × (1 + growth). Late-stage asset FCFF = sales × PoS × retained share × post-tax margin. Asset rNPV = discounted FCFF − included development-cost PV. Early, paused, and other SEC-listed programs use explicit include controls and analyst-entered PVs; those PVs stay fixed in sensitivity. Unmapped pipeline is separate.
A39: Sensitivity: implied value per share
A40: WACC / terminal growth | B40: =IF('Biotech Model'!$B$4<>"READY","",MAX(0,$M$16+(-0.01))) | C40: =IF('Biotech Model'!$B$4<>"READY","",MAX(0,$M$16+(-0.005))) | D40: =IF('Biotech Model'!$B$4<>"READY","",MAX(0,$M$16+(0))) | E40: =IF('Biotech Model'!$B$4<>"READY","",MAX(0,$M$16+(0.005))) | F40: =IF('Biotech Model'!$B$4<>"READY","",MAX(0,$M$16+(0.01)))
A41: =IF('Biotech Model'!$B$4<>"READY","",$M$15+(-0.02)) | B41: =IF('Biotech Model'!$B$4<>"READY","",IF(OR($A41<2%,$A41>50%,B$40>10%,$A41<=B$40+0.5%),"",($B$13/(1+$A$41)^1+$C$13/(1+$A$41)^2+$D$13/(1+$A$41)^3+$E$13/(1+$A$41)^4+$F$13/(1+$A$41)^5+$G$13/(1+$A$41)^6+$H$13/(1+$A$41)^7+$I$13/(1+$A$41)^8+$J$13/(1+$A$41)^9+$K$13/(1+$A$41)^10+$K$13*(1+B$40)/($A41-B$40)/(1+$A41)^10+'Pipeline Valuation'!$P$4/(1+$A$41)^1+'Pipeline Valuation'!$Q$4/(1+$A$41)^2+'Pipeline Valuation'!$R$4/(1+$A$41)^3+'Pipeline Valuation'!$S$4/(1+$A$41)^4+'Pipeline Valuation'!$T$4/(1+$A$41)^5+'Pipeline Valuation'!$U$4/(1+$A$41)^6+'Pipeline Valuation'!$V$4/(1+$A$41)^7+'Pipeline Valuation'!$W$4/(1+$A$41)^8+'Pipeline Valuation'!$X$4/(1+$A$41)^9+'Pipeline Valuation'!$Y$4/(1+$A$41)^10+'Pipeline Valuation'!$Z$4/(1+$A$41)^11+'Pipeline Valuation'!$AA$4/(1+$A$41)^12+'Pipeline Valuation'!$AB$4/(1+$A$41)^13+'Pipeline Valuation'!$AC$4/(1+$A$41)^14+'Pipeline Valuation'!$AD$4/(1+$A$41)^15+'Pipeline Valuation'!$AE$4/(1+$A$41)^16+'Pipeline Valuation'!$AF$4/(1+$A$41)^17+'Pipeline Valuation'!$AG$4/(1+$A$41)^18+'Pipeline Valuation'!$AH$4/(1+$A$41)^19+'Pipeline Valuation'!$AI$4/(1+$A$41)^20+'Pipeline Valuation'!$AJ$4/(1+$A$41)^21+'Pipeline Valuation'!$AK$4/(1+$A$41)^22+'Pipeline Valuation'!$AL$4/(1+$A$41)^23+'Pipeline Valuation'!$AM$4/(1+$A$41)^24+'Pipeline Valuation'!$AN$4/(1+$A$41)^25+'Pipeline Valuation'!$AO$4/(1+$A$41)^26+'Pipeline Valuation'!$AP$4/(1+$A$41)^27+'Pipeline Valuation'!$AQ$4/(1+$A$41)^28+'Pipeline Valuation'!$AR$4/(1+$A$41)^29+'Pipeline Valuation'!$AS$4/(1+$A$41)^30+'Pipeline Valuation'!$AT$4/(1+$A$41)^31+'Pipeline Valuation'!$AU$4/(1+$A$41)^32+'Pipeline Valuation'!$AV$4/(1+$A$41)^33+'Pipeline Valuation'!$AW$4/(1+$A$41)^34+'Pipeline Valuation'!$AX$4/(1+$A$41)^35-SUMPRODUCT('Pipeline Valuation'!$E$6:$E$19,'Pipeline Valuation'!$N$6:$N$19)+'Pipeline Valuation'!$B$4+$M$24+$M$26+$M$27-$M$28-$M$29-$M$30)/$M$32)) | C41: =IF('Biotech Model'!$B$4<>"READY","",IF(OR($A41<2%,$A41>50%,C$40>10%,$A41<=C$40+0.5%),"",($B$13/(1+$A$41)^1+$C$13/(1+$A$41)^2+$D$13/(1+$A$41)^3+$E$13/(1+$A$41)^4+$F$13/(1+$A$41)^5+$G$13/(1+$A$41)^6+$H$13/(1+$A$41)^7+$I$13/(1+$A$41)^8+$J$13/(1+$A$41)^9+$K$13/(1+$A$41)^10+$K$13*(1+C$40)/($A41-C$40)/(1+$A41)^10+'Pipeline Valuation'!$P$4/(1+$A$41)^1+'Pipeline Valuation'!$Q$4/(1+$A$41)^2+'Pipeline Valuation'!$R$4/(1+$A$41)^3+'Pipeline Valuation'!$S$4/(1+$A$41)^4+'Pipeline Valuation'!$T$4/(1+$A$41)^5+'Pipeline Valuation'!$U$4/(1+$A$41)^6+'Pipeline Valuation'!$V$4/(1+$A$41)^7+'Pipeline Valuation'!$W$4/(1+$A$41)^8+'Pipeline Valuation'!$X$4/(1+$A$41)^9+'Pipeline Valuation'!$Y$4/(1+$A$41)^10+'Pipeline Valuation'!$Z$4/(1+$A$41)^11+'Pipeline Valuation'!$AA$4/(1+$A$41)^12+'Pipeline Valuation'!$AB$4/(1+$A$41)^13+'Pipeline Valuation'!$AC$4/(1+$A$41)^14+'Pipeline Valuation'!$AD$4/(1+$A$41)^15+'Pipeline Valuation'!$AE$4/(1+$A$41)^16+'Pipeline Valuation'!$AF$4/(1+$A$41)^17+'Pipeline Valuation'!$AG$4/(1+$A$41)^18+'Pipeline Valuation'!$AH$4/(1+$A$41)^19+'Pipeline Valuation'!$AI$4/(1+$A$41)^20+'Pipeline Valuation'!$AJ$4/(1+$A$41)^21+'Pipeline Valuation'!$AK$4/(1+$A$41)^22+'Pipeline Valuation'!$AL$4/(1+$A$41)^23+'Pipeline Valuation'!$AM$4/(1+$A$41)^24+'Pipeline Valuation'!$AN$4/(1+$A$41)^25+'Pipeline Valuation'!$AO$4/(1+$A$41)^26+'Pipeline Valuation'!$AP$4/(1+$A$41)^27+'Pipeline Valuation'!$AQ$4/(1+$A$41)^28+'Pipeline Valuation'!$AR$4/(1+$A$41)^29+'Pipeline Valuation'!$AS$4/(1+$A$41)^30+'Pipeline Valuation'!$AT$4/(1+$A$41)^31+'Pipeline Valuation'!$AU$4/(1+$A$41)^32+'Pipeline Valuation'!$AV$4/(1+$A$41)^33+'Pipeline Valuation'!$AW$4/(1+$A$41)^34+'Pipeline Valuation'!$AX$4/(1+$A$41)^35-SUMPRODUCT('Pipeline Valuation'!$E$6:$E$19,'Pipeline Valuation'!$N$6:$N$19)+'Pipeline Valuation'!$B$4+$M$24+$M$26+$M$27-$M$28-$M$29-$M$30)/$M$32)) | D41: =IF('Biotech Model'!$B$4<>"READY","",IF(OR($A41<2%,$A41>50%,D$40>10%,$A41<=D$40+0.5%),"",($B$13/(1+$A$41)^1+$C$13/(1+$A$41)^2+$D$13/(1+$A$41)^3+$E$13/(1+$A$41)^4+$F$13/(1+$A$41)^5+$G$13/(1+$A$41)^6+$H$13/(1+$A$41)^7+$I$13/(1+$A$41)^8+$J$13/(1+$A$41)^9+$K$13/(1+$A$41)^10+$K$13*(1+D$40)/($A41-D$40)/(1+$A41)^10+'Pipeline Valuation'!$P$4/(1+$A$41)^1+'Pipeline Valuation'!$Q$4/(1+$A$41)^2+'Pipeline Valuation'!$R$4/(1+$A$41)^3+'Pipeline Valuation'!$S$4/(1+$A$41)^4+'Pipeline Valuation'!$T$4/(1+$A$41)^5+'Pipeline Valuation'!$U$4/(1+$A$41)^6+'Pipeline Valuation'!$V$4/(1+$A$41)^7+'Pipeline Valuation'!$W$4/(1+$A$41)^8+'Pipeline Valuation'!$X$4/(1+$A$41)^9+'Pipeline Valuation'!$Y$4/(1+$A$41)^10+'Pipeline Valuation'!$Z$4/(1+$A$41)^11+'Pipeline Valuation'!$AA$4/(1+$A$41)^12+'Pipeline Valuation'!$AB$4/(1+$A$41)^13+'Pipeline Valuation'!$AC$4/(1+$A$41)^14+'Pipeline Valuation'!$AD$4/(1+$A$41)^15+'Pipeline Valuation'!$AE$4/(1+$A$41)^16+'Pipeline Valuation'!$AF$4/(1+$A$41)^17+'Pipeline Valuation'!$AG$4/(1+$A$41)^18+'Pipeline Valuation'!$AH$4/(1+$A$41)^19+'Pipeline Valuation'!$AI$4/(1+$A$41)^20+'Pipeline Valuation'!$AJ$4/(1+$A$41)^21+'Pipeline Valuation'!$AK$4/(1+$A$41)^22+'Pipeline Valuation'!$AL$4/(1+$A$41)^23+'Pipeline Valuation'!$AM$4/(1+$A$41)^24+'Pipeline Valuation'!$AN$4/(1+$A$41)^25+'Pipeline Valuation'!$AO$4/(1+$A$41)^26+'Pipeline Valuation'!$AP$4/(1+$A$41)^27+'Pipeline Valuation'!$AQ$4/(1+$A$41)^28+'Pipeline Valuation'!$AR$4/(1+$A$41)^29+'Pipeline Valuation'!$AS$4/(1+$A$41)^30+'Pipeline Valuation'!$AT$4/(1+$A$41)^31+'Pipeline Valuation'!$AU$4/(1+$A$41)^32+'Pipeline Valuation'!$AV$4/(1+$A$41)^33+'Pipeline Valuation'!$AW$4/(1+$A$41)^34+'Pipeline Valuation'!$AX$4/(1+$A$41)^35-SUMPRODUCT('Pipeline Valuation'!$E$6:$E$19,'Pipeline Valuation'!$N$6:$N$19)+'Pipeline Valuation'!$B$4+$M$24+$M$26+$M$27-$M$28-$M$29-$M$30)/$M$32)) | E41: =IF('Biotech Model'!$B$4<>"READY","",IF(OR($A41<2%,$A41>50%,E$40>10%,$A41<=E$40+0.5%),"",($B$13/(1+$A$41)^1+$C$13/(1+$A$41)^2+$D$13/(1+$A$41)^3+$E$13/(1+$A$41)^4+$F$13/(1+$A$41)^5+$G$13/(1+$A$41)^6+$H$13/(1+$A$41)^7+$I$13/(1+$A$41)^8+$J$13/(1+$A$41)^9+$K$13/(1+$A$41)^10+$K$13*(1+E$40)/($A41-E$40)/(1+$A41)^10+'Pipeline Valuation'!$P$4/(1+$A$41)^1+'Pipeline Valuation'!$Q$4/(1+$A$41)^2+'Pipeline Valuation'!$R$4/(1+$A$41)^3+'Pipeline Valuation'!$S$4/(1+$A$41)^4+'Pipeline Valuation'!$T$4/(1+$A$41)^5+'Pipeline Valuation'!$U$4/(1+$A$41)^6+'Pipeline Valuation'!$V$4/(1+$A$41)^7+'Pipeline Valuation'!$W$4/(1+$A$41)^8+'Pipeline Valuation'!$X$4/(1+$A$41)^9+'Pipeline Valuation'!$Y$4/(1+$A$41)^10+'Pipeline Valuation'!$Z$4/(1+$A$41)^11+'Pipeline Valuation'!$AA$4/(1+$A$41)^12+'Pipeline Valuation'!$AB$4/(1+$A$41)^13+'Pipeline Valuation'!$AC$4/(1+$A$41)^14+'Pipeline Valuation'!$AD$4/(1+$A$41)^15+'Pipeline Valuation'!$AE$4/(1+$A$41)^16+'Pipeline Valuation'!$AF$4/(1+$A$41)^17+'Pipeline Valuation'!$AG$4/(1+$A$41)^18+'Pipeline Valuation'!$AH$4/(1+$A$41)^19+'Pipeline Valuation'!$AI$4/(1+$A$41)^20+'Pipeline Valuation'!$AJ$4/(1+$A$41)^21+'Pipeline Valuation'!$AK$4/(1+$A$41)^22+'Pipeline Valuation'!$AL$4/(1+$A$41)^23+'Pipeline Valuation'!$AM$4/(1+$A$41)^24+'Pipeline Valuation'!$AN$4/(1+$A$41)^25+'Pipeline Valuation'!$AO$4/(1+$A$41)^26+'Pipeline Valuation'!$AP$4/(1+$A$41)^27+'Pipeline Valuation'!$AQ$4/(1+$A$41)^28+'Pipeline Valuation'!$AR$4/(1+$A$41)^29+'Pipeline Valuation'!$AS$4/(1+$A$41)^30+'Pipeline Valuation'!$AT$4/(1+$A$41)^31+'Pipeline Valuation'!$AU$4/(1+$A$41)^32+'Pipeline Valuation'!$AV$4/(1+$A$41)^33+'Pipeline Valuation'!$AW$4/(1+$A$41)^34+'Pipeline Valuation'!$AX$4/(1+$A$41)^35-SUMPRODUCT('Pipeline Valuation'!$E$6:$E$19,'Pipeline Valuation'!$N$6:$N$19)+'Pipeline Valuation'!$B$4+$M$24+$M$26+$M$27-$M$28-$M$29-$M$30)/$M$32)) | F41: =IF('Biotech Model'!$B$4<>"READY","",IF(OR($A41<2%,$A41>50%,F$40>10%,$A41<=F$40+0.5%),"",($B$13/(1+$A$41)^1+$C$13/(1+$A$41)^2+$D$13/(1+$A$41)^3+$E$13/(1+$A$41)^4+$F$13/(1+$A$41)^5+$G$13/(1+$A$41)^6+$H$13/(1+$A$41)^7+$I$13/(1+$A$41)^8+$J$13/(1+$A$41)^9+$K$13/(1+$A$41)^10+$K$13*(1+F$40)/($A41-F$40)/(1+$A41)^10+'Pipeline Valuation'!$P$4/(1+$A$41)^1+'Pipeline Valuation'!$Q$4/(1+$A$41)^2+'Pipeline Valuation'!$R$4/(1+$A$41)^3+'Pipeline Valuation'!$S$4/(1+$A$41)^4+'Pipeline Valuation'!$T$4/(1+$A$41)^5+'Pipeline Valuation'!$U$4/(1+$A$41)^6+'Pipeline Valuation'!$V$4/(1+$A$41)^7+'Pipeline Valuation'!$W$4/(1+$A$41)^8+'Pipeline Valuation'!$X$4/(1+$A$41)^9+'Pipeline Valuation'!$Y$4/(1+$A$41)^10+'Pipeline Valuation'!$Z$4/(1+$A$41)^11+'Pipeline Valuation'!$AA$4/(1+$A$41)^12+'Pipeline Valuation'!$AB$4/(1+$A$41)^13+'Pipeline Valuation'!$AC$4/(1+$A$41)^14+'Pipeline Valuation'!$AD$4/(1+$A$41)^15+'Pipeline Valuation'!$AE$4/(1+$A$41)^16+'Pipeline Valuation'!$AF$4/(1+$A$41)^17+'Pipeline Valuation'!$AG$4/(1+$A$41)^18+'Pipeline Valuation'!$AH$4/(1+$A$41)^19+'Pipeline Valuation'!$AI$4/(1+$A$41)^20+'Pipeline Valuation'!$AJ$4/(1+$A$41)^21+'Pipeline Valuation'!$AK$4/(1+$A$41)^22+'Pipeline Valuation'!$AL$4/(1+$A$41)^23+'Pipeline Valuation'!$AM$4/(1+$A$41)^24+'Pipeline Valuation'!$AN$4/(1+$A$41)^25+'Pipeline Valuation'!$AO$4/(1+$A$41)^26+'Pipeline Valuation'!$AP$4/(1+$A$41)^27+'Pipeline Valuation'!$AQ$4/(1+$A$41)^28+'Pipeline Valuation'!$AR$4/(1+$A$41)^29+'Pipeline Valuation'!$AS$4/(1+$A$41)^30+'Pipeline Valuation'!$AT$4/(1+$A$41)^31+'Pipeline Valuation'!$AU$4/(1+$A$41)^32+'Pipeline Valuation'!$AV$4/(1+$A$41)^33+'Pipeline Valuation'!$AW$4/(1+$A$41)^34+'Pipeline Valuation'!$AX$4/(1+$A$41)^35-SUMPRODUCT('Pipeline Valuation'!$E$6:$E$19,'Pipeline Valuation'!$N$6:$N$19)+'Pipeline Valuation'!$B$4+$M$24+$M$26+$M$27-$M$28-$M$29-$M$30)/$M$32))
A42: =IF('Biotech Model'!$B$4<>"READY","",$M$15+(-0.01)) | B42: =IF('Biotech Model'!$B$4<>"READY","",IF(OR($A42<2%,$A42>50%,B$40>10%,$A42<=B$40+0.5%),"",($B$13/(1+$A$42)^1+$C$13/(1+$A$42)^2+$D$13/(1+$A$42)^3+$E$13/(1+$A$42)^4+$F$13/(1+$A$42)^5+$G$13/(1+$A$42)^6+$H$13/(1+$A$42)^7+$I$13/(1+$A$42)^8+$J$13/(1+$A$42)^9+$K$13/(1+$A$42)^10+$K$13*(1+B$40)/($A42-B$40)/(1+$A42)^10+'Pipeline Valuation'!$P$4/(1+$A$42)^1+'Pipeline Valuation'!$Q$4/(1+$A$42)^2+'Pipeline Valuation'!$R$4/(1+$A$42)^3+'Pipeline Valuation'!$S$4/(1+$A$42)^4+'Pipeline Valuation'!$T$4/(1+$A$42)^5+'Pipeline Valuation'!$U$4/(1+$A$42)^6+'Pipeline Valuation'!$V$4/(1+$A$42)^7+'Pipeline Valuation'!$W$4/(1+$A$42)^8+'Pipeline Valuation'!$X$4/(1+$A$42)^9+'Pipeline Valuation'!$Y$4/(1+$A$42)^10+'Pipeline Valuation'!$Z$4/(1+$A$42)^11+'Pipeline Valuation'!$AA$4/(1+$A$42)^12+'Pipeline Valuation'!$AB$4/(1+$A$42)^13+'Pipeline Valuation'!$AC$4/(1+$A$42)^14+'Pipeline Valuation'!$AD$4/(1+$A$42)^15+'Pipeline Valuation'!$AE$4/(1+$A$42)^16+'Pipeline Valuation'!$AF$4/(1+$A$42)^17+'Pipeline Valuation'!$AG$4/(1+$A$42)^18+'Pipeline Valuation'!$AH$4/(1+$A$42)^19+'Pipeline Valuation'!$AI$4/(1+$A$42)^20+'Pipeline Valuation'!$AJ$4/(1+$A$42)^21+'Pipeline Valuation'!$AK$4/(1+$A$42)^22+'Pipeline Valuation'!$AL$4/(1+$A$42)^23+'Pipeline Valuation'!$AM$4/(1+$A$42)^24+'Pipeline Valuation'!$AN$4/(1+$A$42)^25+'Pipeline Valuation'!$AO$4/(1+$A$42)^26+'Pipeline Valuation'!$AP$4/(1+$A$42)^27+'Pipeline Valuation'!$AQ$4/(1+$A$42)^28+'Pipeline Valuation'!$AR$4/(1+$A$42)^29+'Pipeline Valuation'!$AS$4/(1+$A$42)^30+'Pipeline Valuation'!$AT$4/(1+$A$42)^31+'Pipeline Valuation'!$AU$4/(1+$A$42)^32+'Pipeline Valuation'!$AV$4/(1+$A$42)^33+'Pipeline Valuation'!$AW$4/(1+$A$42)^34+'Pipeline Valuation'!$AX$4/(1+$A$42)^35-SUMPRODUCT('Pipeline Valuation'!$E$6:$E$19,'Pipeline Valuation'!$N$6:$N$19)+'Pipeline Valuation'!$B$4+$M$24+$M$26+$M$27-$M$28-$M$29-$M$30)/$M$32)) | C42: =IF('Biotech Model'!$B$4<>"READY","",IF(OR($A42<2%,$A42>50%,C$40>10%,$A42<=C$40+0.5%),"",($B$13/(1+$A$42)^1+$C$13/(1+$A$42)^2+$D$13/(1+$A$42)^3+$E$13/(1+$A$42)^4+$F$13/(1+$A$42)^5+$G$13/(1+$A$42)^6+$H$13/(1+$A$42)^7+$I$13/(1+$A$42)^8+$J$13/(1+$A$42)^9+$K$13/(1+$A$42)^10+$K$13*(1+C$40)/($A42-C$40)/(1+$A42)^10+'Pipeline Valuation'!$P$4/(1+$A$42)^1+'Pipeline Valuation'!$Q$4/(1+$A$42)^2+'Pipeline Valuation'!$R$4/(1+$A$42)^3+'Pipeline Valuation'!$S$4/(1+$A$42)^4+'Pipeline Valuation'!$T$4/(1+$A$42)^5+'Pipeline Valuation'!$U$4/(1+$A$42)^6+'Pipeline Valuation'!$V$4/(1+$A$42)^7+'Pipeline Valuation'!$W$4/(1+$A$42)^8+'Pipeline Valuation'!$X$4/(1+$A$42)^9+'Pipeline Valuation'!$Y$4/(1+$A$42)^10+'Pipeline Valuation'!$Z$4/(1+$A$42)^11+'Pipeline Valuation'!$AA$4/(1+$A$42)^12+'Pipeline Valuation'!$AB$4/(1+$A$42)^13+'Pipeline Valuation'!$AC$4/(1+$A$42)^14+'Pipeline Valuation'!$AD$4/(1+$A$42)^15+'Pipeline Valuation'!$AE$4/(1+$A$42)^16+'Pipeline Valuation'!$AF$4/(1+$A$42)^17+'Pipeline Valuation'!$AG$4/(1+$A$42)^18+'Pipeline Valuation'!$AH$4/(1+$A$42)^19+'Pipeline Valuation'!$AI$4/(1+$A$42)^20+'Pipeline Valuation'!$AJ$4/(1+$A$42)^21+'Pipeline Valuation'!$AK$4/(1+$A$42)^22+'Pipeline Valuation'!$AL$4/(1+$A$42)^23+'Pipeline Valuation'!$AM$4/(1+$A$42)^24+'Pipeline Valuation'!$AN$4/(1+$A$42)^25+'Pipeline Valuation'!$AO$4/(1+$A$42)^26+'Pipeline Valuation'!$AP$4/(1+$A$42)^27+'Pipeline Valuation'!$AQ$4/(1+$A$42)^28+'Pipeline Valuation'!$AR$4/(1+$A$42)^29+'Pipeline Valuation'!$AS$4/(1+$A$42)^30+'Pipeline Valuation'!$AT$4/(1+$A$42)^31+'Pipeline Valuation'!$AU$4/(1+$A$42)^32+'Pipeline Valuation'!$AV$4/(1+$A$42)^33+'Pipeline Valuation'!$AW$4/(1+$A$42)^34+'Pipeline Valuation'!$AX$4/(1+$A$42)^35-SUMPRODUCT('Pipeline Valuation'!$E$6:$E$19,'Pipeline Valuation'!$N$6:$N$19)+'Pipeline Valuation'!$B$4+$M$24+$M$26+$M$27-$M$28-$M$29-$M$30)/$M$32)) | D42: =IF('Biotech Model'!$B$4<>"READY","",IF(OR($A42<2%,$A42>50%,D$40>10%,$A42<=D$40+0.5%),"",($B$13/(1+$A$42)^1+$C$13/(1+$A$42)^2+$D$13/(1+$A$42)^3+$E$13/(1+$A$42)^4+$F$13/(1+$A$42)^5+$G$13/(1+$A$42)^6+$H$13/(1+$A$42)^7+$I$13/(1+$A$42)^8+$J$13/(1+$A$42)^9+$K$13/(1+$A$42)^10+$K$13*(1+D$40)/($A42-D$40)/(1+$A42)^10+'Pipeline Valuation'!$P$4/(1+$A$42)^1+'Pipeline Valuation'!$Q$4/(1+$A$42)^2+'Pipeline Valuation'!$R$4/(1+$A$42)^3+'Pipeline Valuation'!$S$4/(1+$A$42)^4+'Pipeline Valuation'!$T$4/(1+$A$42)^5+'Pipeline Valuation'!$U$4/(1+$A$42)^6+'Pipeline Valuation'!$V$4/(1+$A$42)^7+'Pipeline Valuation'!$W$4/(1+$A$42)^8+'Pipeline Valuation'!$X$4/(1+$A$42)^9+'Pipeline Valuation'!$Y$4/(1+$A$42)^10+'Pipeline Valuation'!$Z$4/(1+$A$42)^11+'Pipeline Valuation'!$AA$4/(1+$A$42)^12+'Pipeline Valuation'!$AB$4/(1+$A$42)^13+'Pipeline Valuation'!$AC$4/(1+$A$42)^14+'Pipeline Valuation'!$AD$4/(1+$A$42)^15+'Pipeline Valuation'!$AE$4/(1+$A$42)^16+'Pipeline Valuation'!$AF$4/(1+$A$42)^17+'Pipeline Valuation'!$AG$4/(1+$A$42)^18+'Pipeline Valuation'!$AH$4/(1+$A$42)^19+'Pipeline Valuation'!$AI$4/(1+$A$42)^20+'Pipeline Valuation'!$AJ$4/(1+$A$42)^21+'Pipeline Valuation'!$AK$4/(1+$A$42)^22+'Pipeline Valuation'!$AL$4/(1+$A$42)^23+'Pipeline Valuation'!$AM$4/(1+$A$42)^24+'Pipeline Valuation'!$AN$4/(1+$A$42)^25+'Pipeline Valuation'!$AO$4/(1+$A$42)^26+'Pipeline Valuation'!$AP$4/(1+$A$42)^27+'Pipeline Valuation'!$AQ$4/(1+$A$42)^28+'Pipeline Valuation'!$AR$4/(1+$A$42)^29+'Pipeline Valuation'!$AS$4/(1+$A$42)^30+'Pipeline Valuation'!$AT$4/(1+$A$42)^31+'Pipeline Valuation'!$AU$4/(1+$A$42)^32+'Pipeline Valuation'!$AV$4/(1+$A$42)^33+'Pipeline Valuation'!$AW$4/(1+$A$42)^34+'Pipeline Valuation'!$AX$4/(1+$A$42)^35-SUMPRODUCT('Pipeline Valuation'!$E$6:$E$19,'Pipeline Valuation'!$N$6:$N$19)+'Pipeline Valuation'!$B$4+$M$24+$M$26+$M$27-$M$28-$M$29-$M$30)/$M$32)) | E42: =IF('Biotech Model'!$B$4<>"READY","",IF(OR($A42<2%,$A42>50%,E$40>10%,$A42<=E$40+0.5%),"",($B$13/(1+$A$42)^1+$C$13/(1+$A$42)^2+$D$13/(1+$A$42)^3+$E$13/(1+$A$42)^4+$F$13/(1+$A$42)^5+$G$13/(1+$A$42)^6+$H$13/(1+$A$42)^7+$I$13/(1+$A$42)^8+$J$13/(1+$A$42)^9+$K$13/(1+$A$42)^10+$K$13*(1+E$40)/($A42-E$40)/(1+$A42)^10+'Pipeline Valuation'!$P$4/(1+$A$42)^1+'Pipeline Valuation'!$Q$4/(1+$A$42)^2+'Pipeline Valuation'!$R$4/(1+$A$42)^3+'Pipeline Valuation'!$S$4/(1+$A$42)^4+'Pipeline Valuation'!$T$4/(1+$A$42)^5+'Pipeline Valuation'!$U$4/(1+$A$42)^6+'Pipeline Valuation'!$V$4/(1+$A$42)^7+'Pipeline Valuation'!$W$4/(1+$A$42)^8+'Pipeline Valuation'!$X$4/(1+$A$42)^9+'Pipeline Valuation'!$Y$4/(1+$A$42)^10+'Pipeline Valuation'!$Z$4/(1+$A$42)^11+'Pipeline Valuation'!$AA$4/(1+$A$42)^12+'Pipeline Valuation'!$AB$4/(1+$A$42)^13+'Pipeline Valuation'!$AC$4/(1+$A$42)^14+'Pipeline Valuation'!$AD$4/(1+$A$42)^15+'Pipeline Valuation'!$AE$4/(1+$A$42)^16+'Pipeline Valuation'!$AF$4/(1+$A$42)^17+'Pipeline Valuation'!$AG$4/(1+$A$42)^18+'Pipeline Valuation'!$AH$4/(1+$A$42)^19+'Pipeline Valuation'!$AI$4/(1+$A$42)^20+'Pipeline Valuation'!$AJ$4/(1+$A$42)^21+'Pipeline Valuation'!$AK$4/(1+$A$42)^22+'Pipeline Valuation'!$AL$4/(1+$A$42)^23+'Pipeline Valuation'!$AM$4/(1+$A$42)^24+'Pipeline Valuation'!$AN$4/(1+$A$42)^25+'Pipeline Valuation'!$AO$4/(1+$A$42)^26+'Pipeline Valuation'!$AP$4/(1+$A$42)^27+'Pipeline Valuation'!$AQ$4/(1+$A$42)^28+'Pipeline Valuation'!$AR$4/(1+$A$42)^29+'Pipeline Valuation'!$AS$4/(1+$A$42)^30+'Pipeline Valuation'!$AT$4/(1+$A$42)^31+'Pipeline Valuation'!$AU$4/(1+$A$42)^32+'Pipeline Valuation'!$AV$4/(1+$A$42)^33+'Pipeline Valuation'!$AW$4/(1+$A$42)^34+'Pipeline Valuation'!$AX$4/(1+$A$42)^35-SUMPRODUCT('Pipeline Valuation'!$E$6:$E$19,'Pipeline Valuation'!$N$6:$N$19)+'Pipeline Valuation'!$B$4+$M$24+$M$26+$M$27-$M$28-$M$29-$M$30)/$M$32)) | F42: =IF('Biotech Model'!$B$4<>"READY","",IF(OR($A42<2%,$A42>50%,F$40>10%,$A42<=F$40+0.5%),"",($B$13/(1+$A$42)^1+$C$13/(1+$A$42)^2+$D$13/(1+$A$42)^3+$E$13/(1+$A$42)^4+$F$13/(1+$A$42)^5+$G$13/(1+$A$42)^6+$H$13/(1+$A$42)^7+$I$13/(1+$A$42)^8+$J$13/(1+$A$42)^9+$K$13/(1+$A$42)^10+$K$13*(1+F$40)/($A42-F$40)/(1+$A42)^10+'Pipeline Valuation'!$P$4/(1+$A$42)^1+'Pipeline Valuation'!$Q$4/(1+$A$42)^2+'Pipeline Valuation'!$R$4/(1+$A$42)^3+'Pipeline Valuation'!$S$4/(1+$A$42)^4+'Pipeline Valuation'!$T$4/(1+$A$42)^5+'Pipeline Valuation'!$U$4/(1+$A$42)^6+'Pipeline Valuation'!$V$4/(1+$A$42)^7+'Pipeline Valuation'!$W$4/(1+$A$42)^8+'Pipeline Valuation'!$X$4/(1+$A$42)^9+'Pipeline Valuation'!$Y$4/(1+$A$42)^10+'Pipeline Valuation'!$Z$4/(1+$A$42)^11+'Pipeline Valuation'!$AA$4/(1+$A$42)^12+'Pipeline Valuation'!$AB$4/(1+$A$42)^13+'Pipeline Valuation'!$AC$4/(1+$A$42)^14+'Pipeline Valuation'!$AD$4/(1+$A$42)^15+'Pipeline Valuation'!$AE$4/(1+$A$42)^16+'Pipeline Valuation'!$AF$4/(1+$A$42)^17+'Pipeline Valuation'!$AG$4/(1+$A$42)^18+'Pipeline Valuation'!$AH$4/(1+$A$42)^19+'Pipeline Valuation'!$AI$4/(1+$A$42)^20+'Pipeline Valuation'!$AJ$4/(1+$A$42)^21+'Pipeline Valuation'!$AK$4/(1+$A$42)^22+'Pipeline Valuation'!$AL$4/(1+$A$42)^23+'Pipeline Valuation'!$AM$4/(1+$A$42)^24+'Pipeline Valuation'!$AN$4/(1+$A$42)^25+'Pipeline Valuation'!$AO$4/(1+$A$42)^26+'Pipeline Valuation'!$AP$4/(1+$A$42)^27+'Pipeline Valuation'!$AQ$4/(1+$A$42)^28+'Pipeline Valuation'!$AR$4/(1+$A$42)^29+'Pipeline Valuation'!$AS$4/(1+$A$42)^30+'Pipeline Valuation'!$AT$4/(1+$A$42)^31+'Pipeline Valuation'!$AU$4/(1+$A$42)^32+'Pipeline Valuation'!$AV$4/(1+$A$42)^33+'Pipeline Valuation'!$AW$4/(1+$A$42)^34+'Pipeline Valuation'!$AX$4/(1+$A$42)^35-SUMPRODUCT('Pipeline Valuation'!$E$6:$E$19,'Pipeline Valuation'!$N$6:$N$19)+'Pipeline Valuation'!$B$4+$M$24+$M$26+$M$27-$M$28-$M$29-$M$30)/$M$32))
A43: =IF('Biotech Model'!$B$4<>"READY","",$M$15+(0)) | B43: =IF('Biotech Model'!$B$4<>"READY","",IF(OR($A43<2%,$A43>50%,B$40>10%,$A43<=B$40+0.5%),"",($B$13/(1+$A$43)^1+$C$13/(1+$A$43)^2+$D$13/(1+$A$43)^3+$E$13/(1+$A$43)^4+$F$13/(1+$A$43)^5+$G$13/(1+$A$43)^6+$H$13/(1+$A$43)^7+$I$13/(1+$A$43)^8+$J$13/(1+$A$43)^9+$K$13/(1+$A$43)^10+$K$13*(1+B$40)/($A43-B$40)/(1+$A43)^10+'Pipeline Valuation'!$P$4/(1+$A$43)^1+'Pipeline Valuation'!$Q$4/(1+$A$43)^2+'Pipeline Valuation'!$R$4/(1+$A$43)^3+'Pipeline Valuation'!$S$4/(1+$A$43)^4+'Pipeline Valuation'!$T$4/(1+$A$43)^5+'Pipeline Valuation'!$U$4/(1+$A$43)^6+'Pipeline Valuation'!$V$4/(1+$A$43)^7+'Pipeline Valuation'!$W$4/(1+$A$43)^8+'Pipeline Valuation'!$X$4/(1+$A$43)^9+'Pipeline Valuation'!$Y$4/(1+$A$43)^10+'Pipeline Valuation'!$Z$4/(1+$A$43)^11+'Pipeline Valuation'!$AA$4/(1+$A$43)^12+'Pipeline Valuation'!$AB$4/(1+$A$43)^13+'Pipeline Valuation'!$AC$4/(1+$A$43)^14+'Pipeline Valuation'!$AD$4/(1+$A$43)^15+'Pipeline Valuation'!$AE$4/(1+$A$43)^16+'Pipeline Valuation'!$AF$4/(1+$A$43)^17+'Pipeline Valuation'!$AG$4/(1+$A$43)^18+'Pipeline Valuation'!$AH$4/(1+$A$43)^19+'Pipeline Valuation'!$AI$4/(1+$A$43)^20+'Pipeline Valuation'!$AJ$4/(1+$A$43)^21+'Pipeline Valuation'!$AK$4/(1+$A$43)^22+'Pipeline Valuation'!$AL$4/(1+$A$43)^23+'Pipeline Valuation'!$AM$4/(1+$A$43)^24+'Pipeline Valuation'!$AN$4/(1+$A$43)^25+'Pipeline Valuation'!$AO$4/(1+$A$43)^26+'Pipeline Valuation'!$AP$4/(1+$A$43)^27+'Pipeline Valuation'!$AQ$4/(1+$A$43)^28+'Pipeline Valuation'!$AR$4/(1+$A$43)^29+'Pipeline Valuation'!$AS$4/(1+$A$43)^30+'Pipeline Valuation'!$AT$4/(1+$A$43)^31+'Pipeline Valuation'!$AU$4/(1+$A$43)^32+'Pipeline Valuation'!$AV$4/(1+$A$43)^33+'Pipeline Valuation'!$AW$4/(1+$A$43)^34+'Pipeline Valuation'!$AX$4/(1+$A$43)^35-SUMPRODUCT('Pipeline Valuation'!$E$6:$E$19,'Pipeline Valuation'!$N$6:$N$19)+'Pipeline Valuation'!$B$4+$M$24+$M$26+$M$27-$M$28-$M$29-$M$30)/$M$32)) | C43: =IF('Biotech Model'!$B$4<>"READY","",IF(OR($A43<2%,$A43>50%,C$40>10%,$A43<=C$40+0.5%),"",($B$13/(1+$A$43)^1+$C$13/(1+$A$43)^2+$D$13/(1+$A$43)^3+$E$13/(1+$A$43)^4+$F$13/(1+$A$43)^5+$G$13/(1+$A$43)^6+$H$13/(1+$A$43)^7+$I$13/(1+$A$43)^8+$J$13/(1+$A$43)^9+$K$13/(1+$A$43)^10+$K$13*(1+C$40)/($A43-C$40)/(1+$A43)^10+'Pipeline Valuation'!$P$4/(1+$A$43)^1+'Pipeline Valuation'!$Q$4/(1+$A$43)^2+'Pipeline Valuation'!$R$4/(1+$A$43)^3+'Pipeline Valuation'!$S$4/(1+$A$43)^4+'Pipeline Valuation'!$T$4/(1+$A$43)^5+'Pipeline Valuation'!$U$4/(1+$A$43)^6+'Pipeline Valuation'!$V$4/(1+$A$43)^7+'Pipeline Valuation'!$W$4/(1+$A$43)^8+'Pipeline Valuation'!$X$4/(1+$A$43)^9+'Pipeline Valuation'!$Y$4/(1+$A$43)^10+'Pipeline Valuation'!$Z$4/(1+$A$43)^11+'Pipeline Valuation'!$AA$4/(1+$A$43)^12+'Pipeline Valuation'!$AB$4/(1+$A$43)^13+'Pipeline Valuation'!$AC$4/(1+$A$43)^14+'Pipeline Valuation'!$AD$4/(1+$A$43)^15+'Pipeline Valuation'!$AE$4/(1+$A$43)^16+'Pipeline Valuation'!$AF$4/(1+$A$43)^17+'Pipeline Valuation'!$AG$4/(1+$A$43)^18+'Pipeline Valuation'!$AH$4/(1+$A$43)^19+'Pipeline Valuation'!$AI$4/(1+$A$43)^20+'Pipeline Valuation'!$AJ$4/(1+$A$43)^21+'Pipeline Valuation'!$AK$4/(1+$A$43)^22+'Pipeline Valuation'!$AL$4/(1+$A$43)^23+'Pipeline Valuation'!$AM$4/(1+$A$43)^24+'Pipeline Valuation'!$AN$4/(1+$A$43)^25+'Pipeline Valuation'!$AO$4/(1+$A$43)^26+'Pipeline Valuation'!$AP$4/(1+$A$43)^27+'Pipeline Valuation'!$AQ$4/(1+$A$43)^28+'Pipeline Valuation'!$AR$4/(1+$A$43)^29+'Pipeline Valuation'!$AS$4/(1+$A$43)^30+'Pipeline Valuation'!$AT$4/(1+$A$43)^31+'Pipeline Valuation'!$AU$4/(1+$A$43)^32+'Pipeline Valuation'!$AV$4/(1+$A$43)^33+'Pipeline Valuation'!$AW$4/(1+$A$43)^34+'Pipeline Valuation'!$AX$4/(1+$A$43)^35-SUMPRODUCT('Pipeline Valuation'!$E$6:$E$19,'Pipeline Valuation'!$N$6:$N$19)+'Pipeline Valuation'!$B$4+$M$24+$M$26+$M$27-$M$28-$M$29-$M$30)/$M$32)) | D43: =IF('Biotech Model'!$B$4<>"READY","",IF(OR($A43<2%,$A43>50%,D$40>10%,$A43<=D$40+0.5%),"",($B$13/(1+$A$43)^1+$C$13/(1+$A$43)^2+$D$13/(1+$A$43)^3+$E$13/(1+$A$43)^4+$F$13/(1+$A$43)^5+$G$13/(1+$A$43)^6+$H$13/(1+$A$43)^7+$I$13/(1+$A$43)^8+$J$13/(1+$A$43)^9+$K$13/(1+$A$43)^10+$K$13*(1+D$40)/($A43-D$40)/(1+$A43)^10+'Pipeline Valuation'!$P$4/(1+$A$43)^1+'Pipeline Valuation'!$Q$4/(1+$A$43)^2+'Pipeline Valuation'!$R$4/(1+$A$43)^3+'Pipeline Valuation'!$S$4/(1+$A$43)^4+'Pipeline Valuation'!$T$4/(1+$A$43)^5+'Pipeline Valuation'!$U$4/(1+$A$43)^6+'Pipeline Valuation'!$V$4/(1+$A$43)^7+'Pipeline Valuation'!$W$4/(1+$A$43)^8+'Pipeline Valuation'!$X$4/(1+$A$43)^9+'Pipeline Valuation'!$Y$4/(1+$A$43)^10+'Pipeline Valuation'!$Z$4/(1+$A$43)^11+'Pipeline Valuation'!$AA$4/(1+$A$43)^12+'Pipeline Valuation'!$AB$4/(1+$A$43)^13+'Pipeline Valuation'!$AC$4/(1+$A$43)^14+'Pipeline Valuation'!$AD$4/(1+$A$43)^15+'Pipeline Valuation'!$AE$4/(1+$A$43)^16+'Pipeline Valuation'!$AF$4/(1+$A$43)^17+'Pipeline Valuation'!$AG$4/(1+$A$43)^18+'Pipeline Valuation'!$AH$4/(1+$A$43)^19+'Pipeline Valuation'!$AI$4/(1+$A$43)^20+'Pipeline Valuation'!$AJ$4/(1+$A$43)^21+'Pipeline Valuation'!$AK$4/(1+$A$43)^22+'Pipeline Valuation'!$AL$4/(1+$A$43)^23+'Pipeline Valuation'!$AM$4/(1+$A$43)^24+'Pipeline Valuation'!$AN$4/(1+$A$43)^25+'Pipeline Valuation'!$AO$4/(1+$A$43)^26+'Pipeline Valuation'!$AP$4/(1+$A$43)^27+'Pipeline Valuation'!$AQ$4/(1+$A$43)^28+'Pipeline Valuation'!$AR$4/(1+$A$43)^29+'Pipeline Valuation'!$AS$4/(1+$A$43)^30+'Pipeline Valuation'!$AT$4/(1+$A$43)^31+'Pipeline Valuation'!$AU$4/(1+$A$43)^32+'Pipeline Valuation'!$AV$4/(1+$A$43)^33+'Pipeline Valuation'!$AW$4/(1+$A$43)^34+'Pipeline Valuation'!$AX$4/(1+$A$43)^35-SUMPRODUCT('Pipeline Valuation'!$E$6:$E$19,'Pipeline Valuation'!$N$6:$N$19)+'Pipeline Valuation'!$B$4+$M$24+$M$26+$M$27-$M$28-$M$29-$M$30)/$M$32)) | E43: =IF('Biotech Model'!$B$4<>"READY","",IF(OR($A43<2%,$A43>50%,E$40>10%,$A43<=E$40+0.5%),"",($B$13/(1+$A$43)^1+$C$13/(1+$A$43)^2+$D$13/(1+$A$43)^3+$E$13/(1+$A$43)^4+$F$13/(1+$A$43)^5+$G$13/(1+$A$43)^6+$H$13/(1+$A$43)^7+$I$13/(1+$A$43)^8+$J$13/(1+$A$43)^9+$K$13/(1+$A$43)^10+$K$13*(1+E$40)/($A43-E$40)/(1+$A43)^10+'Pipeline Valuation'!$P$4/(1+$A$43)^1+'Pipeline Valuation'!$Q$4/(1+$A$43)^2+'Pipeline Valuation'!$R$4/(1+$A$43)^3+'Pipeline Valuation'!$S$4/(1+$A$43)^4+'Pipeline Valuation'!$T$4/(1+$A$43)^5+'Pipeline Valuation'!$U$4/(1+$A$43)^6+'Pipeline Valuation'!$V$4/(1+$A$43)^7+'Pipeline Valuation'!$W$4/(1+$A$43)^8+'Pipeline Valuation'!$X$4/(1+$A$43)^9+'Pipeline Valuation'!$Y$4/(1+$A$43)^10+'Pipeline Valuation'!$Z$4/(1+$A$43)^11+'Pipeline Valuation'!$AA$4/(1+$A$43)^12+'Pipeline Valuation'!$AB$4/(1+$A$43)^13+'Pipeline Valuation'!$AC$4/(1+$A$43)^14+'Pipeline Valuation'!$AD$4/(1+$A$43)^15+'Pipeline Valuation'!$AE$4/(1+$A$43)^16+'Pipeline Valuation'!$AF$4/(1+$A$43)^17+'Pipeline Valuation'!$AG$4/(1+$A$43)^18+'Pipeline Valuation'!$AH$4/(1+$A$43)^19+'Pipeline Valuation'!$AI$4/(1+$A$43)^20+'Pipeline Valuation'!$AJ$4/(1+$A$43)^21+'Pipeline Valuation'!$AK$4/(1+$A$43)^22+'Pipeline Valuation'!$AL$4/(1+$A$43)^23+'Pipeline Valuation'!$AM$4/(1+$A$43)^24+'Pipeline Valuation'!$AN$4/(1+$A$43)^25+'Pipeline Valuation'!$AO$4/(1+$A$43)^26+'Pipeline Valuation'!$AP$4/(1+$A$43)^27+'Pipeline Valuation'!$AQ$4/(1+$A$43)^28+'Pipeline Valuation'!$AR$4/(1+$A$43)^29+'Pipeline Valuation'!$AS$4/(1+$A$43)^30+'Pipeline Valuation'!$AT$4/(1+$A$43)^31+'Pipeline Valuation'!$AU$4/(1+$A$43)^32+'Pipeline Valuation'!$AV$4/(1+$A$43)^33+'Pipeline Valuation'!$AW$4/(1+$A$43)^34+'Pipeline Valuation'!$AX$4/(1+$A$43)^35-SUMPRODUCT('Pipeline Valuation'!$E$6:$E$19,'Pipeline Valuation'!$N$6:$N$19)+'Pipeline Valuation'!$B$4+$M$24+$M$26+$M$27-$M$28-$M$29-$M$30)/$M$32)) | F43: =IF('Biotech Model'!$B$4<>"READY","",IF(OR($A43<2%,$A43>50%,F$40>10%,$A43<=F$40+0.5%),"",($B$13/(1+$A$43)^1+$C$13/(1+$A$43)^2+$D$13/(1+$A$43)^3+$E$13/(1+$A$43)^4+$F$13/(1+$A$43)^5+$G$13/(1+$A$43)^6+$H$13/(1+$A$43)^7+$I$13/(1+$A$43)^8+$J$13/(1+$A$43)^9+$K$13/(1+$A$43)^10+$K$13*(1+F$40)/($A43-F$40)/(1+$A43)^10+'Pipeline Valuation'!$P$4/(1+$A$43)^1+'Pipeline Valuation'!$Q$4/(1+$A$43)^2+'Pipeline Valuation'!$R$4/(1+$A$43)^3+'Pipeline Valuation'!$S$4/(1+$A$43)^4+'Pipeline Valuation'!$T$4/(1+$A$43)^5+'Pipeline Valuation'!$U$4/(1+$A$43)^6+'Pipeline Valuation'!$V$4/(1+$A$43)^7+'Pipeline Valuation'!$W$4/(1+$A$43)^8+'Pipeline Valuation'!$X$4/(1+$A$43)^9+'Pipeline Valuation'!$Y$4/(1+$A$43)^10+'Pipeline Valuation'!$Z$4/(1+$A$43)^11+'Pipeline Valuation'!$AA$4/(1+$A$43)^12+'Pipeline Valuation'!$AB$4/(1+$A$43)^13+'Pipeline Valuation'!$AC$4/(1+$A$43)^14+'Pipeline Valuation'!$AD$4/(1+$A$43)^15+'Pipeline Valuation'!$AE$4/(1+$A$43)^16+'Pipeline Valuation'!$AF$4/(1+$A$43)^17+'Pipeline Valuation'!$AG$4/(1+$A$43)^18+'Pipeline Valuation'!$AH$4/(1+$A$43)^19+'Pipeline Valuation'!$AI$4/(1+$A$43)^20+'Pipeline Valuation'!$AJ$4/(1+$A$43)^21+'Pipeline Valuation'!$AK$4/(1+$A$43)^22+'Pipeline Valuation'!$AL$4/(1+$A$43)^23+'Pipeline Valuation'!$AM$4/(1+$A$43)^24+'Pipeline Valuation'!$AN$4/(1+$A$43)^25+'Pipeline Valuation'!$AO$4/(1+$A$43)^26+'Pipeline Valuation'!$AP$4/(1+$A$43)^27+'Pipeline Valuation'!$AQ$4/(1+$A$43)^28+'Pipeline Valuation'!$AR$4/(1+$A$43)^29+'Pipeline Valuation'!$AS$4/(1+$A$43)^30+'Pipeline Valuation'!$AT$4/(1+$A$43)^31+'Pipeline Valuation'!$AU$4/(1+$A$43)^32+'Pipeline Valuation'!$AV$4/(1+$A$43)^33+'Pipeline Valuation'!$AW$4/(1+$A$43)^34+'Pipeline Valuation'!$AX$4/(1+$A$43)^35-SUMPRODUCT('Pipeline Valuation'!$E$6:$E$19,'Pipeline Valuation'!$N$6:$N$19)+'Pipeline Valuation'!$B$4+$M$24+$M$26+$M$27-$M$28-$M$29-$M$30)/$M$32))
...

Sheet Pipeline Valuation
A1: Risk-adjusted Pipeline Valuation — MRNA
A2: SEC identity, stage, status, partner, and filing narrative are reported facts. The 35-year schedule captures launch and post-LOE cash flows; sales, probability, economics, and residual rNPV remain analyst inputs.
A3: Total individually forecast late-stage asset rNPV | B3: =IF('Biotech Model'!$B$4<>"READY","",SUM(O6:O19)) | O3: Discount factor | P3: =IF('Biotech Model'!$B$4<>"READY","",1/(1+'Biotech Model'!$M$15)^1) | Q3: =IF('Biotech Model'!$B$4<>"READY","",1/(1+'Biotech Model'!$M$15)^2) | R3: =IF('Biotech Model'!$B$4<>"READY","",1/(1+'Biotech Model'!$M$15)^3) | S3: =IF('Biotech Model'!$B$4<>"READY","",1/(1+'Biotech Model'!$M$15)^4) | T3: =IF('Biotech Model'!$B$4<>"READY","",1/(1+'Biotech Model'!$M$15)^5) | U3: =IF('Biotech Model'!$B$4<>"READY","",1/(1+'Biotech Model'!$M$15)^6) | V3: =IF('Biotech Model'!$B$4<>"READY","",1/(1+'Biotech Model'!$M$15)^7) | W3: =IF('Biotech Model'!$B$4<>"READY","",1/(1+'Biotech Model'!$M$15)^8) | X3: =IF('Biotech Model'!$B$4<>"READY","",1/(1+'Biotech Model'!$M$15)^9) | Y3: =IF('Biotech Model'!$B$4<>"READY","",1/(1+'Biotech Model'!$M$15)^10) | Z3: =IF('Biotech Model'!$B$4<>"READY","",1/(1+'Biotech Model'!$M$15)^11) | AA3: =IF('Biotech Model'!$B$4<>"READY","",1/(1+'Biotech Model'!$M$15)^12) | AB3: =IF('Biotech Model'!$B$4<>"READY","",1/(1+'Biotech Model'!$M$15)^13) | AC3: =IF('Biotech Model'!$B$4<>"READY","",1/(1+'Biotech Model'!$M$15)^14) | AD3: =IF('Biotech Model'!$B$4<>"READY","",1/(1+'Biotech Model'!$M$15)^15) | AE3: =IF('Biotech Model'!$B$4<>"READY","",1/(1+'Biotech Model'!$M$15)^16) | AF3: =IF('Biotech Model'!$B$4<>"READY","",1/(1+'Biotech Model'!$M$15)^17) | AG3: =IF('Biotech Model'!$B$4<>"READY","",1/(1+'Biotech Model'!$M$15)^18) | AH3: =IF('Biotech Model'!$B$4<>"READY","",1/(1+'Biotech Model'!$M$15)^19) | AI3: =IF('Biotech Model'!$B$4<>"READY","",1/(1+'Biotech Model'!$M$15)^20) | AJ3: =IF('Biotech Model'!$B$4<>"READY","",1/(1+'Biotech Model'!$M$15)^21) | AK3: =IF('Biotech Model'!$B$4<>"READY","",1/(1+'Biotech Model'!$M$15)^22) | AL3: =IF('Biotech Model'!$B$4<>"READY","",1/(1+'Biotech Model'!$M$15)^23) | AM3: =IF('Biotech Model'!$B$4<>"READY","",1/(1+'Biotech Model'!$M$15)^24) | AN3: =IF('Biotech Model'!$B$4<>"READY","",1/(1+'Biotech Model'!$M$15)^25) | AO3: =IF('Biotech Model'!$B$4<>"READY","",1/(1+'Biotech Model'!$M$15)^26) | AP3: =IF('Biotech Model'!$B$4<>"READY","",1/(1+'Biotech Model'!$M$15)^27) | AQ3: =IF('Biotech Model'!$B$4<>"READY","",1/(1+'Biotech Model'!$M$15)^28) | AR3: =IF('Biotech Model'!$B$4<>"READY","",1/(1+'Biotech Model'!$M$15)^29) | AS3: =IF('Biotech Model'!$B$4<>"READY","",1/(1+'Biotech Model'!$M$15)^30) | AT3: =IF('Biotech Model'!$B$4<>"READY","",1/(1+'Biotech Model'!$M$15)^31) | AU3: =IF('Biotech Model'!$B$4<>"READY","",1/(1+'Biotech Model'!$M$15)^32) | AV3: =IF('Biotech Model'!$B$4<>"READY","",1/(1+'Biotech Model'!$M$15)^33) | AW3: =IF('Biotech Model'!$B$4<>"READY","",1/(1+'Biotech Model'!$M$15)^34) | AX3: =IF('Biotech Model'!$B$4<>"READY","",1/(1+'Biotech Model'!$M$15)^35)
A4: Other SEC-listed pipeline asset rNPV | B4: =IF('Biotech Model'!$B$4<>"READY","",SUM(G24:G41)) | O4: Risk-adjusted asset FCFF | P4: =IF('Biotech Model'!$B$4<>"READY","",SUM(P6:P19)) | Q4: =IF('Biotech Model'!$B$4<>"READY","",SUM(Q6:Q19)) | R4: =IF('Biotech Model'!$B$4<>"READY","",SUM(R6:R19)) | S4: =IF('Biotech Model'!$B$4<>"READY","",SUM(S6:S19)) | T4: =IF('Biotech Model'!$B$4<>"READY","",SUM(T6:T19)) | U4: =IF('Biotech Model'!$B$4<>"READY","",SUM(U6:U19)) | V4: =IF('Biotech Model'!$B$4<>"READY","",SUM(V6:V19)) | W4: =IF('Biotech Model'!$B$4<>"READY","",SUM(W6:W19)) | ... AX4: =IF('Biotech Model'!$B$4<>"READY","",SUM(AX6:AX19))
A5: Asset ID | B5: SEC asset label | C5: Stage / status / partner | D5: SEC source and filing basis | E5: Include | F5: Launch year | G5: Peak sales | H5: Years to peak | I5: Exclusivity year | J5: Post-LOE erosion | K5: PoS | L5: Retained share | M5: Post-tax FCFF margin | N5: Development-cost PV | O5: Asset rNPV | P5: 2026 | Q5: 2027 | R5: 2028 | S5: 2029 | T5: 2030 | U5: 2031 | V5: 2032 | W5: 2033 | X5: 2034 | Y5: 2035 | Z5: 2036 | AA5: 2037 | AB5: 2038 | AC5: 2039 | AD5: 2040 | AE5: 2041 | AF5: 2042 | AG5: 2043 | AH5: 2044 | AI5: 2045 | AJ5: 2046 | AK5: 2047 | AL5: 2048 | AM5: 2049 | AN5: 2050 | AO5: 2051 | AP5: 2052 | AQ5: 2053 | AR5: 2054 | AS5: 2055 | AT5: 2056 | AU5: 2057 | AV5: 2058 | AW5: 2059 | AX5: 2060
A6: mRNA-4157 | B6: mRNA-4157 | C6: Phase 2; disclosed; Partner: Merck | D6: SEC accession 0001682852-26-000033; filed 2026-02-20; report date 2025-12-31; 10-K; SEC 10-K Item 1, Business: In January 2026, we and Merck announced five-year data from the Phase 2b study of intismeran autogene (mRNA-4157), our mRNA-based individualized neoantigen therapy, in combination with Merck’s pembrolizumab (KEYTRUDA®), which demonstrated sustained improvement in recurrence-free survival in patients with high-risk melanoma (stage III/IV) following complete resection. | ONCOLOGY THERAPEUTICS FRANCHISE Within our oncology therapeutics franchise, we are developing intismeran autogene (mRNA-4157) in collaboration with Merck. | 18 Table of Contents Intismeran autogene (mRNA-4157) As tumors grow, they acquire mutations which may lead to the creation of new protein segments (neoantigens) that can be presented on human leukocyte antigen (HLA) molecules in the tumor and recognized as non-self by T cells. | Intismeran autogene, mRNA-4157, uses next generation sequencing and a machine-learning base | E6: =IF('Input Required'!$B$3<>"READY","",'Input Required'!F17/1) | F6: =IF('Input Required'!$B$3<>"READY","",'Input Required'!F18/1) | G6: =IF('Input Required'!$B$3<>"READY","",'Input Required'!F19/1000000) | H6: =IF('Input Required'!$B$3<>"READY","",'Input Required'!F20/1) | I6: =IF('Input Required'!$B$3<>"READY","",'Input Required'!F21/1) | J6: =IF('Input Required'!$B$3<>"READY","",'Input Required'!F22/1) | K6: =IF('Input Required'!$B$3<>"READY","",'Input Required'!F23/1) | L6: =IF('Input Required'!$B$3<>"READY","",'Input Required'!F24/1) | M6: =IF('Input Required'!$B$3<>"READY","",'Input Required'!F25/1) | N6: =IF('Input Required'!$B$3<>"READY","",'Input Required'!F26/1000000) | O6: =IF('Biotech Model'!$B$4<>"READY","",SUMPRODUCT(P6:AX6,$P$3:$AX$3)-E6*N6) | P6: =IF('Biotech Model'!$B$4<>"READY","",IF(E6=0,0,IF(P$5<F6,0,G6*MIN(1,(P$5-F6+1)/H6)*IF(P$5<=I6,1,(1-J6)^(P$5-I6)))*K6*L6*M6)) | Q6: =IF('Biotech Model'!$B$4<>"READY","",IF(E6=0,0,IF(Q$5<F6,0,G6*MIN(1,(Q$5-F6+1)/H6)*IF(Q$5<=I6,1,(1-J6)^(Q$5-I6)))*K6*L6*M6)) | R6: =IF('Biotech Model'!$B$4<>"READY","",IF(E6=0,0,IF(R$5<F6,0,G6*MIN(1,(R$5-F6+1)/H6)*IF(R$5<=I6,1,(1-J6)^(R$5-I6)))*K6*L6*M6)) | S6: =IF('Biotech Model'!$B$4<>"READY","",IF(E6=0,0,IF(S$5<F6,0,G6*MIN(1,(S$5-F6+1)/H6)*IF(S$5<=I6,1,(1-J6)^(S$5-I6)))*K6*L6*M6)) | T6: =IF('Biotech Model'!$B$4<>"READY","",IF(E6=0,0,IF(T$5<F6,0,G6*MIN(1,(T$5-F6+1)/H6)*IF(T$5<=I6,1,(1-J6)^(T$5-I6)))*K6*L6*M6)) | U6: =IF('Biotech Model'!$B$4<>"READY","",IF(E6=0,0,IF(U$5<F6,0,G6*MIN(1,(U$5-F6+1)/H6)*IF(U$5<=I6,1,(1-J6)^(U$5-I6)))*K6*L6*M6)) | V6: =IF('Biotech Model'!$B$4<>"READY","",IF(E6=0,0,IF(V$5<F6,0,G6*MIN(1,(V$5-F6+1)/H6)*IF(V$5<=I6,1,(1-J6)^(V$5-I6)))*K6*L6*M6)) | W6: =IF('Biotech Model'!$B$4<>"READY","",IF(E6=0,0,IF(W$5<F6,0,G6*MIN(1,(W$5-F6+1)/H6)*IF(W$5<=I6,1,(1-J6)^(W$5-I6)))*K6*L6*M6)) | X6: =IF('Biotech Model'!$B$4<>"READY","",IF(E6=0,0,IF(X$5<F6,0,G6*MIN(1,(X$5-F6+1)/H6)*IF(X$5<=I6,1,(1-J6)^(X$5-I6)))*K6*L6*M6)) | Y6: =IF('Biotech Model'!$B$4<>"READY","",IF(E6=0,0,IF(Y$5<F6,0,G6*MIN(1,(Y$5-F6+1)/H6)*IF(Y$5<=I6,1,(1-J6)^(Y$5-I6)))*K6*L6*M6)) | Z6: =IF('Biotech Model'!$B$4<>"READY","",IF(E6=0,0,IF(Z$5<F6,0,G6*MIN(1,(Z$5-F6+1)/H6)*IF(Z$5<=I6,1,(1-J6)^(Z$5-I6)))*K6*L6*M6)) | AA6: =IF('Biotech Model'!$B$4<>"READY","",IF(E6=0,0,IF(AA$5<F6,0,G6*MIN(1,(AA$5-F6+1)/H6)*IF(AA$5<=I6,1,(1-J6)^(AA$5-I6)))*K6*L6*M6)) | AB6: =IF('Biotech Model'!$B$4<>"READY","",IF(E6=0,0,IF(AB$5<F6,0,G6*MIN(1,(AB$5-F6+1)/H6)*IF(AB$5<=I6,1,(1-J6)^(AB$5-I6)))*K6*L6*M6)) | AC6: =IF('Biotech Model'!$B$4<>"READY","",IF(E6=0,0,IF(AC$5<F6,0,G6*MIN(1,(AC$5-F6+1)/H6)*IF(AC$5<=I6,1,(1-J6)^(AC$5-I6)))*K6*L6*M6)) | AD6: =IF('Biotech Model'!$B$4<>"READY","",IF(E6=0,0,IF(AD$5<F6,0,G6*MIN(1,(AD$5-F6+1)/H6)*IF(AD$5<=I6,1,(1-J6)^(AD$5-I6)))*K6*L6*M6)) | AE6: =IF('Biotech Model'!$B$4<>"READY","",IF(E6=0,0,IF(AE$5<F6,0,G6*MIN(1,(AE$5-F6+1)/H6)*IF(AE$5<=I6,1,(1-J6)^(AE$5-I6)))*K6*L6*M6)) | AF6: =IF('Biotech Model'!$B$4<>"READY","",IF(E6=0,0,IF(AF$5<F6,0,G6*MIN(1,(AF$5-F6+1)/H6)*IF(AF$5<=I6,1,(1-J6)^(AF$5-I6)))*K6*L6*M6)) | AG6: =IF('Biotech Model'!$B$4<>"READY","",IF(E6=0,0,IF(AG$5<F6,0,G6*MIN(1,(AG$5-F6+1)/H6)*IF(AG$5<=I6,1,(1-J6)^(AG$5-I6)))*K6*L6*M6)) | AH6: =IF('Biotech Model'!$B$4<>"READY","",IF(E6=0,0,IF(AH$5<F6,0,G6*MIN(1,(AH$5-F6+1)/H6)*IF(AH$5<=I6,1,(1-J6)^(AH$5-I6)))*K6*L6*M6)) | AI6: =IF('Biotech Model'!$B$4<>"READY","",IF(E6=0,0,IF(AI$5<F6,0,G6*MIN(1,(AI$5-F6+1)/H6)*IF(AI$5<=I6,1,(1-J6)^(AI$5-I6)))*K6*L6*M6)) | AJ6: =IF('Biotech Model'!$B$4<>"READY","",IF(E6=0,0,IF(AJ$5<F6,0,G6*MIN(1,(AJ$5-F6+1)/H6)*IF(AJ$5<=I6,1,(1-J6)^(AJ$5-I6)))*K6*L6*M6)) | AK6: =IF('Biotech Model'!$B$4<>"READY","",IF(E6=0,0,IF(AK$5<F6,0,G6*MIN(1,(AK$5-F6+1)/H6)*IF(AK$5<=I6,1,(1-J6)^(AK$5-I6)))*K6*L6*M6)) | AL6: =IF('Biotech Model'!$B$4<>"READY","",IF(E6=0,0,IF(AL$5<F6,0,G6*MIN(1,(AL$5-F6+1)/H6)*IF(AL$5<=I6,1,(1-J6)^(AL$5-I6)))*K6*L6*M6)) | AM6: =IF('Biotech Model'!$B$4<>"READY","",IF(E6=0,0,IF(AM$5<F6,0,G6*MIN(1,(AM$5-F6+1)/H6)*IF(AM$5<=I6,1,(1-J6)^(AM$5-I6)))*K6*L6*M6)) | AN6: =IF('Biotech Model'!$B$4<>"READY","",IF(E6=0,0,IF(AN$5<F6,0,G6*MIN(1,(AN$5-F6+1)/H6)*IF(AN$5<=I6,1,(1-J6)^(AN$5-I6)))*K6*L6*M6)) | AO6: =IF('Biotech Model'!$B$4<>"READY","",IF(E6=0,0,IF(AO$5<F6,0,G6*MIN(1,(AO$5-F6+1)/H6)*IF(AO$5<=I6,1,(1-J6)^(AO$5-I6)))*K6*L6*M6)) | AP6: =IF('Biotech Model'!$B$4<>"READY","",IF(E6=0,0,IF(AP$5<F6,0,G6*MIN(1,(AP$5-F6+1)/H6)*IF(AP$5<=I6,1,(1-J6)^(AP$5-I6)))*K6*L6*M6)) | AQ6: =IF('Biotech Model'!$B$4<>"READY","",IF(E6=0,0,IF(AQ$5<F6,0,G6*MIN(1,(AQ$5-F6+1)/H6)*IF(AQ$5<=I6,1,(1-J6)^(AQ$5-I6)))*K6*L6*M6)) | AR6: =IF('Biotech Model'!$B$4<>"READY","",IF(E6=0,0,IF(AR$5<F6,0,G6*MIN(1,(AR$5-F6+1)/H6)*IF(AR$5<=I6,1,(1-J6)^(AR$5-I6)))*K6*L6*M6)) | AS6: =IF('Biotech Model'!$B$4<>"READY","",IF(E6=0,0,IF(AS$5<F6,0,G6*MIN(1,(AS$5-F6+1)/H6)*IF(AS$5<=I6,1,(1-J6)^(AS$5-I6)))*K6*L6*M6)) | AT6: =IF('Biotech Model'!$B$4<>"READY","",IF(E6=0,0,IF(AT$5<F6,0,G6*MIN(1,(AT$5-F6+1)/H6)*IF(AT$5<=I6,1,(1-J6)^(AT$5-I6)))*K6*L6*M6)) | AU6: =IF('Biotech Model'!$B$4<>"READY","",IF(E6=0,0,IF(AU$5<F6,0,G6*MIN(1,(AU$5-F6+1)/H6)*IF(AU$5<=I6,1,(1-J6)^(AU$5-I6)))*K6*L6*M6)) | AV6: =IF('Biotech Model'!$B$4<>"READY","",IF(E6=0,0,IF(AV$5<F6,0,G6*MIN(1,(AV$5-F6+1)/H6)*IF(AV$5<=I6,1,(1-J6)^(AV$5-I6)))*K6*L6*M6)) | AW6: =IF('Biotech Model'!$B$4<>"READY","",IF(E6=0,0,IF(AW$5<F6,0,G6*MIN(1,(AW$5-F6+1)/H6)*IF(AW$5<=I6,1,(1-J6)^(AW$5-I6)))*K6*L6*M6)) | AX6: =IF('Biotech Model'!$B$4<>"READY","",IF(E6=0,0,IF(AX$5<F6,0,G6*MIN(1,(AX$5-F6+1)/H6)*IF(AX$5<=I6,1,(1-J6)^(AX$5-I6)))*K6*L6*M6))
A7: mRNA-4359 | B7: mRNA-4359 | C7: Phase 1/2; disclosed | D7: SEC accession 0001682852-26-000033; filed 2026-02-20; report date 2025-12-31; 10-K; SEC 10-K Item 1, Business: In oncology, we are also advancing mRNA-4359, a cancer antigen therapy designed to elicit T-cell immune responses against tumor and immunosuppressive cells. | Separate from the collaboration with Merck, our Phase 1/2 study of mRNA-4359, an investigational wholly-owned cancer antigen therapy, is ongoing. | Cancer antigen therapy (mRNA-4359) We are developing a cancer antigen therapy (mRNA-4359) that encodes Indoleamine 2,3-dioxygenase (IDO) and programmed death-ligand 1 (PD-L1) antigens. | We designed mRNA-4359 with the goal of stimulating effector T cells that target and kill suppressive immune and tumor cells that express the target antigens. | Our initial indications for mRNA-4359 are advanced or metastatic cutaneous melanoma and NSCLC. | 19 Table of Contents We presented data from the Phase 1a study of mRNA-4359 at the European Society for Medical Oncology (ESMO) Congress in 2024, whe | E7: =IF('Input Required'!$B$3<>"READY","",'Input Required'!F27/1) | F7: =IF('Input Required'!$B$3<>"READY","",'Input Required'!F28/1) | G7: =IF('Input Required'!$B$3<>"READY","",'Input Required'!F29/1000000) | H7: =IF('Input Required'!$B$3<>"READY","",'Input Required'!F30/1) | I7: =IF('Input Required'!$B$3<>"READY","",'Input Required'!F31/1) | J7: =IF('Input Required'!$B$3<>"READY","",'Input Required'!F32/1) | K7: =IF('Input Required'!$B$3<>"READY","",'Input Required'!F33/1) | L7: =IF('Input Required'!$B$3<>"READY","",'Input Required'!F34/1) | M7: =IF('Input Required'!$B$3<>"READY","",'Input Required'!F35/1) | N7: =IF('Input Required'!$B$3<>"READY","",'Input Required'!F36/1000000) | O7: =IF('Biotech Model'!$B$4<>"READY","",SUMPRODUCT(P7:AX7,$P$3:$AX$3)-E7*N7) | P7: =IF('Biotech Model'!$B$4<>"READY","",IF(E7=0,0,IF(P$5<F7,0,G7*MIN(1,(P$5-F7+1)/H7)*IF(P$5<=I7,1,(1-J7)^(P$5-I7)))*K7*L7*M7)) | Q7: =IF('Biotech Model'!$B$4<>"READY","",IF(E7=0,0,IF(Q$5<F7,0,G7*MIN(1,(Q$5-F7+1)/H7)*IF(Q$5<=I7,1,(1-J7)^(Q$5-I7)))*K7*L7*M7)) | R7: =IF('Biotech Model'!$B$4<>"READY","",IF(E7=0,0,IF(R$5<F7,0,G7*MIN(1,(R$5-F7+1)/H7)*IF(R$5<=I7,1,(1-J7)^(R$5-I7)))*K7*L7*M7)) | S7: =IF('Biotech Model'!$B$4<>"READY","",IF(E7=0,0,IF(S$5<F7,0,G7*MIN(1,(S$5-F7+1)/H7)*IF(S$5<=I7,1,(1-J7)^(S$5-I7)))*K7*L7*M7)) | T7: =IF('Biotech Model'!$B$4<>"READY","",IF(E7=0,0,IF(T$5<F7,0,G7*MIN(1,(T$5-F7+1)/H7)*IF(T$5<=I7,1,(1-J7)^(T$5-I7)))*K7*L7*M7)) | U7: =IF('Biotech Model'!$B$4<>"READY","",IF(E7=0,0,IF(U$5<F7,0,G7*MIN(1,(U$5-F7+1)/H7)*IF(U$5<=I7,1,(1-J7)^(U$5-I7)))*K7*L7*M7)) | V7: =IF('Biotech Model'!$B$4<>"READY","",IF(E7=0,0,IF(V$5<F7,0,G7*MIN(1,(V$5-F7+1)/H7)*IF(V$5<=I7,1,(1-J7)^(V$5-I7)))*K7*L7*M7)) | W7: =IF('Biotech Model'!$B$4<>"READY","",IF(E7=0,0,IF(W$5<F7,0,G7*MIN(1,(W$5-F7+1)/H7)*IF(W$5<=I7,1,(1-J7)^(W$5-I7)))*K7*L7*M7)) | X7: =IF('Biotech Model'!$B$4<>"READY","",IF(E7=0,0,IF(X$5<F7,0,G7*MIN(1,(X$5-F7+1)/H7)*IF(X$5<=I7,1,(1-J7)^(X$5-I7)))*K7*L7*M7)) | Y7: =IF('Biotech Model'!$B$4<>"READY","",IF(E7=0,0,IF(Y$5<F7,0,G7*MIN(1,(Y$5-F7+1)/H7)*IF(Y$5<=I7,1,(1-J7)^(Y$5-I7)))*K7*L7*M7)) | Z7: =IF('Biotech Model'!$B$4<>"READY","",IF(E7=0,0,IF(Z$5<F7,0,G7*MIN(1,(Z$5-F7+1)/H7)*IF(Z$5<=I7,1,(1-J7)^(Z$5-I7)))*K7*L7*M7)) | AA7: =IF('Biotech Model'!$B$4<>"READY","",IF(E7=0,0,IF(AA$5<F7,0,G7*MIN(1,(AA$5-F7+1)/H7)*IF(AA$5<=I7,1,(1-J7)^(AA$5-I7)))*K7*L7*M7)) | AB7: =IF('Biotech Model'!$B$4<>"READY","",IF(E7=0,0,IF(AB$5<F7,0,G7*MIN(1,(AB$5-F7+1)/H7)*IF(AB$5<=I7,1,(1-J7)^(AB$5-I7)))*K7*L7*M7)) | AC7: =IF('Biotech Model'!$B$4<>"READY","",IF(E7=0,0,IF(AC$5<F7,0,G7*MIN(1,(AC$5-F7+1)/H7)*IF(AC$5<=I7,1,(1-J7)^(AC$5-I7)))*K7*L7*M7)) | AD7: =IF('Biotech Model'!$B$4<>"READY","",IF(E7=0,0,IF(AD$5<F7,0,G7*MIN(1,(AD$5-F7+1)/H7)*IF(AD$5<=I7,1,(1-J7)^(AD$5-I7)))*K7*L7*M7)) | AE7: =IF('Biotech Model'!$B$4<>"READY","",IF(E7=0,0,IF(AE$5<F7,0,G7*MIN(1,(AE$5-F7+1)/H7)*IF(AE$5<=I7,1,(1-J7)^(AE$5-I7)))*K7*L7*M7)) | AF7: =IF('Biotech Model'!$B$4<>"READY","",IF(E7=0,0,IF(AF$5<F7,0,G7*MIN(1,(AF$5-F7+1)/H7)*IF(AF$5<=I7,1,(1-J7)^(AF$5-I7)))*K7*L7*M7)) | AG7: =IF('Biotech Model'!$B$4<>"READY","",IF(E7=0,0,IF(AG$5<F7,0,G7*MIN(1,(AG$5-F7+1)/H7)*IF(AG$5<=I7,1,(1-J7)^(AG$5-I7)))*K7*L7*M7)) | AH7: =IF('Biotech Model'!$B$4<>"READY","",IF(E7=0,0,IF(AH$5<F7,0,G7*MIN(1,(AH$5-F7+1)/H7)*IF(AH$5<=I7,1,(1-J7)^(AH$5-I7)))*K7*L7*M7)) | AI7: =IF('Biotech Model'!$B$4<>"READY","",IF(E7=0,0,IF(AI$5<F7,0,G7*MIN(1,(AI$5-F7+1)/H7)*IF(AI$5<=I7,1,(1-J7)^(AI$5-I7)))*K7*L7*M7)) | AJ7: =IF('Biotech Model'!$B$4<>"READY","",IF(E7=0,0,IF(AJ$5<F7,0,G7*MIN(1,(AJ$5-F7+1)/H7)*IF(AJ$5<=I7,1,(1-J7)^(AJ$5-I7)))*K7*L7*M7)) | AK7: =IF('Biotech Model'!$B$4<>"READY","",IF(E7=0,0,IF(AK$5<F7,0,G7*MIN(1,(AK$5-F7+1)/H7)*IF(AK$5<=I7,1,(1-J7)^(AK$5-I7)))*K7*L7*M7)) | AL7: =IF('Biotech Model'!$B$4<>"READY","",IF(E7=0,0,IF(AL$5<F7,0,G7*MIN(1,(AL$5-F7+1)/H7)*IF(AL$5<=I7,1,(1-J7)^(AL$5-I7)))*K7*L7*M7)) | AM7: =IF('Biotech Model'!$B$4<>"READY","",IF(E7=0,0,IF(AM$5<F7,0,G7*MIN(1,(AM$5-F7+1)/H7)*IF(AM$5<=I7,1,(1-J7)^(AM$5-I7)))*K7*L7*M7)) | AN7: =IF('Biotech Model'!$B$4<>"READY","",IF(E7=0,0,IF(AN$5<F7,0,G7*MIN(1,(AN$5-F7+1)/H7)*IF(AN$5<=I7,1,(1-J7)^(AN$5-I7)))*K7*L7*M7)) | AO7: =IF('Biotech Model'!$B$4<>"READY","",IF(E7=0,0,IF(AO$5<F7,0,G7*MIN(1,(AO$5-F7+1)/H7)*IF(AO$5<=I7,1,(1-J7)^(AO$5-I7)))*K7*L7*M7)) | AP7: =IF('Biotech Model'!$B$4<>"READY","",IF(E7=0,0,IF(AP$5<F7,0,G7*MIN(1,(AP$5-F7+1)/H7)*IF(AP$5<=I7,1,(1-J7)^(AP$5-I7)))*K7*L7*M7)) | AQ7: =IF('Biotech Model'!$B$4<>"READY","",IF(E7=0,0,IF(AQ$5<F7,0,G7*MIN(1,(AQ$5-F7+1)/H7)*IF(AQ$5<=I7,1,(1-J7)^(AQ$5-I7)))*K7*L7*M7)) | AR7: =IF('Biotech Model'!$B$4<>"READY","",IF(E7=0,0,IF(AR$5<F7,0,G7*MIN(1,(AR$5-F7+1)/H7)*IF(AR$5<=I7,1,(1-J7)^(AR$5-I7)))*K7*L7*M7)) | AS7: =IF('Biotech Model'!$B$4<>"READY","",IF(E7=0,0,IF(AS$5<F7,0,G7*MIN(1,(AS$5-F7+1)/H7)*IF(AS$5<=I7,1,(1-J7)^(AS$5-I7)))*K7*L7*M7)) | AT7: =IF('Biotech Model'!$B$4<>"READY","",IF(E7=0,0,IF(AT$5<F7,0,G7*MIN(1,(AT$5-F7+1)/H7)*IF(AT$5<=I7,1,(1-J7)^(AT$5-I7)))*K7*L7*M7)) | AU7: =IF('Biotech Model'!$B$4<>"READY","",IF(E7=0,0,IF(AU$5<F7,0,G7*MIN(1,(AU$5-F7+1)/H7)*IF(AU$5<=I7,1,(1-J7)^(AU$5-I7)))*K7*L7*M7)) | AV7: =IF('Biotech Model'!$B$4<>"READY","",IF(E7=0,0,IF(AV$5<F7,0,G7*MIN(1,(AV$5-F7+1)/H7)*IF(AV$5<=I7,1,(1-J7)^(AV$5-I7)))*K7*L7*M7)) | AW7: =IF('Biotech Model'!$B$4<>"READY","",IF(E7=0,0,IF(AW$5<F7,0,G7*MIN(1,(AW$5-F7+1)/H7)*IF(AW$5<=I7,1,(1-J7)^(AW$5-I7)))*K7*L7*M7)) | AX7: =IF('Biotech Model'!$B$4<>"READY","",IF(E7=0,0,IF(AX$5<F7,0,G7*MIN(1,(AX$5-F7+1)/H7)*IF(AX$5<=I7,1,(1-J7)^(AX$5-I7)))*K7*L7*M7))
A8: mRNA-1083 | B8: mRNA-1083 | C8: Phase 3; disclosed | D8: SEC accession 0001682852-26-000033; filed 2026-02-20; report date 2025-12-31; 10-K; SEC 10-K Item 1, Business: In infectious disease, we have regulatory filings under review for our seasonal flu+COVID combination vaccine candidate (mRNA-1083) in Europe and Canada, and for our seasonal flu vaccine candidate (mRNA-1010) in the United States, Europe, Canada and Australia. | Additionally, we have regulatory filings under review for our seasonal flu+COVID vaccine (mRNA-1083) in Europe and Canada and for our seasonal flu vaccine (mRNA-1010) in the United States, Europe, Canada and Australia. | Combination vaccines (mRNA-1083 and mRNA-1365) We are developing combination vaccine candidates to simplify and facilitate protection against a range of respiratory diseases. | Our COVID and seasonal influenza combination vaccine (mRNA-1083), encodes the same antigens as our seasonal influenza vaccine (mRNA-1010) and mNEXSPIKE. | In June 2024, we announced that our Phase 3 clinical trial of mRNA-1083 met its prim | E8: =IF('Input Required'!$B$3<>"READY","",'Input Required'!F37/1) | F8: =IF('Input Required'!$B$3<>"READY","",'Input Required'!F38/1) | G8: =IF('Input Required'!$B$3<>"READY","",'Input Required'!F39/1000000) | H8: =IF('Input Required'!$B$3<>"READY","",'Input Required'!F40/1) | I8: =IF('Input Required'!$B$3<>"READY","",'Input Required'!F41/1) | J8: =IF('Input Required'!$B$3<>"READY","",'Input Required'!F42/1) | K8: =IF('Input Required'!$B$3<>"READY","",'Input Required'!F43/1) | L8: =IF('Input Required'!$B$3<>"READY","",'Input Required'!F44/1) | M8: =IF('Input Required'!$B$3<>"READY","",'Input Required'!F45/1) | N8: =IF('Input Required'!$B$3<>"READY","",'Input Required'!F46/1000000) | O8: =IF('Biotech Model'!$B$4<>"READY","",SUMPRODUCT(P8:AX8,$P$3:$AX$3)-E8*N8) | P8: =IF('Biotech Model'!$B$4<>"READY","",IF(E8=0,0,IF(P$5<F8,0,G8*MIN(1,(P$5-F8+1)/H8)*IF(P$5<=I8,1,(1-J8)^(P$5-I8)))*K8*L8*M8)) | Q8: =IF('Biotech Model'!$B$4<>"READY","",IF(E8=0,0,IF(Q$5<F8,0,G8*MIN(1,(Q$5-F8+1)/H8)*IF(Q$5<=I8,1,(1-J8)^(Q$5-I8)))*K8*L8*M8)) | R8: =IF('Biotech Model'!$B$4<>"READY","",IF(E8=0,0,IF(R$5<F8,0,G8*MIN(1,(R$5-F8+1)/H8)*IF(R$5<=I8,1,(1-J8)^(R$5-I8)))*K8*L8*M8)) | S8: =IF('Biotech Model'!$B$4<>"READY","",IF(E8=0,0,IF(S$5<F8,0,G8*MIN(1,(S$5-F8+1)/H8)*IF(S$5<=I8,1,(1-J8)^(S$5-I8)))*K8*L8*M8)) | T8: =IF('Biotech Model'!$B$4<>"READY","",IF(E8=0,0,IF(T$5<F8,0,G8*MIN(1,(T$5-F8+1)/H8)*IF(T$5<=I8,1,(1-J8)^(T$5-I8)))*K8*L8*M8)) | U8: =IF('Biotech Model'!$B$4<>"READY","",IF(E8=0,0,IF(U$5<F8,0,G8*MIN(1,(U$5-F8+1)/H8)*IF(U$5<=I8,1,(1-J8)^(U$5-I8)))*K8*L8*M8)) | V8: =IF('Biotech Model'!$B$4<>"READY","",IF(E8=0,0,IF(V$5<F8,0,G8*MIN(1,(V$5-F8+1)/H8)*IF(V$5<=I8,1,(1-J8)^(V$5-I8)))*K8*L8*M8)) | W8: =IF('Biotech Model'!$B$4<>"READY","",IF(E8=0,0,IF(W$5<F8,0,G8*MIN(1,(W$5-F8+1)/H8)*IF(W$5<=I8,1,(1-J8)^(W$5-I8)))*K8*L8*M8)) | X8: =IF('Biotech Model'!$B$4<>"READY","",IF(E8=0,0,IF(X$5<F8,0,G8*MIN(1,(X$5-F8+1)/H8)*IF(X$5<=I8,1,(1-J8)^(X$5-I8)))*K8*L8*M8)) | Y8: =IF('Biotech Model'!$B$4<>"READY","",IF(E8=0,0,IF(Y$5<F8,0,G8*MIN(1,(Y$5-F8+1)/H8)*IF(Y$5<=I8,1,(1-J8)^(Y$5-I8)))*K8*L8*M8)) | Z8: =IF('Biotech Model'!$B$4<>"READY","",IF(E8=0,0,IF(Z$5<F8,0,G8*MIN(1,(Z$5-F8+1)/H8)*IF(Z$5<=I8,1,(1-J8)^(Z$5-I8)))*K8*L8*M8)) | AA8: =IF('Biotech Model'!$B$4<>"READY","",IF(E8=0,0,IF(AA$5<F8,0,G8*MIN(1,(AA$5-F8+1)/H8)*IF(AA$5<=I8,1,(1-J8)^(AA$5-I8)))*K8*L8*M8)) | AB8: =IF('Biotech Model'!$B$4<>"READY","",IF(E8=0,0,IF(AB$5<F8,0,G8*MIN(1,(AB$5-F8+1)/H8)*IF(AB$5<=I8,1,(1-J8)^(AB$5-I8)))*K8*L8*M8)) | AC8: =IF('Biotech Model'!$B$4<>"READY","",IF(E8=0,0,IF(AC$5<F8,0,G8*MIN(1,(AC$5-F8+1)/H8)*IF(AC$5<=I8,1,(1-J8)^(AC$5-I8)))*K8*L8*M8)) | AD8: =IF('Biotech Model'!$B$4<>"READY","",IF(E8=0,0,IF(AD$5<F8,0,G8*MIN(1,(AD$5-F8+1)/H8)*IF(AD$5<=I8,1,(1-J8)^(AD$5-I8)))*K8*L8*M8)) | AE8: =IF('Biotech Model'!$B$4<>"READY","",IF(E8=0,0,IF(AE$5<F8,0,G8*MIN(1,(AE$5-F8+1)/H8)*IF(AE$5<=I8,1,(1-J8)^(AE$5-I8)))*K8*L8*M8)) | AF8: =IF('Biotech Model'!$B$4<>"READY","",IF(E8=0,0,IF(AF$5<F8,0,G8*MIN(1,(AF$5-F8+1)/H8)*IF(AF$5<=I8,1,(1-J8)^(AF$5-I8)))*K8*L8*M8)) | AG8: =IF('Biotech Model'!$B$4<>"READY","",IF(E8=0,0,IF(AG$5<F8,0,G8*MIN(1,(AG$5-F8+1)/H8)*IF(AG$5<=I8,1,(1-J8)^(AG$5-I8)))*K8*L8*M8)) | AH8: =IF('Biotech Model'!$B$4<>"READY","",IF(E8=0,0,IF(AH$5<F8,0,G8*MIN(1,(AH$5-F8+1)/H8)*IF(AH$5<=I8,1,(1-J8)^(AH$5-I8)))*K8*L8*M8)) | AI8: =IF('Biotech Model'!$B$4<>"READY","",IF(E8=0,0,IF(AI$5<F8,0,G8*MIN(1,(AI$5-F8+1)/H8)*IF(AI$5<=I8,1,(1-J8)^(AI$5-I8)))*K8*L8*M8)) | AJ8: =IF('Biotech Model'!$B$4<>"READY","",IF(E8=0,0,IF(AJ$5<F8,0,G8*MIN(1,(AJ$5-F8+1)/H8)*IF(AJ$5<=I8,1,(1-J8)^(AJ$5-I8)))*K8*L8*M8)) | AK8: =IF('Biotech Model'!$B$4<>"READY","",IF(E8=0,0,IF(AK$5<F8,0,G8*MIN(1,(AK$5-F8+1)/H8)*IF(AK$5<=I8,1,(1-J8)^(AK$5-I8)))*K8*L8*M8)) | AL8: =IF('Biotech Model'!$B$4<>"READY","",IF(E8=0,0,IF(AL$5<F8,0,G8*MIN(1,(AL$5-F8+1)/H8)*IF(AL$5<=I8,1,(1-J8)^(AL$5-I8)))*K8*L8*M8)) | AM8: =IF('Biotech Model'!$B$4<>"READY","",IF(E8=0,0,IF(AM$5<F8,0,G8*MIN(1,(AM$5-F8+1)/H8)*IF(AM$5<=I8,1,(1-J8)^(AM$5-I8)))*K8*L8*M8)) | AN8: =IF('Biotech Model'!$B$4<>"READY","",IF(E8=0,0,IF(AN$5<F8,0,G8*MIN(1,(AN$5-F8+1)/H8)*IF(AN$5<=I8,1,(1-J8)^(AN$5-I8)))*K8*L8*M8)) | AO8: =IF('Biotech Model'!$B$4<>"READY","",IF(E8=0,0,IF(AO$5<F8,0,G8*MIN(1,(AO$5-F8+1)/H8)*IF(AO$5<=I8,1,(1-J8)^(AO$5-I8)))*K8*L8*M8)) | AP8: =IF('Biotech Model'!$B$4<>"READY","",IF(E8=0,0,IF(AP$5<F8,0,G8*MIN(1,(AP$5-F8+1)/H8)*IF(AP$5<=I8,1,(1-J8)^(AP$5-I8)))*K8*L8*M8)) | AQ8: =IF('Biotech Model'!$B$4<>"READY","",IF(E8=0,0,IF(AQ$5<F8,0,G8*MIN(1,(AQ$5-F8+1)/H8)*IF(AQ$5<=I8,1,(1-J8)^(AQ$5-I8)))*K8*L8*M8)) | AR8: =IF('Biotech Model'!$B$4<>"READY","",IF(E8=0,0,IF(AR$5<F8,0,G8*MIN(1,(AR$5-F8+1)/H8)*IF(AR$5<=I8,1,(1-J8)^(AR$5-I8)))*K8*L8*M8)) | AS8: =IF('Biotech Model'!$B$4<>"READY","",IF(E8=0,0,IF(AS$5<F8,0,G8*MIN(1,(AS$5-F8+1)/H8)*IF(AS$5<=I8,1,(1-J8)^(AS$5-I8)))*K8*L8*M8)) | AT8: =IF('Biotech Model'!$B$4<>"READY","",IF(E8=0,0,IF(AT$5<F8,0,G8*MIN(1,(AT$5-F8+1)/H8)*IF(AT$5<=I8,1,(1-J8)^(AT$5-I8)))*K8*L8*M8)) | AU8: =IF('Biotech Model'!$B$4<>"READY","",IF(E8=0,0,IF(AU$5<F8,0,G8*MIN(1,(AU$5-F8+1)/H8)*IF(AU$5<=I8,1,(1-J8)^(AU$5-I8)))*K8*L8*M8)) | AV8: =IF('Biotech Model'!$B$4<>"READY","",IF(E8=0,0,IF(AV$5<F8,0,G8*MIN(1,(AV$5-F8+1)/H8)*IF(AV$5<=I8,1,(1-J8)^(AV$5-I8)))*K8*L8*M8)) | AW8: =IF('Biotech Model'!$B$4<>"READY","",IF(E8=0,0,IF(AW$5<F8,0,G8*MIN(1,(AW$5-F8+1)/H8)*IF(AW$5<=I8,1,(1-J8)^(AW$5-I8)))*K8*L8*M8)) | AX8: =IF('Biotech Model'!$B$4<>"READY","",IF(E8=0,0,IF(AX$5<F8,0,G8*MIN(1,(AX$5-F8+1)/H8)*IF(AX$5<=I8,1,(1-J8)^(AX$5-I8)))*K8*L8*M8))
